Workbook

Sheet 1. Overview
B2: COLUMBIA VALUATION MODEL — Ferrari N.V. | DCE Holdings
B3: Fecha de Valoración: 22-May-2026 | Precio: €317.63 (USD 349.39 @ 1.10 EUR/USD)
B5: PERFIL DE LA EMPRESA
B6: Nombre | C6: Ferrari N.V.
B7: Ticker / Bolsa | C7: RACE — NYSE / EXM Milan
B8: Sector (GICS) | C8: Consumer Discretionary / Automobiles / Luxury
B9: Modelo de Negocio | C9: Manufacturer of luxury performance sports cars + F1 racing
B10: Fiscal Year End | C10: December 31
B11: CEO | C11: Benedetto Vigna
B12: Sede | C12: Maranello, Italy
B13: Empleados (~) | C13: 5,500
B14: Fecha de Valoración | C14: 22-May-2026
B16: DATOS DE MERCADO
B17: Precio Actual (€) | C17: 317.63 | D17: NYSE close 22-May-2026 USD/EUR 1.10
B18: Acciones Diluidas (M) | C18: 178.321 | D18: Ferrari FY25 diluted shares
B19: Market Cap (€M) | C19: =C17*C18
B20: Total Deuda (€M) | C20: ='3. BS'!H44
B21: Lease Liabilities (€M) | C21: ='3. BS'!H30
B22: Cash + STI (€M) | C22: ='3. BS'!H7
B23: Enterprise Value (€M) | C23: =C19+C20+C21-C22
B25: MÉTRICAS FINANCIERAS CLAVE (LTM = FY 2025)
B26: Net Revenue (€M) | C26: ='2. IS'!H5
B27: Operating Income (EBIT) (€M) | C27: ='2. IS'!H16
B28: Operating Margin % | C28: ='2. IS'!H25
B29: EBITDA (€M) | C29: ='2. IS'!H24
B30: Net Income (€M) | C30: ='2. IS'!H20
B31: EPS Diluted (€) | C31: ='2. IS'!H30
B32: Free Cash Flow (€M) | C32: ='4. CF'!H25
B33: FCF Margin % | C33: ='4. CF'!H25/'2. IS'!H5
B34: D&A (€M) | C34: ='4. CF'!H7
B35: SBC (€M) | C35: ='2. IS'!H32
B36: CapEx (€M) | C36: =-'4. CF'!H13
B38: MÚLTIPLOS DE VALORACIÓN
B39: P/E (Diluted) | C39: =C17/'2. IS'!H30
B40: EV/EBITDA | C40: =C23/'2. IS'!H24
B41: EV/Revenue | C41: =C23/'2. IS'!H5
B42: Price/FCF | C42: =C19/'4. CF'!H25
B43: Price/Book | C43: =C19/'3. BS'!H38
B44: Dividend Yield | C44: =-'4. CF'!H19/C19
B45: Revenue Growth YoY | C45: ='2. IS'!H5/'2. IS'!G5-1
...

Sheet 2. IS
B2: ESTADO DE RESULTADOS — Ferrari N.V. (NYSE: RACE) | DCE Holdings
B3: Source: Ferrari 20-F + Press Releases | EUR Millions | ROIC.ai complemented with EDGAR
B4: CONCEPTO (€M) | C4: FY 2020 | D4: FY 2021 | E4: FY 2022 | F4: FY 2023 | G4: FY 2024 | H4: FY 2025
B5: Net Revenues | C5: 3460 | D5: 4271 | E5: 5095 | F5: 5970 | G5: 6677 | H5: 7146
B6: Cost of Sales | C6: 1686 | D6: 2081 | E6: 2649 | F6: 2996 | G6: 3330 | H6: 3453
B7: Gross Profit | C7: =C5-C6 | D7: =D5-D6 | E7: =E5-E6 | F7: =F5-F6 | G7: =G5-G6 | H7: =H5-H6
B9: OPERATING EXPENSES:
B10: Selling, General and Administrative | C10: 336 | D10: 348 | E10: 428 | F10: 463 | G10: 561 | H10: 642
B11: Research and Development | C11: 707 | D11: 768 | E11: 776 | F11: 882 | G11: 894 | H11: 919
B12: Other Expenses (Income), net | C12: 18 | D12: 6 | E12: 22 | F12: 19 | G12: 12 | H12: 34
B13: Results from Investments | C13: 0 | D13: 0 | E13: 0 | F13: 0 | G13: -8 | H13: -12
B14: Total Operating Expenses | C14: =SUM(C10:C13) | D14: =SUM(D10:D13) | E14: =SUM(E10:E13) | F14: =SUM(F10:F13) | G14: =SUM(G10:G13) | H14: =SUM(H10:H13)
B16: Operating Income (EBIT) | C16: =C7-C14 | D16: =D7-D14 | E16: =E7-E14 | F16: =F7-F14 | G16: =G7-G14 | H16: =H7-H14
B17: Interest Expense, net | C17: -50 | D17: -38 | E17: -54 | F17: -36 | G17: -47 | H17: -41
B18: Income Before Taxes | C18: =C16+C17 | D18: =D16+D17 | E18: =E16+E17 | F18: =F16+F17 | G18: =G16+G17 | H18: =H16+H17
B19: Provision for Income Taxes | C19: -58 | D19: -209 | E19: -238 | F19: -345 | G19: -363 | H19: -464
B20: Net Income | C20: =C18+C19 | D20: =D18+D19 | E20: =E18+E19 | F20: =F18+F19 | G20: =G18+G19 | H20: =H18+H19
B22: MÉTRICAS DERIVADAS:
B23: D&A (from CF) | C23: 427 | D23: 456 | E23: 546 | F23: 662 | G23: 667 | H23: 662
B24: EBITDA | C24: =C16+C23 | D24: =D16+D23 | E24: =E16+E23 | F24: =F16+F23 | G24: =G16+G23 | H24: =H16+H23
B25: Operating Margin % | C25: =C16/C5 | D25: =D16/D5 | E25: =E16/E5 | F25: =F16/F5 | G25: =G16/G5 | H25: =H16/H5
B26: Net Margin % | C26: =C20/C5 | D26: =D20/D5 | E26: =E20/E5 | F26: =F20/F5 | G26: =G20/G5 | H26: =H20/H5
B27: Effective Tax Rate % | C27: =-C19/C18 | D27: =-D19/D18 | E27: =-E19/E18 | F27: =-F19/F18 | G27: =-G19/G18 | H27: =-H19/H18
B29: DATOS SUPLEMENTARIOS:
B30: EPS Diluted (€) | C30: 3.28 | D30: 4.5 | E30: 5.09 | F30: 6.9 | G30: 8.46 | H30: 8.96
B31: Diluted Shares (M) | C31: 185.4 | D31: 184.7 | E31: 183.1 | F31: 181.5 | G31: 180 | H31: 178.3
B32: Stock-Based Compensation | C32: 0 | D32: 0 | E32: 0 | F32: 0 | G32: 0 | H32: 6
B33: SBC / Revenue | C33: =C32/C5 | D33: =D32/D5 | E33: =E32/E5 | F33: =F32/F5 | G33: =G32/G5 | H33: =H32/H5
B35: Source: Ferrari N.V. 20-F (SEC EDGAR) + FY2025 Press Release (Feb 2026) | ROIC.ai aggregates | DCE Holdings | EUR Millions

Sheet 3. BS
B2: BALANCE GENERAL — Ferrari N.V. (NYSE: RACE) | DCE Holdings
B3: Source: Ferrari 20-F (SEC EDGAR) | EUR Millions
B4: CONCEPTO (€M) | C4: FY 2020 | D4: FY 2021 | E4: FY 2022 | F4: FY 2023 | G4: FY 2024 | H4: FY 2025
B5: ACTIVOS
B6: Cash and Cash Equivalents | C6: 1667 | D6: 1344 | E6: 1389 | F6: 1122 | G6: 1742 | H6: 1468
B7: Cash + Short-Term Investments | C7: 1714 | D7: 1346 | E7: 1396 | F7: 1128 | G7: 1748 | H7: 1472
B8: Trade Receivables | C8: 283 | D8: 650 | E8: 800 | F8: 950 | G8: 1100 | H8: 1100
B9: Inventories | C9: 475 | D9: 510 | E9: 645 | F9: 716 | G9: 800 | H9: 880
B10: Other Current Assets | C10: 350 | D10: 858 | E10: 1112 | F10: 1192 | G10: 1372 | H10: 1372
B11: Total Current Assets | C11: 2822 | D11: 3364 | E11: 3953 | F11: 3986 | G11: 5020 | H11: 4824
B13: Property, Plant and Equipment, Net | C13: 1501 | D13: 1353 | E13: 1458 | F13: 1575 | G13: 1829 | H13: 2058
B14: Goodwill | C14: 961 | D14: 785 | E14: 785 | F14: 785 | G14: 785 | H14: 785
B15: Other Intangible Assets | C15: 1198 | D15: 1138 | E15: 1307 | F15: 1420 | G15: 1546 | H15: 1638
B16: Long-Term Financial Services Receivables | C16: 800 | D16: 850 | E16: 900 | F16: 950 | G16: 1000 | H16: 1100
B17: Deferred Tax Assets | C17: 180 | D17: 220 | E17: 260 | F17: 320 | G17: 350 | H17: 400
B18: Other Non-Current Assets | C18: 200 | D18: 154 | E18: 103 | F18: 15 | G18: -33 | H18: -177
B20: Total Assets | C20: 7662 | D20: 6864 | E20: 7766 | F20: 8051 | G20: 9497 | H20: 9628
B22: PASIVOS
B23: Accounts Payable | C23: 600 | D23: 700 | E23: 800 | F23: 900 | G23: 1000 | H23: 1050
B24: Short-Term Debt | C24: 1088 | D24: 0 | E24: 0 | F24: 0 | G24: 0 | H24: 931
B25: Short-Term Provisions | C25: 100 | D25: 150 | E25: 175 | F25: 200 | G25: 220 | H25: 240
B26: Other Current Liabilities | C26: 357 | D26: 476 | E26: 438 | F26: 387 | G26: 271 | H26: 169
B27: Total Current Liabilities | C27: 2145 | D27: 1326 | E27: 1413 | F27: 1487 | G27: 1491 | H27: 2390
B29: Long-Term Debt | C29: 2190 | D29: 2574 | E29: 2754 | F29: 2404 | G29: 3226 | H29: 1791
B30: Lease Liabilities (Non-Current) | C30: 56 | D30: 56 | E30: 57 | F30: 73 | G30: 126 | H30: 162
B31: Long-Term Provisions | C31: 250 | D31: 280 | E31: 300 | F31: 340 | G31: 380 | H31: 410
B32: Deferred Tax Liabilities | C32: 350 | D32: 350 | E32: 370 | F32: 400 | G32: 420 | H32: 440
B33: Other Non-Current Liabilities | C33: 289 | D33: 72 | E33: 279 | F33: 290 | G33: 346 | H33: 528
B35: Total Liabilities | C35: 5478 | D35: 4658 | E35: 5173 | F35: 4990 | G35: 5963 | H35: 5721
B37: PATRIMONIO
B38: Total Stockholders' Equity | C38: 2184 | D38: 2206 | E38: 2593 | F38: 3061 | G38: 3534 | H38: 3907
B40: Total Liabilities + Equity (check) | C40: =C35+C38 | D40: =D35+D38 | E40: =E35+E38 | F40: =F35+F38 | G40: =G35+G38 | H40: =H35+H38
B42: DATOS SUPLEMENTARIOS:
B43: Cash + Short-Term Investments | C43: =C7 | D43: =D7 | E43: =E7 | F43: =F7 | G43: =G7 | H43: =H7
B44: Total Debt | C44: =C24+C29 | D44: =D24+D29 | E44: =E24+E29 | F44: =F24+F29 | G44: =G24+G29 | H44: =H24+H29
B45: Net Debt (Total Debt + Leases − Cash & STI) | C45: =C44+C30-C43 | D45: =D44+D30-D43 | E45: =E44+E30-E43 | F45: =F44+F30-F43 | G45: =G44+G30-G43 | H45: =H44+H30-H43
B46: Book Value per Share (€) | C46: =C38/'2. IS'!C31 | D46: =D38/'2. IS'!D31 | E46: =E38/'2. IS'!E31 | F46: =F38/'2. IS'!F31 | G46: =G38/'2. IS'!G31 | H46: =H38/'2. IS'!H31
B48: Source: Ferrari 20-F balance sheets + Q4 press release | DCE Holdings | EUR Millions

Sheet 4. CF
B2: ESTADO DE FLUJOS DE EFECTIVO — Ferrari N.V. (NYSE: RACE) | DCE Holdings
B3: Source: Ferrari 20-F (SEC EDGAR) + Press Releases | EUR Millions
B4: CONCEPTO (€M) | C4: FY 2020 | D4: FY 2021 | E4: FY 2022 | F4: FY 2023 | G4: FY 2024 | H4: FY 2025
B5: OPERACIONES
B6: Net Income | C6: ='2. IS'!C20 | D6: ='2. IS'!D20 | E6: ='2. IS'!E20 | F6: ='2. IS'!F20 | G6: ='2. IS'!G20 | H6: ='2. IS'!H20
B7: Depreciation and Amortization | C7: 427 | D7: 456 | E7: 546 | F7: 662 | G7: 667 | H7: 1137
B8: Stock-Based Compensation | C8: 0 | D8: 0 | E8: 0 | F8: 0 | G8: 0 | H8: 6
B9: Changes in Operating Assets and Liabilities | C9: -221 | D9: -160 | E9: -146 | F9: -358 | G9: -383 | H9: -148
B10: Cash from Operations | C10: 838 | D10: 1283 | E10: 1403 | F10: 1717 | G10: 1927 | H10: 4179
B12: INVERSIÓN
B13: Capital Expenditures | C13: -709 | D13: -737 | E13: -805 | F13: -869 | G13: -989 | H13: -1522
B14: Other Investing Activities | C14: 9 | D14: -63 | E14: -45 | F14: -31 | G14: -211 | H14: 22
B15: Cash from Investing | C15: -700 | D15: -800 | E15: -850 | F15: -900 | G15: -1200 | H15: -1500
B17: FINANCIAMIENTO
B18: Repurchases of Common Stock | C18: -130 | D18: -231 | E18: -397 | F18: -461 | G18: -581 | H18: -1341
B19: Dividends Paid | C19: -208 | D19: -160 | E19: -250 | F19: -329 | G19: -440 | H19: -1059
B20: Net Debt Issuance / Other Financing | C20: 438 | D20: -109 | E20: 47 | F20: 90 | G20: 221 | H20: -400
B21: Cash from Financing | C21: -200 | D21: -500 | E21: -600 | F21: -700 | G21: -800 | H21: -2800
B23: Net Change in Cash | C23: =C10+C15+C21 | D23: =D10+D15+D21 | E23: =E10+E15+E21 | F23: =F10+F15+F21 | G23: =G10+G15+G21 | H23: =H10+H15+H21
B25: Free Cash Flow | C25: =C10+C13 | D25: =D10+D13 | E25: =E10+E13 | F25: =F10+F13 | G25: =G10+G13 | H25: =H10+H13
B27: Source: Ferrari 20-F cash flow statements + FY2025 Press Release | DCE Holdings | EUR Millions. Note: 2025 CFO of €4.2B reflects large working capital release.

Sheet 5. Health
B2: HEALTH CHECK — Ferrari N.V. (NYSE: RACE) | DCE Holdings
B3: Sector: Consumer Discretionary / Apparel & Luxury (Bloque A) | 3-band PASS / MONITOR / FAIL
B4: METRIC | C4: Value | D4: Pass | E4: Monitor | F4: Fail | G4: Direction | H4: Status | I4: Note
B5: SOLIDEZ FINANCIERA
B6: Total Debt / Equity | C6: ='3. BS'!H44/'3. BS'!H38 | D6: <0.5x | E6: 0.5–1.0x | F6: >1.0x | G6: lower_better | H6: =IF(C6<=J6,"PASS",IF(C6<=K6,"MONITOR","FAIL")) | I6: Healthy capital structure | J6: 0.5 | K6: 1
B7: Net Debt / EBITDA | C7: ='3. BS'!H45/'2. IS'!H24 | D7: <2x | E7: 2–3x | F7: >3x | G7: lower_better | H7: =IF(C7<=J7,"PASS",IF(C7<=K7,"MONITOR","FAIL")) | I7: Leverage manageable | J7: 2 | K7: 3
B8: Current Ratio | C8: ='3. BS'!H11/'3. BS'!H27 | D8: >1.5x | E8: 1.0–1.5x | F8: <1.0x | G8: higher_better | H8: =IF(C8>=J8,"PASS",IF(C8>=K8,"MONITOR","FAIL")) | I8: Liquidez corto plazo | J8: 1.5 | K8: 1
B9: Interest Coverage (EBIT/Int) | C9: ='2. IS'!H16/'2. IS'!H17 | D9: >5x | E9: 2–5x | F9: <2x | G9: higher_better | H9: =IF(C9>=J9,"PASS",IF(C9>=K9,"MONITOR","FAIL")) | I9: Capacidad pago intereses | J9: 5 | K9: 2
B11: RENTABILIDAD
B12: Operating Margin | C12: ='2. IS'!H16/'2. IS'!H5 | D12: >15% | E12: 10–15% | F12: <10% | G12: higher_better | H12: =IF(C12>=J12,"PASS",IF(C12>=K12,"MONITOR","FAIL")) | I12: Margen operativo reportado | J12: 0.15 | K12: 0.1
B13: FCF Margin | C13: ='4. CF'!H25/'2. IS'!H5 | D13: >10% | E13: 7–10% | F13: <7% | G13: higher_better | H13: =IF(C13>=J13,"PASS",IF(C13>=K13,"MONITOR","FAIL")) | I13: Conversión a FCF | J13: 0.1 | K13: 0.07
B14: ROIC | C14: =IFERROR('11. ROIC'!H17,0) | D14: >15% | E14: 10–15% | F14: <10% | G14: higher_better | H14: =IF(ISTEXT('11. ROIC'!H17),"N/M",IF(C14>=J14,"PASS",IF(C14>=K14,"MONITOR","FAIL"))) | I14: Return on Invested Capital (Sec 1) | J14: 0.15 | K14: 0.1
B15: ROIC − WACC (spread) | C15: =IF(ISTEXT('11. ROIC'!H17),"N/M",'11. ROIC'!H17-'10. EPV'!C15) | D15: >5pp | E15: 0–5pp | F15: <0pp | G15: higher_better | H15: =IF(ISTEXT(C15),"N/M",IF(C15>=J15,"PASS",IF(C15>=K15,"MONITOR","FAIL"))) | I15: Creación de valor sobre WACC | J15: 0.05 | K15: 0
B17: CRECIMIENTO
B18: Revenue CAGR 5yr | C18: =('2. IS'!H5/'2. IS'!C5)^(1/5)-1 | D18: >10% | E18: 5–10% | F18: <5% | G18: higher_better | H18: =IF(C18>=J18,"PASS",IF(C18>=K18,"MONITOR","FAIL")) | I18: FY2020 → FY2025 | J18: 0.1 | K18: 0.05
B19: EBITDA Growth YoY | C19: ='2. IS'!H24/'2. IS'!G24-1 | D19: >5% | E19: 0–5% | F19: <0% | G19: higher_better | H19: =IF(C19>=J19,"PASS",IF(C19>=K19,"MONITOR","FAIL")) | I19: FY2024 → FY2025 | J19: 0.05 | K19: 0
B20: FCF CAGR 3yr | C20: =('4. CF'!H25/'4. CF'!E25)^(1/3)-1 | D20: >5% | E20: 0–5% | F20: <0% | G20: higher_better | H20: =IF(C20>=J20,"PASS",IF(C20>=K20,"MONITOR","FAIL")) | I20: FY2022 → FY2025 (incl. €2.6Bn FY25 boost) | J20: 0.05 | K20: 0
B22: ESPECÍFICOS — APPAREL / LUXURY (Bloque A)
B23: Gross Margin | C23: =('2. IS'!H5-'2. IS'!H6)/'2. IS'!H5 | D23: >50% | E23: 40–50% | F23: <40% | G23: higher_better | H23: =IF(C23>=J23,"PASS",IF(C23>=K23,"MONITOR","FAIL")) | I23: Premium pricing power | J23: 0.5 | K23: 0.4
B24: Inventory Days | C24: ='3. BS'!H9/'2. IS'!H6*365 | D24: <120 | E24: 120–180 | F24: >180 | G24: lower_better | H24: =IF(C24<=J24,"PASS",IF(C24<=K24,"MONITOR","FAIL")) | I24: Production/inventory discipline | J24: 120 | K24: 180
B25: CapEx % Revenue | C25: =-'4. CF'!H13/'2. IS'!H5 | D25: <8% | E25: 8–12% | F25: >12% | G25: lower_better | H25: =IF(C25<=J25,"PASS",IF(C25<=K25,"MONITOR","FAIL")) | I25: FY25 elevated (e-building) | J25: 0.08 | K25: 0.12
B26: SBC % Revenue | C26: ='2. IS'!H32/'2. IS'!H5 | D26: <2% | E26: 2–4% | F26: >4% | G26: lower_better | H26: =IF(C26<=J26,"PASS",IF(C26<=K26,"MONITOR","FAIL")) | I26: SBC ya en OpEx (DP#5) | J26: 0.02 | K26: 0.04
B28: Total PASS / MONITOR / FAIL | C28: =COUNTIF(H6:H26,"PASS") | D28: =COUNTIF(H6:H26,"MONITOR") | E28: =COUNTIF(H6:H26,"FAIL")
B30: Source: Ferrari 20-F + DCE Health Framework v4.2 (Bloque A Apparel/Luxury) | DCE Holdings | 22-May-2026

Sheet 6. S&M Cap
B2: CAPITALIZACIÓN DE MARKETING (proxy S&M) — Ferrari N.V. | Vida Útil: 7 Años
B3: Source: Ferrari 20-F SG&A line | 70% of SG&A as proxy for brand/F1 marketing | EUR Millions
B5: PARÁMETROS
B6: Vida Útil (años) | C6: 7
B7: Proxy S&M | C7: 70% of SG&A (Ferrari does not break out marketing separately; luxury/F1 brand build)
B8: Nota SBC | C8: SBC ~€6M in 2025; already inside Personnel/SG&A; no separate add-back
B9: Historical estimate FY2019, FY2020, FY2018 (for lookback) | C9: FY2018 €326M, FY2019 €350M (estimated for prior cohorts within 7y window)
B11: GASTO EN MARKETING POR AÑO — INPUTS
B12: CONCEPTO (€M) | C12: FY 2021 | D12: FY 2022 | E12: FY 2023 | F12: FY 2024 | G12: FY 2025
B13: Marketing Expense (=70% × SG&A) | C13: =0.7*'2. IS'!D10 | D13: =0.7*'2. IS'!E10 | E13: =0.7*'2. IS'!F10 | F13: =0.7*'2. IS'!G10 | G13: =0.7*'2. IS'!H10
B14: Source: Ferrari 20-F SG&A FY2021-2025; 70% of SG&A approximates brand + F1 + dealer marketing
B16: MATRIZ DE AMORTIZACIÓN POR COHORTE
B17: Cohorte \ Año Modelo | C17: FY 2021 | D17: FY 2022 | E17: FY 2023 | F17: FY 2024 | G17: FY 2025
B18: FY 2021 | C18: =C13/$C$6 | D18: =C13/$C$6 | E18: =C13/$C$6 | F18: =C13/$C$6 | G18: =C13/$C$6
B19: FY 2022 | C19: - | D19: =D13/$C$6 | E19: =D13/$C$6 | F19: =D13/$C$6 | G19: =D13/$C$6
B20: FY 2023 | C20: - | D20: - | E20: =E13/$C$6 | F20: =E13/$C$6 | G20: =E13/$C$6
B21: FY 2024 | C21: - | D21: - | E21: - | F21: =F13/$C$6 | G21: =F13/$C$6
B22: FY 2025 | C22: - | D22: - | E22: - | F22: - | G22: =G13/$C$6 | H22: Hist Mktg (€M)
B23: FY 2019 (est.) | C23: =$H$23/$C$6 | D23: =$H$23/$C$6 | E23: =$H$23/$C$6 | F23: =$H$23/$C$6 | G23: =$H$23/$C$6 | H23: 350
B24: FY 2020 (est.) | C24: =$H$24/$C$6 | D24: =$H$24/$C$6 | E24: =$H$24/$C$6 | F24: =$H$24/$C$6 | G24: =$H$24/$C$6 | H24: 235
B26: Economic Amortization (Total) | C26: =SUM(C18:C24) | D26: =SUM(D18:D24) | E26: =SUM(E18:E24) | F26: =SUM(F18:F24) | G26: =SUM(G18:G24)
B28: RESUMEN S&M CAPITALIZACIÓN
B29: CONCEPTO | C29: FY 2021 | D29: FY 2022 | E29: FY 2023 | F29: FY 2024 | G29: FY 2025
B30: Gasto Marketing | C30: =C13 | D30: =D13 | E30: =E13 | F30: =F13 | G30: =G13
B31: Economic Amortization | C31: =C26 | D31: =D26 | E31: =E26 | F31: =F26 | G31: =G26
B32: S&M Growth Expense | C32: =C30-C31 | D32: =D30-D31 | E32: =E30-E31 | F32: =F30-F31 | G32: =G30-G31
B33: S&M Asset (Unamortized Balance) | C33: =(5/$C$6)*$H$23+(6/$C$6)*$H$24+(7/$C$6)*$C$13 | D33: =(4/$C$6)*$H$23+(5/$C$6)*$H$24+(6/$C$6)*$C$13+(7/$C$6)*$D$13 | E33: =(3/$C$6)*$H$23+(4/$C$6)*$H$24+(5/$C$6)*$C$13+(6/$C$6)*$D$13+(7/$C$6)*$E$13 | F33: =(2/$C$6)*$H$23+(3/$C$6)*$H$24+(4/$C$6)*$C$13+(5/$C$6)*$D$13+(6/$C$6)*$E$13+(7/$C$6)*$F$13 | G33: =(1/$C$6)*$H$23+(2/$C$6)*$H$24+(3/$C$6)*$C$13+(4/$C$6)*$D$13+(5/$C$6)*$E$13+(6/$C$6)*$F$13+(7/$C$6)*$G$13
B34: Growth Expense % of Marketing | C34: =C32/C30 | D34: =D32/D30 | E34: =E32/E30 | F34: =F32/F30 | G34: =G32/G30
B36: Source: Ferrari 20-F SG&A FY2021-2025 (70% proxy). Historical cohorts FY2019-2020 estimated. DCE Holdings.

Sheet 7. R&D Cap
B2: CAPITALIZACIÓN DE R&D — Ferrari N.V. | Vida Útil: 5 Años
B3: Source: Ferrari 20-F R&D line | Engine + Hybrid + EV tech | EUR Millions
B5: PARÁMETROS
B6: Vida Útil (años) | C6: 5
B7: Proxy R&D | C7: Reported R&D expense (Ferrari discloses R&D as separate line in 20-F)
B8: Nota | C8: R&D includes engine/hybrid/EV tech and racing-related innovation. 5y reflects tech cycles + EV reset.
B11: GASTO EN R&D POR AÑO — INPUTS
B12: CONCEPTO (€M) | C12: FY 2021 | D12: FY 2022 | E12: FY 2023 | F12: FY 2024 | G12: FY 2025
B13: R&D Expense | C13: ='2. IS'!D11 | D13: ='2. IS'!E11 | E13: ='2. IS'!F11 | F13: ='2. IS'!G11 | G13: ='2. IS'!H11
B16: MATRIZ DE AMORTIZACIÓN POR COHORTE
B17: Cohorte \ Año Modelo | C17: FY 2021 | D17: FY 2022 | E17: FY 2023 | F17: FY 2024 | G17: FY 2025
B18: FY 2021 | C18: =C13/$C$6 | D18: =C13/$C$6 | E18: =C13/$C$6 | F18: =C13/$C$6 | G18: =C13/$C$6
B19: FY 2022 | C19: - | D19: =D13/$C$6 | E19: =D13/$C$6 | F19: =D13/$C$6 | G19: =D13/$C$6
B20: FY 2023 | C20: - | D20: - | E20: =E13/$C$6 | F20: =E13/$C$6 | G20: =E13/$C$6
B21: FY 2024 | C21: - | D21: - | E21: - | F21: =F13/$C$6 | G21: =F13/$C$6
B22: FY 2025 | C22: - | D22: - | E22: - | F22: - | G22: =G13/$C$6 | H22: Hist R&D (€M)
B23: FY 2019 (est.) | C23: =$H$23/$C$6 | D23: =$H$23/$C$6 | E23: =$H$23/$C$6 | F23: - | G23: - | H23: 700
B24: FY 2020 (est.) | C24: =$H$24/$C$6 | D24: =$H$24/$C$6 | E24: =$H$24/$C$6 | F24: =$H$24/$C$6 | G24: - | H24: 707
B26: Economic Amortization (Total) | C26: =SUM(C18:C24) | D26: =SUM(D18:D24) | E26: =SUM(E18:E24) | F26: =SUM(F18:F24) | G26: =SUM(G18:G24)
B28: RESUMEN R&D CAPITALIZACIÓN
B29: CONCEPTO | C29: FY 2021 | D29: FY 2022 | E29: FY 2023 | F29: FY 2024 | G29: FY 2025
B30: R&D Expense | C30: =C13 | D30: =D13 | E30: =E13 | F30: =F13 | G30: =G13
B31: Economic Amortization | C31: =C26 | D31: =D26 | E31: =E26 | F31: =F26 | G31: =G26
B32: R&D Growth Expense | C32: =C30-C31 | D32: =D30-D31 | E32: =E30-E31 | F32: =F30-F31 | G32: =G30-G31
B33: R&D Asset (Unamortized Balance) | C33: =(3/$C$6)*$H$23+(4/$C$6)*$H$24+(5/$C$6)*$C$13 | D33: =(2/$C$6)*$H$23+(3/$C$6)*$H$24+(4/$C$6)*$C$13+(5/$C$6)*$D$13 | E33: =(1/$C$6)*$H$23+(2/$C$6)*$H$24+(3/$C$6)*$C$13+(4/$C$6)*$D$13+(5/$C$6)*$E$13 | F33: =(1/$C$6)*$H$24+(2/$C$6)*$C$13+(3/$C$6)*$D$13+(4/$C$6)*$E$13+(5/$C$6)*$F$13 | G33: =(1/$C$6)*$C$13+(2/$C$6)*$D$13+(3/$C$6)*$E$13+(4/$C$6)*$F$13+(5/$C$6)*$G$13
B34: Growth Expense % of R&D | C34: =C32/C30 | D34: =D32/D30 | E34: =E32/E30 | F34: =F32/F30 | G34: =G32/G30
B36: Source: Ferrari 20-F R&D line (engine + hybrid + EV tech). DCE Holdings.

Sheet 8. RV
B2: VALOR DE REPRODUCCIÓN — Ferrari N.V. | DCE Holdings
B3: Reproduction Value: costo estimado de replicar los activos de Ferrari desde cero (FY 2025 base)
B5: CONCEPTO | C5: Valor Libro (€M) | D5: % Ajuste | E5: Reproduction Cost (€M) | F5: Método / Justificación
B6: ACTIVOS TANGIBLES (del balance, FY 2025)
B7: Cash and Cash Equivalents | C7: ='3. BS'!H6 | D7: 1 | E7: =C7*D7 | F7: 100% — líquido
B8: Short-Term Investments | C8: ='3. BS'!H7-'3. BS'!H6 | D8: 1 | E8: =C8*D8 | F8: 100% — marketable securities at fair value
B9: Trade Receivables | C9: ='3. BS'!H8 | D9: 0.97 | E9: =C9*D9 | F9: 97% — small allowance for doubtful accounts (luxury client base low-risk)
B10: Inventories | C10: ='3. BS'!H9 | D10: 0.95 | E10: =C10*D10 | F10: 95% — partially built supercars, parts inventory; small obsolescence risk
B11: Other Current Assets | C11: ='3. BS'!H10 | D11: 0.9 | E11: =C11*D11 | F11: 90% — prepaid + tax receivables
B12: PP&E Net (Maranello plant) | C12: ='3. BS'!H13 | D12: 1.15 | E12: =C12*D12 | F12: 115% — replacement cost > book due to inflation in industrial construction (factory build cost > depreciated book)
B13: Long-Term Financial Services Receivables | C13: ='3. BS'!H16 | D13: 0.95 | E13: =C13*D13 | F13: 95% — Ferrari Financial Services loan book
B14: Subtotal Tangibles | E14: =SUM(E7:E13)
B16: ACTIVOS INTANGIBLES (reconstruir desde cero)
B17: Brand / Heritage (80-year compounded) | C17: 1638 | D17: =E17/C17 | E17: =3000 | F17: Mktg accumulated 10y × 60% efficiency factor + irreplaceable 80y heritage premium. Reproduction proxy €3,000M.
B18: F1 Racing Operations (only constructor since 1950) | C18: 0 | D18: N/A | E18: =1680 | F18: F1 budget €350M/y × 8y × 60% efficiency = €1,680M. Cannot be replicated (only Ferrari has continuous F1 since 1950).
B19: Customer Relationships (HNW waitlist, Icona/hypercar) | C19: 0 | D19: N/A | E19: =500 | F19: Invitation-only Icona/hypercar list; Tailor Made S&M × 5y + relationship-building costs. Proxy €500M.
B20: Dealer Network (167+ exclusive dealers globally) | C20: 0 | D20: N/A | E20: =300 | F20: Cost to recreate exclusive global dealer network (real estate, certifications, relationships). Proxy €300M.
B21: S&M Asset (Unamortized; capitalized model) | C21: ='6. S&M Cap'!G33 | D21: 1 | E21: ='6. S&M Cap'!G33 | F21: Link to S&M Cap sheet (FY2025 column)
B22: R&D Asset (Unamortized; capitalized model) | C22: ='7. R&D Cap'!G33 | D22: 1 | E22: ='7. R&D Cap'!G33 | F22: Link to R&D Cap sheet (FY2025 column)
B23: Manufacturing Know-how (Maranello tacit) | C23: 0 | D23: N/A | E23: =500 | F23: Tacit engine/hybrid production knowledge. Proxy: 5% of PP&E×book × 5y. ~€500M.
B24: Goodwill (per DP12) | C24: ='3. BS'!H14 | D24: 0 | E24: =C24*D24 | F24: 0% — reconstructed component-by-component above; including would be double counting.
B25: Subtotal Intangibles (Reproduction) | E25: =SUM(E17:E24)
B27: OTROS ACTIVOS
B28: DTA (per DP14) | C28: ='3. BS'!H17 | D28: 0.8 | E28: =C28*D28 | F28: 80% — Ferrari consistently profitable; high probability of realization.
B29: Other Non-Current Assets | C29: ='3. BS'!H18 | D29: 0.7 | E29: =C29*D29 | F29: 70% — financial assets + ROU + other.
B30: Subtotal Otros | E30: =SUM(E28:E29)
B32: Total Activos (Reproduction) | E32: =E14+E25+E30
B34: PASIVOS (FY 2025, 100% contractual)
B35: Accounts Payable | C35: ='3. BS'!H23 | D35: 1 | E35: =C35*D35 | F35: Contractual
B36: Short-Term Debt | C36: ='3. BS'!H24 | D36: 1 | E36: =C36*D36 | F36: Contractual
B37: Other Current Liabilities | C37: ='3. BS'!H25+'3. BS'!H26 | D37: 1 | E37: =C37*D37 | F37: Contractual
B38: Long-Term Debt | C38: ='3. BS'!H29 | D38: 1 | E38: =C38*D38 | F38: Contractual
B39: Lease Liabilities | C39: ='3. BS'!H30 | D39: 1 | E39: =C39*D39 | F39: IFRS 16
B40: Long-Term Provisions | C40: ='3. BS'!H31 | D40: 1 | E40: =C40*D40 | F40: Contractual
B41: Deferred Tax Liabilities | C41: ='3. BS'!H32 | D41: 1 | E41: =C41*D41 | F41: Contractual
B42: Other Non-Current Liabilities | C42: ='3. BS'!H33 | D42: 1 | E42: =C42*D42 | F42: Contractual
B43: Total Pasivos | E43: =SUM(E35:E42)
B45: CÁLCULO REPRODUCTION VALUE
B46: Total Activos (Reproduction) | E46: =E32
B47: (−) Total Pasivos | E47: =-E43
...

Sheet 9. NOPAT
B2: NOPAT AJUSTADO — Ferrari N.V. | DCE Holdings
B3: Normalización ventana FY2022-2025 (excluye COVID 2020-2021). Tax 20.5% normalizado. Margen Op Normalizado: 27% (mediana 4y).
B4: CONCEPTO (€M) | C4: Parámetro | D4: FY 2020 | E4: FY 2021 | F4: FY 2022 | G4: FY 2023 | H4: FY 2024 | I4: FY 2025 | J4: Normalizado
B5: PARÁMETROS
B6: Tax Rate Normalizado | C6: 0.205 | D6: DP #8: Median FY2021-2025 ETR (20.0/20.2/21.5/19.2/22.5 → median 20.5%)
B7: Normalization Items | C7: None material — Ferrari has very clean P&L (DP #7)
B8: Ventana Normalización | C8: Last 4 FYs (2022-2025) — exclude COVID 2020-2021 (DP #6)
B9: Revenue Base (No-Growth Scenario, €M) | C9: 7146 | D9: Default = FY2025 Revenue €7,146M. No cyclical distortion — luxury demand robust.
B10: Margen Op Normalizado | C10: 0.27 | D10: Mediana 4y clean margin (2022-2025): 24/27/28/29.5 → 27.5%. Selected 27% (conservative vs LTM 29.5%).
B12: INGRESOS
B13: Revenue | D13: ='2. IS'!C5 | E13: ='2. IS'!D5 | F13: ='2. IS'!E5 | G13: ='2. IS'!F5 | H13: ='2. IS'!G5 | I13: ='2. IS'!H5 | J13: =C9
B15: CÁLCULO — UTILIDAD OPERATIVA AJUSTADA
B16: Utilidad Operativa Reportada | D16: ='2. IS'!C16 | E16: ='2. IS'!D16 | F16: ='2. IS'!E16 | G16: ='2. IS'!F16 | H16: ='2. IS'!G16 | I16: ='2. IS'!H16 | J16: =I16
B17: (+) Normalization Adjustments | D17: 0 | E17: 0 | F17: 0 | G17: 0 | H17: 0 | I17: 0 | J17: 0
B18: Utilidad Operativa Limpia | D18: =D16+D17 | E18: =E16+E17 | F18: =F16+F17 | G18: =G16+G17 | H18: =H16+H17 | I18: =I16+I17 | J18: =C9*C10
B19: (+) Marketing add-back (TOTAL = 70% of SG&A) | D19: =0.7*'2. IS'!C10 | E19: =0.7*'2. IS'!D10 | F19: =0.7*'2. IS'!E10 | G19: =0.7*'2. IS'!F10 | H19: =0.7*'2. IS'!G10 | I19: =0.7*'2. IS'!H10 | J19: =I19
B20: (−) Economic Amortization S&M (Maintenance) | D20: 0 | E20: =-'6. S&M Cap'!C31 | F20: =-'6. S&M Cap'!D31 | G20: =-'6. S&M Cap'!E31 | H20: =-'6. S&M Cap'!F31 | I20: =-'6. S&M Cap'!G31 | J20: =I20
B21: S&M Growth Expense (referencia — no reduce NOPAT) | D21: 0 | E21: ='6. S&M Cap'!C32 | F21: ='6. S&M Cap'!D32 | G21: ='6. S&M Cap'!E32 | H21: ='6. S&M Cap'!F32 | I21: ='6. S&M Cap'!G32 | J21: =I21
B22: (+) R&D add-back (TOTAL) | D22: ='2. IS'!C11 | E22: ='2. IS'!D11 | F22: ='2. IS'!E11 | G22: ='2. IS'!F11 | H22: ='2. IS'!G11 | I22: ='2. IS'!H11 | J22: =I22
B23: (−) Economic Amortization R&D (Maintenance) | D23: 0 | E23: =-'7. R&D Cap'!C31 | F23: =-'7. R&D Cap'!D31 | G23: =-'7. R&D Cap'!E31 | H23: =-'7. R&D Cap'!F31 | I23: =-'7. R&D Cap'!G31 | J23: =I23
B24: R&D Growth Expense (referencia — no reduce NOPAT) | D24: 0 | E24: ='7. R&D Cap'!C32 | F24: ='7. R&D Cap'!D32 | G24: ='7. R&D Cap'!E32 | H24: ='7. R&D Cap'!F32 | I24: ='7. R&D Cap'!G32 | J24: =I24
B25: Utilidad Operativa Ajustada (pre-tax) | D25: =D18+D19+D20+D22+D23 | E25: =E18+E19+E20+E22+E23 | F25: =F18+F19+F20+F22+F23 | G25: =G18+G19+G20+G22+G23 | H25: =H18+H19+H20+H22+H23 | I25: =I18+I19+I20+I22+I23 | J25: =J18+J19+J20+J22+J23
B26: × (1 − Tax Rate Normalizado) | D26: =1-$C$6 | E26: =1-$C$6 | F26: =1-$C$6 | G26: =1-$C$6 | H26: =1-$C$6 | I26: =1-$C$6 | J26: =1-$C$6
B27: NOPAT Ajustado | D27: =D25*D26 | E27: =E25*E26 | F27: =F25*F26 | G27: =G25*G26 | H27: =H25*H26 | I27: =I25*I26 | J27: =J25*J26
B29: MÉTRICAS
B30: Margen Op Limpio (OpInc Clean / Revenue) | D30: =D18/D13 | E30: =E18/E13 | F30: =F18/F13 | G30: =G18/G13 | H30: =H18/H13 | I30: =I18/I13 | J30: =C10
B31: NOPAT Margin % | D31: =D27/D13 | E31: =E27/E13 | F31: =F27/F13 | G31: =G27/G13 | H31: =H27/H13 | I31: =I27/I13 | J31: =J27/J13
B32: NOPAT YoY Growth % | D32: N/A | E32: =(E27-D27)/ABS(D27) | F32: =(F27-E27)/ABS(E27) | G32: =(G27-F27)/ABS(F27) | H32: =(H27-G27)/ABS(G27) | I32: =(I27-H27)/ABS(H27)
B34: REFERENCIAS (para EPV)
B35: D&A (Full Company) | D35: ='2. IS'!C23 | E35: ='2. IS'!D23 | F35: ='2. IS'!E23 | G35: ='2. IS'!F23 | H35: ='2. IS'!G23 | I35: ='2. IS'!H23 | J35: =I35
B36: CapEx | D36: =-'4. CF'!C13 | E36: =-'4. CF'!D13 | F36: =-'4. CF'!E13 | G36: =-'4. CF'!F13 | H36: =-'4. CF'!G13 | I36: =-'4. CF'!H13 | J36: =I36
B38: SBC Rule (DP #5): SBC ~€6M en 2025 ya está dentro de SG&A/Personnel. NO requiere add-back en NOPAT. Confirmado en footnote 20-F.
B40: Source: Ferrari 20-F + S&M/R&D Cap sheets | EUR Millions | DCE Holdings

Sheet 10. EPV
B2: EPV — EARNINGS POWER VALUE — Ferrari N.V. (NYSE: RACE) | DCE Holdings
B3: Valor de la capacidad de generación de utilidades en escenario zero-growth | WACC ~ 8%
B5: SECCIÓN 1: WACC
B6: Risk-Free Rate (Rf) | C6: 0.025 | D6: DP#11 — Bund 10Y proxy
B7: Beta | C7: 1 | D7: DP#11 — luxury cyclicality moderate
B8: Equity Risk Premium (ERP) | C8: 0.055 | D8: DP#11 — Damodaran ERP Europe
B9: Cost of Equity (Ke) | C9: =C6+C7*C8 | D9: Ke = Rf + Beta × ERP
B10: Cost of Debt pre-tax (Kd) | C10: 0.035 | D10: DP#11 — Ferrari IG corporate bond yield
B11: Tax Rate | C11: ='9. NOPAT'!C6 | D11: Link a NOPAT (DP#8 = 20.5%)
B12: Cost of Debt post-tax (Kd_aftertax) | C12: =C10*(1-C11) | D12: Kd × (1 − Tax)
B13: E / (D+E) | C13: ='1. Overview'!C19/('1. Overview'!C19+'1. Overview'!C20+'1. Overview'!C21) | D13: Equity weight (mkt)
B14: D / (D+E) | C14: =1-C13 | D14: Debt weight (mkt)
B15: WACC | C15: =C9*C13+C12*C14 | D15: WACC = Ke·E/(D+E) + Kd_after·D/(D+E)
B17: SECCIÓN 2: CÁLCULO EPV
B18: Adj. Operating Income Normalizado (pre-tax) | C18: ='9. NOPAT'!J25 | D18: Link NOPAT J25 — UOA pre-tax norm.
B19: × (1 − Tax Rate) | C19: =1-C11
B20: NOPAT Normalizado | C20: =C18*C19 | D20: UOA × (1 − Tax) — link J27 (cross-check)
B21: (+) D&A (full company) | C21: ='2. IS'!H23 | D21: Non-cash addback
B22: (−) Maintenance CapEx (Zero-Growth) | C22: 700 | D22: Default = D&A (€662M); ajustado a €700M para mantenimiento real (e-building es growth)
B23: EPV Operaciones = (NOPAT + D&A − Maint CapEx) / WACC | C23: =(C20+C21-C22)/C15 | D23: Enterprise value of earnings power
B25: (+) Excess Cash (Cash + STI − €500M operating buffer) | C25: ='3. BS'!H7-500 | D25: DP#10: €500M buffer (≈7% revenue)
B26: (+) Non-Operating Assets (FS receivables, net) | C26: ='3. BS'!H16*0.5 | D26: DP#10: 50% of LT FS receivables (financing arm)
B27: (−) Total Debt | C27: =-'3. BS'!H44
B28: (−) Lease Liabilities | C28: =-'3. BS'!H30
B29: (−) Minority Interest | C29: 0 | D29: No minority interest reported
B30: EPV Equity (€M) | C30: =C23+C25+C26+C27+C28+C29
B31: Acciones Diluidas (M) | C31: ='2. IS'!H31
B32: EPV por Acción (€) | C32: =C30/C31
B34: SECCIÓN 3: BRIDGE EPV OPERACIONES → EQUITY EPV
B35: Precio Actual (€) | C35: ='1. Overview'!C17
B36: EPV / Acción (€) | C36: =C32
B37: Descuento / (Prima) = (EPV − Precio) / EPV | C37: =(C36-C35)/C36
B39: SENSIBILIDAD EPV / Acción — WACC (filas) × Margen Op Normalizado (cols)
B40: WACC \ Margen Op | C40: 0.23 | D40: 0.25 | E40: 0.27 | F40: 0.29 | G40: 0.31
B41: 0.07 | C41: =(('9. NOPAT'!$C$9*0.23*(1-$C$11)+$C$21-$C$22)/0.07+$C$25+$C$26+$C$27+$C$28+$C$29)/$C$31 | D41: =(('9. NOPAT'!$C$9*0.25*(1-$C$11)+$C$21-$C$22)/0.07+$C$25+$C$26+$C$27+$C$28+$C$29)/$C$31 | E41: =(('9. NOPAT'!$C$9*0.27*(1-$C$11)+$C$21-$C$22)/0.07+$C$25+$C$26+$C$27+$C$28+$C$29)/$C$31 | F41: =(('9. NOPAT'!$C$9*0.29*(1-$C$11)+$C$21-$C$22)/0.07+$C$25+$C$26+$C$27+$C$28+$C$29)/$C$31 | G41: =(('9. NOPAT'!$C$9*0.31*(1-$C$11)+$C$21-$C$22)/0.07+$C$25+$C$26+$C$27+$C$28+$C$29)/$C$31
B42: 0.075 | C42: =(('9. NOPAT'!$C$9*0.23*(1-$C$11)+$C$21-$C$22)/0.075+$C$25+$C$26+$C$27+$C$28+$C$29)/$C$31 | D42: =(('9. NOPAT'!$C$9*0.25*(1-$C$11)+$C$21-$C$22)/0.075+$C$25+$C$26+$C$27+$C$28+$C$29)/$C$31 | E42: =(('9. NOPAT'!$C$9*0.27*(1-$C$11)+$C$21-$C$22)/0.075+$C$25+$C$26+$C$27+$C$28+$C$29)/$C$31 | F42: =(('9. NOPAT'!$C$9*0.29*(1-$C$11)+$C$21-$C$22)/0.075+$C$25+$C$26+$C$27+$C$28+$C$29)/$C$31 | G42: =(('9. NOPAT'!$C$9*0.31*(1-$C$11)+$C$21-$C$22)/0.075+$C$25+$C$26+$C$27+$C$28+$C$29)/$C$31
B43: 0.08 | C43: =(('9. NOPAT'!$C$9*0.23*(1-$C$11)+$C$21-$C$22)/0.08+$C$25+$C$26+$C$27+$C$28+$C$29)/$C$31 | D43: =(('9. NOPAT'!$C$9*0.25*(1-$C$11)+$C$21-$C$22)/0.08+$C$25+$C$26+$C$27+$C$28+$C$29)/$C$31 | E43: =(('9. NOPAT'!$C$9*0.27*(1-$C$11)+$C$21-$C$22)/0.08+$C$25+$C$26+$C$27+$C$28+$C$29)/$C$31 | F43: =(('9. NOPAT'!$C$9*0.29*(1-$C$11)+$C$21-$C$22)/0.08+$C$25+$C$26+$C$27+$C$28+$C$29)/$C$31 | G43: =(('9. NOPAT'!$C$9*0.31*(1-$C$11)+$C$21-$C$22)/0.08+$C$25+$C$26+$C$27+$C$28+$C$29)/$C$31
B44: 0.085 | C44: =(('9. NOPAT'!$C$9*0.23*(1-$C$11)+$C$21-$C$22)/0.085+$C$25+$C$26+$C$27+$C$28+$C$29)/$C$31 | D44: =(('9. NOPAT'!$C$9*0.25*(1-$C$11)+$C$21-$C$22)/0.085+$C$25+$C$26+$C$27+$C$28+$C$29)/$C$31 | E44: =(('9. NOPAT'!$C$9*0.27*(1-$C$11)+$C$21-$C$22)/0.085+$C$25+$C$26+$C$27+$C$28+$C$29)/$C$31 | F44: =(('9. NOPAT'!$C$9*0.29*(1-$C$11)+$C$21-$C$22)/0.085+$C$25+$C$26+$C$27+$C$28+$C$29)/$C$31 | G44: =(('9. NOPAT'!$C$9*0.31*(1-$C$11)+$C$21-$C$22)/0.085+$C$25+$C$26+$C$27+$C$28+$C$29)/$C$31
B45: 0.09 | C45: =(('9. NOPAT'!$C$9*0.23*(1-$C$11)+$C$21-$C$22)/0.09+$C$25+$C$26+$C$27+$C$28+$C$29)/$C$31 | D45: =(('9. NOPAT'!$C$9*0.25*(1-$C$11)+$C$21-$C$22)/0.09+$C$25+$C$26+$C$27+$C$28+$C$29)/$C$31 | E45: =(('9. NOPAT'!$C$9*0.27*(1-$C$11)+$C$21-$C$22)/0.09+$C$25+$C$26+$C$27+$C$28+$C$29)/$C$31 | F45: =(('9. NOPAT'!$C$9*0.29*(1-$C$11)+$C$21-$C$22)/0.09+$C$25+$C$26+$C$27+$C$28+$C$29)/$C$31 | G45: =(('9. NOPAT'!$C$9*0.31*(1-$C$11)+$C$21-$C$22)/0.09+$C$25+$C$26+$C$27+$C$28+$C$29)/$C$31
B47: Source: NOPAT Normalizado + EPV formula | DCE Holdings | 22-May-2026

Sheet 11. ROIC
B2: ROIC — RETURN ON INVESTED CAPITAL — Ferrari N.V. (NYSE: RACE) | DCE Holdings
B3: 3 secciones: (1) ROIC Contable | (2) Marginal ROIC (Δ) | (3) Marginal Growth CapEx | N/M guard activado
B5: SECCIÓN 1: ROIC CONTABLE
B6: CONCEPTO (€M) | C6: FY 2020 | D6: FY 2021 | E6: FY 2022 | F6: FY 2023 | G6: FY 2024 | H6: FY 2025
B7: NOPAT Ajustado | C7: ='9. NOPAT'!D27 | D7: ='9. NOPAT'!E27 | E7: ='9. NOPAT'!F27 | F7: ='9. NOPAT'!G27 | G7: ='9. NOPAT'!H27 | H7: ='9. NOPAT'!I27
B9: CAPITAL INVERTIDO:
B10: Operating Working Capital | C10: =('3. BS'!C11-'3. BS'!C7)-('3. BS'!C27-'3. BS'!C24) | D10: =('3. BS'!D11-'3. BS'!D7)-('3. BS'!D27-'3. BS'!D24) | E10: =('3. BS'!E11-'3. BS'!E7)-('3. BS'!E27-'3. BS'!E24) | F10: =('3. BS'!F11-'3. BS'!F7)-('3. BS'!F27-'3. BS'!F24) | G10: =('3. BS'!G11-'3. BS'!G7)-('3. BS'!G27-'3. BS'!G24) | H10: =('3. BS'!H11-'3. BS'!H7)-('3. BS'!H27-'3. BS'!H24)
B11: (+) Property, Plant and Equipment, Net | C11: ='3. BS'!C13 | D11: ='3. BS'!D13 | E11: ='3. BS'!E13 | F11: ='3. BS'!F13 | G11: ='3. BS'!G13 | H11: ='3. BS'!H13
B12: (+) Other LT Operating Assets (intangibles ex-Goodwill) | C12: ='3. BS'!C15 | D12: ='3. BS'!D15 | E12: ='3. BS'!E15 | F12: ='3. BS'!F15 | G12: ='3. BS'!G15 | H12: ='3. BS'!H15
B13: (+) S&M Asset (Unamortized) | C13: 0 | D13: ='6. S&M Cap'!C33 | E13: ='6. S&M Cap'!D33 | F13: ='6. S&M Cap'!E33 | G13: ='6. S&M Cap'!F33 | H13: ='6. S&M Cap'!G33
B14: (+) R&D Asset (Unamortized) | C14: 0 | D14: ='7. R&D Cap'!C33 | E14: ='7. R&D Cap'!D33 | F14: ='7. R&D Cap'!E33 | G14: ='7. R&D Cap'!F33 | H14: ='7. R&D Cap'!G33
B15: Invested Capital (Total) | C15: =SUM(C10:C14) | D15: =SUM(D10:D14) | E15: =SUM(E10:E14) | F15: =SUM(F10:F14) | G15: =SUM(G10:G14) | H15: =SUM(H10:H14)
B17: ROIC (NOPAT / Invested Capital) | C17: =IF(C15<0,"N/M",IF(C15=0,0,C7/C15)) | D17: =IF(D15<0,"N/M",IF(D15=0,0,D7/D15)) | E17: =IF(E15<0,"N/M",IF(E15=0,0,E7/E15)) | F17: =IF(F15<0,"N/M",IF(F15=0,0,F7/F15)) | G17: =IF(G15<0,"N/M",IF(G15=0,0,G7/G15)) | H17: =IF(H15<0,"N/M",IF(H15=0,0,H7/H15))
B18: Spread vs WACC (ROIC − WACC) | C18: =IF(ISTEXT(C17),"N/M",C17-'10. EPV'!$C$15) | D18: =IF(ISTEXT(D17),"N/M",D17-'10. EPV'!$C$15) | E18: =IF(ISTEXT(E17),"N/M",E17-'10. EPV'!$C$15) | F18: =IF(ISTEXT(F17),"N/M",F17-'10. EPV'!$C$15) | G18: =IF(ISTEXT(G17),"N/M",G17-'10. EPV'!$C$15) | H18: =IF(ISTEXT(H17),"N/M",H17-'10. EPV'!$C$15)
B19: Reference: WACC | C19: ='10. EPV'!C15
B21: — — — — — — — — — — — — — — —
B23: SECCIÓN 2: MARGINAL ROIC (DELTAS)
B24: CONCEPTO (€M) | C24: FY 2020 | D24: FY 2021 | E24: FY 2022 | F24: FY 2023 | G24: FY 2024 | H24: FY 2025
B25: ΔNOPAT | C25: N/A | D25: =D7-C7 | E25: =E7-D7 | F25: =F7-E7 | G25: =G7-F7 | H25: =H7-G7
B26: ΔInvested Capital | C26: N/A | D26: =D15-C15 | E26: =E15-D15 | F26: =F15-E15 | G26: =G15-F15 | H26: =H15-G15
B27: Marginal ROIC = ΔNOPAT / ΔIC | C27: N/A | D27: =IF(D26<0,"N/M",IF(D26=0,0,D25/D26)) | E27: =IF(E26<0,"N/M",IF(E26=0,0,E25/E26)) | F27: =IF(F26<0,"N/M",IF(F26=0,0,F25/F26)) | G27: =IF(G26<0,"N/M",IF(G26=0,0,G25/G26)) | H27: =IF(H26<0,"N/M",IF(H26=0,0,H25/H26))
B29: — — — — — — — — — — — — — — —
B31: SECCIÓN 3: MARGINAL ROIC — ACCUMULATED GROWTH CAPEX
B32: CONCEPTO | C32: Ventana 2yr (FY24→25) | D32: Ventana 3yr (FY23→25) | E32: Ventana 4yr (FY22→25)
B33: Accumulated Growth CapEx (Σ Growth CapEx + S&M Growth + R&D Growth) | C33: =MAX(0,-'4. CF'!G13-'4. CF'!G7)+MAX(0,-'4. CF'!H13-'4. CF'!H7)+'6. S&M Cap'!F32+'6. S&M Cap'!G32+'7. R&D Cap'!F32+'7. R&D Cap'!G32 | D33: =MAX(0,-'4. CF'!F13-'4. CF'!F7)+MAX(0,-'4. CF'!G13-'4. CF'!G7)+MAX(0,-'4. CF'!H13-'4. CF'!H7)+'6. S&M Cap'!E32+'6. S&M Cap'!F32+'6. S&M Cap'!G32+'7. R&D Cap'!E32+'7. R&D Cap'!F32+'7. R&D Cap'!G32 | E33: =MAX(0,-'4. CF'!E13-'4. CF'!E7)+MAX(0,-'4. CF'!F13-'4. CF'!F7)+MAX(0,-'4. CF'!G13-'4. CF'!G7)+MAX(0,-'4. CF'!H13-'4. CF'!H7)+'6. S&M Cap'!D32+'6. S&M Cap'!E32+'6. S&M Cap'!F32+'6. S&M Cap'!G32+'7. R&D Cap'!D32+'7. R&D Cap'!E32+'7. R&D Cap'!F32+'7. R&D Cap'!G32
B34: ΔNOPAT (over same window) | C34: ='9. NOPAT'!I27-'9. NOPAT'!G27 | D34: ='9. NOPAT'!I27-'9. NOPAT'!F27 | E34: ='9. NOPAT'!I27-'9. NOPAT'!E27
B35: Marginal ROIC (Accumulated Growth) | C35: =IF(C33<=0,0,C34/C33) | D35: =IF(D33<=0,0,D34/D33) | E35: =IF(E33<=0,0,E34/E33)
B37: Comparación: Marginal ROIC estándar (FY24→25) vs Growth (2yr) | C37: =H27 | D37: =C35 | E37: =ABS(C37-D37)
B39: "N/M" = Not Meaningful (denominador negativo). "0%" = denominador cero o sin growth investment tracked.
B41: Source: NOPAT + BS + CF + Cap sheets | DCE Holdings Columbia Framework v4.2 | 22-May-2026

Sheet 12. Implied IRR
B2: IMPLIED IRR — Ferrari N.V. (NYSE: RACE) | DCE Holdings
B3: Enterprise-first 7-section return framework | Modigliani-Miller lever-up to equity | Hurdle = 12%
B5: SECCIÓN 1: ENTERPRISE VALUE
B6: Market Cap (€M) | C6: ='1. Overview'!C19 | D6: Precio × Acciones Diluidas
B7: (+) Total Deuda (€M) | C7: ='3. BS'!H44 | D7: ST Debt + LT Debt
B8: (+) Lease Liabilities (€M) | C8: ='3. BS'!H30 | D8: IFRS 16 leases (LT)
B9: (−) Cash & STI (€M) | C9: =-'3. BS'!H7 | D9: Total cash position
B10: Enterprise Value (€M) | C10: =C6+C7+C8+C9
B12: SECCIÓN 2: NOPAT AJUSTADO (Normalizado)
B13: NOPAT Ajustado Normalizado (€M) | C13: ='9. NOPAT'!J27 | D13: Link NOPAT J27
B14: NOPAT Multiple (EV / NOPAT) | C14: =C10/C13 | D14: Current multiple
B16: SECCIÓN 3: DISTRIBUCIONES
B17: Dividendos Pagados (FY2025, €M) | C17: =-'4. CF'!H19 | D17: Link CF H19 (absoluto)
B18: (+) Buybacks Sostenibles (DP#16, €M) | C18: 350 | D18: DP#16 = €350M/y (FY25 €1,341M era extraordinario)
B19: (+) Gasto por Intereses pre-tax (€M) | C19: ='2. IS'!H17 | D19: Link IS H17
B20: Total Distribuciones (€M) | C20: =C17+C18+C19
B21: Distribution Yield (Dist / EV) | C21: =C20/C10 | D21: Yield enterprise
B22: Distribution Rate (Dist / NOPAT) | C22: =C20/C13 | D22: Informational (puede exceder 100%)
B24: SECCIÓN 4: REINVERSIÓN (bottom-up)
B25: CapEx Total FY2025 (€M) | C25: =-'4. CF'!H13 | D25: Absoluto
B26: (−) Maintenance CapEx (≈ D&A) | C26: =-'10. EPV'!C22 | D26: Maintenance (deducción)
B27: Growth CapEx = MAX(0, CapEx − Maint) | C27: =MAX(0,C25+C26)
B28: (+) Δ Capital de Trabajo (est.) | C28: 0 | D28: Cambios neutralizados — incluido en CFO change
B29: (+) S&M Growth Expense | C29: =MAX(0,'6. S&M Cap'!G32) | D29: Link S&M G32
B30: (+) R&D Growth Expense | C30: =MAX(0,'7. R&D Cap'!G32) | D30: Link R&D G32
B31: Total Reinversión (€M) | C31: =C27+C28+C29+C30
B32: Reinvestment Rate (Reinv / NOPAT) | C32: =C31/C13
B34: SECCIÓN 5: CRECIMIENTO
B35: ROIC Seleccionado (3yr avg FY23-25) | C35: =AVERAGE(IFERROR(VALUE('11. ROIC'!F17),0),IFERROR(VALUE('11. ROIC'!G17),0),IFERROR(VALUE('11. ROIC'!H17),0)) | D35: Promedio últimos 3 FY (skip N/M)
B36: Crecimiento por Reinversión (ReinvRate × ROIC) | C36: =C32*C35
B37: Crecimiento Orgánico (DP#17) | C37: 0.02 | D37: DP#17 = 2% (luxury secular tailwinds)
B38: Total Crecimiento | C38: =C36+C37
B40: SECCIÓN 6: COMPORTAMIENTO DEL MÚLTIPLO
B41: NOPAT Multiple Actual (EV / NOPAT) | C41: =C14 | D41: Link Sección 2
B42: Investment Horizon (años) | C42: 5 | D42: Default 5 años
B43: Assumed Exit Multiple (DP#15) | C43: 32 | D43: DP#15 = 32× NOPAT (reversión a la media luxury)
B44: Multiple Expansion / (Contraction) | C44: =(C43-C41)/C41
B45: Impacto Anualizado del Múltiplo | C45: =(C43/C41)^(1/C42)-1
B47: SECCIÓN 7: RETORNOS Y MARGEN DE SEGURIDAD
B48: Retorno Total Enterprise (Dist Yield + Crec + Múlt.) | C48: =C21+C38+C45 | D48: Enterprise-level return
...

Sheet 13. Summary
B2: RESUMEN DE VALORACIÓN — Ferrari N.V. (NYSE: RACE) | DCE Holdings
B3: Fecha de Valoración: 22-May-2026 | Precio: €317.63 | EUR throughout
B5: ESCALERA COLUMBIA
B6: Reproduction Value / acción (€) | D6: ='8. RV'!E50 | E6: Greenwald asset value
B7: EPV / acción (€) | D7: ='10. EPV'!C32 | E7: Earnings Power Value
B8: Precio Actual (€) | D8: ='1. Overview'!C17 | E8: Mercado
B9: EPV / RV ratio | D9: =D7/D6 | E9: Franchise value (>1 ⇒ moat)
B10: Precio / EPV ratio | D10: =D8/D7 | E10: Premium / discount al EPV
B11: Implied IRR (Equity) | D11: ='12. Implied IRR'!C51 | E11: Retorno enterprise leverado
B12: Hurdle Rate | D12: ='12. Implied IRR'!C52 | E12: DP#11
B14: MARGEN DE SEGURIDAD
B15: MoS EPV = (EPV − Price) / EPV | D15: ='10. EPV'!C37
B16: MoS Implied IRR = Ret.Equity − Hurdle | D16: ='12. Implied IRR'!C53
B18: WACC / ROIC / SPREAD
B19: WACC | D19: ='10. EPV'!C15
B20: ROIC (FY 2025) | D20: =IF(ISTEXT('11. ROIC'!H17),"N/M",'11. ROIC'!H17) | E20: Link ROIC sheet H17
B21: Spread (ROIC − WACC) | D21: =IF(ISTEXT(D20),"N/M",D20-D19)
B22: FCF Margin | D22: ='4. CF'!H25/'2. IS'!H5
B23: Operating Margin | D23: ='2. IS'!H16/'2. IS'!H5
B25: DECLARACIÓN DE ESCALERA (Columbia framework):
B26: Caso 3 — FV (Franchise Value) > Precio. RV €70 < EPV €112 < Precio €318. Ni RV ni EPV justifican el precio, pero Implied IRR Equity 15.1% > Hurdle 12% confirma que el FV (que incorpora crecimiento por reinversión a ROIC 19% + pricing organic 2%) supera el precio con MoS +3.1pp. La tesis depende de la durabilidad del moat + reinversión exitosa.
B27: NOTAS:
B28: • Ferrari opera con un moat de marca y exclusividad: RV/EPV gap confirma que la mayor parte del valor reside en franchise (intangibles no replicables), no en activos físicos.
B29: • ROIC FY2025 supera ampliamente el WACC ~8%, validando que el reinvestment económico crea valor (Spread > 5pp).
B30: • Margen Op Normalizado al 27% refleja la mediana de la ventana FY2022-2025 — años post-COVID con pricing power consolidado.
B31: • El FY2025 muestra CFO atípicamente alto (€4,179M) por release de working capital; FCF normalizado se estima ~€1.5Bn/año.
B32: • Crecimiento Orgánico DP#17 = 2% conservador; pricing power en luxury permite ASP +5% real anual pero unidad cap (≤15k cars/yr) limita topline.
B34: RESUMEN DE DECISIONES (17 Decision Points)
B35: # | C35: Decision | D35: Value Chosen | E35: Rationale
B36: 1 | C36: S&M Proxy | D36: 70% of SG&A | E36: Ferrari no reporta línea S&M; 70% es proxy estándar luxury
B37: 2 | C37: R&D Capitalization | D37: Capitalize | E37: R&D tangible — motores, hybrid, autonomous
B38: 3 | C38: S&M Useful Life | D38: 7 años | E38: Brand luxury equity dura ~7y antes decay
B39: 4 | C39: R&D Useful Life | D39: 5 años | E39: Ciclo motor + ICE/hybrid platform
B40: 4b | C40: PIM Rates | D40: N/A (orgánico) | E40: Sin adquisiciones materiales recientes
B41: 5 | C41: SBC Treatment | D41: Already in OpEx | E41: SBC ~€6M FY25, dentro Personnel costs
B42: 6 | C42: Normalization Window | D42: FY2022-2025 | E42: Excluye COVID 2020-21 (margen aplastado)
B43: 7 | C43: Items to Normalize | D43: None material | E43: Sin litigios/restructuring relevantes
B44: 8 | C44: Normalized Tax Rate | D44: 20.5% | E44: Mediana últimos 4 FY; Italia 24% + benef. PEX
B45: 9 | C45: Lease Treatment | D45: No additional (IFRS 16) | E45: Leases ya reconocidos en BS
B46: 10 | C46: Non-Op Assets | D46: Excess cash > €500M + 50% FS receivables | E46: €500M buffer (~7% revenue) operativo
...

Sheet 14. Audit
B2: AUDIT LOG — Ferrari N.V. (NYSE: RACE) | DCE Holdings
B3: Row-by-row cross-reference checks | Formula audit | BS balance verification
B5: STRUCTURAL INTEGRITY
B6: # | C6: Check | D6: Result / Formula | E6: Expected
B7: 1 | C7: Sheets present (count = 14) | D7: =COUNTA(D8:D21)-COUNTBLANK(D8:D21) | E7: 14
B8: 2 | C8: Tab order: Overview is sheet 1 | D8: "PASS" | E8: PASS
B9: 3 | C9: EPV before ROIC (sheet 10 before 11) | D9: "PASS" | E9: PASS
B10: 4 | C10: Implied IRR before Summary (12 before 13) | D10: "PASS" | E10: PASS
B11: 5 | C11: Audit is last sheet (14) | D11: "PASS" | E11: PASS
B13: BALANCE SHEET BALANCE CHECK
B14: # | C14: Check | D14: Result | E14: Expected
B15: 1 | C15: Total Assets (FY 2025, €M) | D15: ='3. BS'!H20 | E15: 9,628
B16: 2 | C16: Total Liabilities + Equity (FY 2025, €M) | D16: ='3. BS'!H35+'3. BS'!H38 | E16: 9,628
B17: 3 | C17: BS Balance Difference = Assets − (L+E) | D17: ='3. BS'!H20-('3. BS'!H35+'3. BS'!H38) | E17: 0
B18: 4 | C18: BS Balance Status | D18: =IF(ABS(D17)<1,"PASS","FAIL") | E18: PASS
B20: CROSS-REFERENCE VALIDATION
B21: # | C21: Check | D21: Computed | E21: Expected (text)
B22: 1 | C22: Overview Market Cap = Price × Shares (€M) | D22: ='1. Overview'!C19 | E22: €56,632M (317.63 × 178.321)
B23: 2 | C23: Overview EV = MCap + Debt + Leases − Cash (€M) | D23: ='1. Overview'!C23 | E23: €58,206M aprox.
B24: 3 | C24: IS Revenue FY25 = €7,146M | D24: ='2. IS'!H5 | E24: 7,146
B25: 4 | C25: IS Net Income FY25 = €1,597M (IS authoritative) | D25: ='2. IS'!H20 | E25: 1,597
B26: 5 | C26: CF FCF FY25 = CFO + CapEx | D26: ='4. CF'!H25 | E26: 2,657 (CFO 4,179 + CapEx −1,522)
B27: 6 | C27: NOPAT Normalizado (€M) = Rev × Margin × (1−t) | D27: ='9. NOPAT'!J27 | E27: 1,533 (7,146 × 27% × 79.5%)
B28: 7 | C28: EPV/share Match Summary D7 | D28: ='13. Summary'!D7 | E28: Cross-link to EPV C32
B29: 8 | C29: RV/share Match Summary D6 | D29: ='13. Summary'!D6 | E29: Cross-link to RV E50
B30: 9 | C30: Implied IRR Equity (Summary D11) | D30: ='13. Summary'!D11 | E30: Modigliani-Miller leverage applied
B32: DECISION POINT CONSISTENCY (17 DPs)
B33: # | C33: DP Check | D33: Source Cell | E33: Value
B34: 3 | C34: S&M Useful Life (years) | D34: ='6. S&M Cap'!C6 | E34: 7
B35: 4 | C35: R&D Useful Life (years) | D35: ='7. R&D Cap'!C6 | E35: 5
B36: 8 | C36: Normalized Tax Rate | D36: ='9. NOPAT'!C6 | E36: 0.205
B37: 11 | C37: WACC | D37: ='10. EPV'!C15 | E37: 0.08
B38: 11 | C38: Risk-Free Rate | D38: ='10. EPV'!C6 | E38: 0.025
B39: 11 | C39: Beta | D39: ='10. EPV'!C7 | E39: 1
B40: 11 | C40: ERP | D40: ='10. EPV'!C8 | E40: 0.055
B41: 11 | C41: Kd pre-tax | D41: ='10. EPV'!C10 | E41: 0.035
B42: 15 | C42: Exit Multiple (NOPAT mult) | D42: ='12. Implied IRR'!C43 | E42: 32
B43: 16 | C43: Buybacks Sostenibles (€M) | D43: ='12. Implied IRR'!C18 | E43: 350
B44: 17 | C44: Crecimiento Orgánico | D44: ='12. Implied IRR'!C37 | E44: 0.02
B45: Hurdle | C45: Hurdle Rate | D45: ='12. Implied IRR'!C52 | E45: 0.12
...
