Workbook

Sheet 1. Overview
B2: COLUMBIA VALUATION MODEL — Lululemon Athletica Inc. | DCE Holdings
B3: Fecha de Valoración: 03-May-2026 | Precio: $137.70
B5: PERFIL DE LA EMPRESA
B6: Nombre | C6: Lululemon Athletica Inc.
B7: Ticker / Bolsa | C7: LULU / NASDAQ
B8: Sector (GICS) | C8: Consumer Discretionary / Apparel & Athleisure
B9: Modelo de Negocio | C9: Athleisure premium DTC + Wholesale + Retail
B10: Fiscal Year End | C10: ~1 de febrero (52/53 semanas)
B11: CEO | C11: Calvin McDonald
B12: Sede | C12: Vancouver, Canadá
B13: Empleados | C13: ~38,000
B14: Fecha de Valoración | C14: 03-May-2026
B16: DATOS DE MERCADO
B17: Precio Actual ($) | C17: 137.7 | D17: Cotización 03-May-2026
B18: Acciones Diluidas (M) | C18: 118.5 | D18: 10-K FY2025
B19: Market Cap ($M) | C19: =C17*C18 | D19: Precio × Acciones
B20: Total Deuda ($M) | C20: 0 | D20: LULU sin deuda LP
B21: Lease Liabilities ($M) | C21: ='3. BS'!H23+'3. BS'!H28 | D21: Suma corriente + LP FY2025
B22: Cash + STI ($M) | C22: ='3. BS'!H7 | D22: BS FY2025
B23: Enterprise Value ($M) | C23: =C19+C20+C21-C22 | D23: MCap + Debt + Leases − Cash
B25: MÉTRICAS FINANCIERAS CLAVE (FY2025)
B26: Net Revenue ($M) | C26: ='2. IS'!H5
B27: Operating Income ($M) | C27: ='2. IS'!H13
B28: Operating Margin % | C28: ='2. IS'!H13/'2. IS'!H5
B29: EBITDA ($M) | C29: ='2. IS'!H13+'2. IS'!H10
B30: Net Income ($M) | C30: ='2. IS'!H17
B31: EPS Diluted | C31: ='2. IS'!H28
B32: CFO ($M) | C32: ='4. CF'!H12
B33: CapEx ($M) | C33: =ABS('4. CF'!H14)
B34: FCF ($M) | C34: ='4. CF'!H22
B35: FCF Margin % | C35: ='4. CF'!H22/'2. IS'!H5
B36: D&A ($M) | C36: ='2. IS'!H10
B37: SBC ($M) | C37: ='2. IS'!H25
B39: MÚLTIPLOS DE VALORACIÓN
B40: P/E (TTM) | C40: =C19/C30
B41: EV/EBITDA | C41: =C23/C29
B42: EV/Revenue | C42: =C23/C26
B43: P/FCF | C43: =C19/C34
B44: Price / Book | C44: =C19/'3. BS'!H32
B45: Dividend Yield | C45: =0
...

Sheet 2. IS
B2: INCOME STATEMENT — Lululemon Athletica Inc.
B3: En $M USD | Source: 10-K filings (SEC EDGAR) + Press Release FY2025
B4: CONCEPTO ($M) | C4: FY 2020 | D4: FY 2021 | E4: FY 2022 | F4: FY 2023 | G4: FY 2024 | H4: FY 2025
B5: Net Revenue | C5: 3979 | D5: 4402 | E5: 6257 | F5: 8111 | G5: 9619 | H5: 11100
B6: Cost of Goods Sold | C6: 1756 | D6: 1938 | E6: 2648 | F6: 3618 | G6: 4010 | H6: 4773
B7: Gross Profit | C7: =C5-C6 | D7: =D5-D6 | E7: =E5-E6 | F7: =F5-F6 | G7: =G5-G6 | H7: =H5-H6
B9: OPERATING EXPENSES:
B10: Depreciation and Amortization | C10: 162 | D10: 185 | E10: 224 | F10: 292 | G10: 322 | H10: 414
B11: Selling, General and Administrative (ex D&A) | C11: 1172 | D11: 1424 | E11: 2001 | F11: 2465 | G11: 3075 | H11: 3567
B12: Impairments and Restructuring | C12: 0 | D12: 0 | E12: 0 | F12: 408 | G12: 0 | H12: 0
B13: Operating Income | C13: =C7-C10-C11-C12 | D13: =D7-D10-D11-D12 | E13: =E7-E10-E11-E12 | F13: =F7-F10-F11-F12 | G13: =G7-G10-G11-G12 | H13: =H7-H10-H11-H12
B15: Income Before Taxes | C15: =C13 | D15: =D13 | E15: =E13 | F15: =F13 | G15: =G13 | H15: =H13
B16: Provision for Income Taxes | C16: 244 | D16: 231 | E16: 358 | F16: 474 | G16: 583 | H16: 660
B17: Net Income | C17: =C15-C16 | D17: =D15-D16 | E17: =E15-E16 | F17: =F15-F16 | G17: =G15-G16 | H17: =H15-H16
B19: MÉTRICAS DERIVADAS:
B20: EBITDA | C20: =C13+C10 | D20: =D13+D10 | E20: =E13+E10 | F20: =F13+F10 | G20: =G13+G10 | H20: =H13+H10
B21: Operating Margin % | C21: =C13/C5 | D21: =D13/D5 | E21: =E13/E5 | F21: =F13/F5 | G21: =G13/G5 | H21: =H13/H5
B22: Net Margin % | C22: =C17/C5 | D22: =D17/D5 | E22: =E17/E5 | F22: =F17/F5 | G22: =G17/G5 | H22: =H17/H5
B23: Effective Tax Rate | C23: =IFERROR(C16/C15,0) | D23: =IFERROR(D16/D15,0) | E23: =IFERROR(E16/E15,0) | F23: =IFERROR(F16/F15,0) | G23: =IFERROR(G16/G15,0) | H23: =IFERROR(H16/H15,0)
B25: Stock-Based Compensation | C25: 46 | D25: 51 | E25: 69 | F25: 78 | G25: 94 | H25: 50
B26: SBC % of Revenue | C26: =C25/C5 | D26: =D25/D5 | E26: =E25/E5 | F26: =F25/F5 | G26: =G25/G5 | H26: =H25/H5
B27: DATOS SUPLEMENTARIOS:
B28: EPS Diluted | C28: 4.93 | D28: 4.5 | E28: 7.48 | F28: 6.68 | G28: 12.2 | H28: 14.2
B29: Diluted Shares (M) | C29: 130.96 | D29: 130.87 | E29: 130.3 | F29: 128.02 | G29: 127.06 | H29: 118.5
B30: Marketing/Brand Spend (estimate) | C30: 130 | D30: 145 | E30: 200 | F30: 265 | G30: 320 | H30: 370
B32: Source: SEC 10-K (Lululemon Athletica Inc.) | Press Release 17-Mar-2026 | DCE Holdings | 03-May-2026

Sheet 3. BS
B2: BALANCE SHEET — Lululemon Athletica Inc.
B3: En $M USD | Source: 10-K filings (SEC EDGAR)
B4: CONCEPTO ($M) | C4: FY 2020 | D4: FY 2021 | E4: FY 2022 | F4: FY 2023 | G4: FY 2024 | H4: FY 2025
B5: ACTIVOS
B6: Current Assets:
B7: Cash and Cash Equivalents | C7: 1094 | D7: 1151 | E7: 1260 | F7: 2243 | G7: 1188 | H7: 1807
B8: Accounts Receivable | C8: 40 | D8: 62 | E8: 77 | F8: 125 | G8: 143 | H8: 191
B9: Inventories | C9: 519 | D9: 647 | E9: 966 | F9: 1324 | G9: 1801 | H9: 1701
B10: Other Current Assets | C10: 156 | D10: 264 | E10: 311 | F10: 368 | G10: 472 | H10: 564
B11: Total Current Assets | C11: =SUM(C7:C10) | D11: =SUM(D7:D10) | E11: =SUM(E7:E10) | F11: =SUM(F7:F10) | G11: =SUM(G7:G10) | H11: =SUM(H7:H10)
B13: Non-Current Assets:
B14: Property and Equipment, net | C14: 672 | D14: 746 | E14: 928 | F14: 1546 | G14: 1698 | H14: 2000
B15: Right-of-Use Lease Assets | C15: 690 | D15: 735 | E15: 804 | F15: 1266 | G15: 1361 | H15: 1650
B16: Goodwill | C16: 24 | D16: 387 | E16: 387 | F16: 24 | G16: 164 | H16: 173
B17: Intangible Assets, net | C17: 0 | D17: 80 | E17: 71 | F17: 0 | G17: 14 | H17: 9
B18: Other Non-Current Assets | C18: 88 | D18: 113 | E18: 138 | F18: 196 | G18: 242 | H18: 305
B19: Total Assets | C19: =C11+SUM(C14:C18) | D19: =D11+SUM(D14:D18) | E19: =E11+SUM(E14:E18) | F19: =F11+SUM(F14:F18) | G19: =G11+SUM(G14:G18) | H19: =H11+SUM(H14:H18)
B21: PASIVOS
B22: Accounts Payable | C22: 80 | D22: 172 | E22: 290 | F22: 348 | G22: 386 | H22: 446
B23: Lease Liabilities (Current) | C23: 129 | D23: 166 | E23: 189 | F23: 208 | G23: 249 | H23: 305
B24: Other Current Liabilities | C24: 412 | D24: 545 | E24: 926 | F24: 1075 | G24: 1169 | H24: 1107
B25: Total Current Liabilities | C25: =SUM(C22:C24) | D25: =SUM(D22:D24) | E25: =SUM(E22:E24) | F25: =SUM(F22:F24) | G25: =SUM(G22:G24) | H25: =SUM(H22:H24)
B27: Non-Current Liabilities:
B28: Lease Liabilities (Non-Current) | C28: 612 | D28: 633 | E28: 692 | F28: 862 | G28: 1154 | H28: 1510
B29: Other Non-Current Liabilities | C29: 98 | D29: 111 | E29: 115 | F29: 367 | G29: 140 | H29: 145
B30: Total Liabilities | C30: =C25+C28+C29 | D30: =D25+D28+D29 | E30: =E25+E28+E29 | F30: =F25+F28+F29 | G30: =G25+G28+G29 | H30: =H25+H28+H29
B31: PATRIMONIO
B32: Total Stockholders Equity | C32: 1952 | D32: 2558 | E32: 2740 | F32: 3148 | G32: 3986 | H32: 4887
B33: Total Liabilities + Equity | C33: =C30+C32 | D33: =D30+D32 | E33: =E30+E32 | F33: =F30+F32 | G33: =G30+G32 | H33: =H30+H32
B35: SUPLEMENTARIOS
B36: Cash + Short-Term Investments | C36: =C7 | D36: =D7 | E36: =E7 | F36: =F7 | G36: =G7 | H36: =H7
B37: Total Debt | C37: 0 | D37: 0 | E37: 0 | F37: 0 | G37: 0 | H37: 0
B38: Net Debt | C38: =C37+C23+C28-C36 | D38: =D37+D23+D28-D36 | E38: =E37+E23+E28-E36 | F38: =F37+F23+F28-F36 | G38: =G37+G23+G28-G36 | H38: =H37+H23+H28-H36
B39: Book Value per Share | C39: =C32/'2. IS'!C29 | D39: =D32/'2. IS'!D29 | E39: =E32/'2. IS'!E29 | F39: =F32/'2. IS'!F29 | G39: =G32/'2. IS'!G29 | H39: =H32/'2. IS'!H29
B41: Source: SEC 10-K (Lululemon Athletica Inc.) | DCE Holdings | 03-May-2026

Sheet 4. CF
B2: CASH FLOW STATEMENT — Lululemon Athletica Inc.
B3: En $M USD | Source: 10-K filings (SEC EDGAR)
B4: CONCEPTO ($M) | C4: FY 2020 | D4: FY 2021 | E4: FY 2022 | F4: FY 2023 | G4: FY 2024 | H4: FY 2025
B5: OPERACIONES
B6: Net Income | C6: 646 | D6: 589 | E6: 975 | F6: 855 | G6: 1550 | H6: 1686
B7: Depreciation and Amortization | C7: 162 | D7: 185 | E7: 224 | F7: 292 | G7: 322 | H7: 414
B8: Impairments | C8: 0 | D8: 0 | E8: 0 | F8: 408 | G8: 0 | H8: 0
B9: Stock-Based Compensation | C9: 46 | D9: 51 | E9: 69 | F9: 78 | G9: 94 | H9: 50
B10: Other Adjustments | C10: 10 | D10: -5 | E10: 41 | F10: -39 | G10: -26 | H10: 30
B11: Changes in Working Capital | C11: -191 | D11: -284 | E11: -311 | F11: -505 | G11: -147 | H11: -577
B12: Cash from Operations (CFO) | C12: =SUM(C6:C11) | D12: =SUM(D6:D11) | E12: =SUM(E6:E11) | F12: =SUM(F6:F11) | G12: =SUM(G6:G11) | H12: =SUM(H6:H11)
B13: INVERSIÓN
B14: Capital Expenditures | C14: -283 | D14: -334 | E14: -379 | F14: -670 | G14: -630 | H14: -681
B15: Other Investing | C15: 4 | D15: 0 | E15: 0 | F15: 10 | G15: 2 | H15: 0
B16: Cash from Investing (CFI) | C16: =SUM(C14:C15) | D16: =SUM(D14:D15) | E16: =SUM(E14:E15) | F16: =SUM(F14:F15) | G16: =SUM(G14:G15) | H16: =SUM(H14:H15)
B17: FINANCIAMIENTO
B18: Repurchases of Common Stock | C18: -173 | D18: -598 | E18: -443 | F18: -444 | G18: -559 | H18: -1180
B19: Other Financing | C19: -4 | D19: -9 | E19: -35 | F19: -78 | G19: -33 | H19: -39
B20: Cash from Financing (CFF) | C20: =SUM(C18:C19) | D20: =SUM(D18:D19) | E20: =SUM(E18:E19) | F20: =SUM(F18:F19) | G20: =SUM(G18:G19) | H20: =SUM(H18:H19)
B21: Net Change in Cash | C21: =C12+C16+C20 | D21: =D12+D16+D20 | E21: =E12+E16+E20 | F21: =F12+F16+F20 | G21: =G12+G16+G20 | H21: =H12+H16+H20
B22: Free Cash Flow (FCF) | C22: =C12+C14 | D22: =D12+D14 | E22: =E12+E14 | F22: =F12+F14 | G22: =G12+G14 | H22: =H12+H14
B24: Source: SEC 10-K (Lululemon Athletica Inc.) | DCE Holdings | 03-May-2026

Sheet 5. Health
B2: HEALTH CHECK — Lululemon Athletica Inc.
B3: En $M USD | FY2025 baseline
B4: MÉTRICA | C4: Valor | D4: Umbral | E4: Estado | F4: Nota
B5: SOLIDEZ FINANCIERA
B6: Total Debt / Equity | C6: =0 | D6: <1.0x | E6: ="✓" | F6: Zero LT debt
B7: Net Debt / EBITDA | C7: ='3. BS'!H38/('2. IS'!H13+'2. IS'!H10) | D7: <2.0x | E7: =IF('3. BS'!H38/('2. IS'!H13+'2. IS'!H10)<2,"✓","✗") | F7: Zero debt + leases only
B8: Current Ratio | C8: ='3. BS'!H11/'3. BS'!H25 | D8: >1.5x | E8: =IF('3. BS'!H11/'3. BS'!H25>1.5,"✓","✗") | F8: Strong liquidity
B9: Interest Coverage | C9: =999 | D9: >10x | E9: ="✓" | F9: No interest expense
B11: RENTABILIDAD
B12: Operating Margin (FY2025) | C12: ='2. IS'!H21 | D12: >15% | E12: =IF('2. IS'!H21>0.15,"✓","✗") | F12: Premium athleisure margin
B13: FCF Margin (FY2025) | C13: ='4. CF'!H22/'2. IS'!H5 | D13: >10% | E13: =IF('4. CF'!H22/'2. IS'!H5>0.10,"✓","✗") | F13: After CapEx
B14: ROIC (FY2025) | C14: ='11. ROIC'!H14 | D14: >15% | E14: =IF(ISNUMBER('11. ROIC'!H14),IF('11. ROIC'!H14>0.15,"✓","✗"),"≈") | F14: Versus ~10.25% WACC
B15: ROIC > WACC | C15: ='11. ROIC'!H14-'10. EPV'!C13 | D15: >0 | E15: =IF(ISNUMBER('11. ROIC'!H14),IF('11. ROIC'!H14-'10. EPV'!C13>0,"✓","✗"),"≈") | F15: Spread vs WACC
B17: CRECIMIENTO
B18: Revenue CAGR 5yr (FY2020→FY2025) | C18: =('2. IS'!H5/'2. IS'!C5)^(1/5)-1 | D18: >10% | E18: =IF(('2. IS'!H5/'2. IS'!C5)^(1/5)-1>0.10,"✓","✗") | F18: Compounding athleisure
B19: EBITDA Growth YoY | C19: =(('2. IS'!H13+'2. IS'!H10)/('2. IS'!G13+'2. IS'!G10))-1 | D19: >5% | E19: =IF(((('2. IS'!H13+'2. IS'!H10)/('2. IS'!G13+'2. IS'!G10))-1)>0.05,"✓","✗") | F19: FY2025 vs FY2024
B20: FCF CAGR 3yr | C20: =('4. CF'!H22/'4. CF'!E22)^(1/3)-1 | D20: >5% | E20: =IF(('4. CF'!H22/'4. CF'!E22)^(1/3)-1>0.05,"✓","✗") | F20: Trailing 3-year
B22: ESPECÍFICOS APPAREL / ATHLEISURE
B23: SBC % of Revenue (FY2025) | C23: ='2. IS'!H26 | D23: <2% | E23: =IF('2. IS'!H26<0.02,"✓","✗") | F23: Compensación moderada
B24: CapEx % of Revenue | C24: =ABS('4. CF'!H14)/'2. IS'!H5 | D24: <7% | E24: =IF(ABS('4. CF'!H14)/'2. IS'!H5<0.07,"✓","✗") | F24: Store expansion
B25: Inventory Days | C25: ='3. BS'!H9/('2. IS'!H6/365) | D25: <140 days | E25: =IF('3. BS'!H9/('2. IS'!H6/365)<140,"✓","✗") | F25: Working capital efficiency
B26: Gross Margin (FY2025) | C26: ='2. IS'!H7/'2. IS'!H5 | D26: >50% | E26: =IF('2. IS'!H7/'2. IS'!H5>0.50,"✓","✗") | F26: Premium pricing power
B28: Source: SEC 10-K + Press Release | DCE Holdings | 03-May-2026

Sheet 6. S&M Cap
B2: CAPITALIZACIÓN DE MARKETING (proxy S&M) — Lululemon Athletica Inc. | Vida Útil: 3 Años
B4: PARÁMETROS
B5: Vida Útil (años) | C5: 3
B6: Proxy S&M | C6: Marketing/Brand Spend dentro de SG&A (~3.3% Revenue)
B7: Nota SBC | C7: SBC ya incluido en SG&A — Case A (no se ajusta nuevamente)
B8: Histórico FY2019 (estimado) | C8: 115
B9: Histórico FY2020 (estimado) | C9: 130
B11: GASTO EN MARKETING POR AÑO — INPUTS
B12: Concepto | C12: FY 2021 | D12: FY 2022 | E12: FY 2023 | F12: FY 2024 | G12: FY 2025
B13: Marketing Expense ($M) | C13: 145 | D13: 200 | E13: 265 | F13: 320 | G13: 370
B14: Source: Estimación basada en peer benchmark apparel ~3.3% revenue
B16: MATRIZ DE AMORTIZACIÓN POR COHORTE
B17: Cohorte \ Año Modelo | C17: FY 2021 | D17: FY 2022 | E17: FY 2023 | F17: FY 2024 | G17: FY 2025
B18: FY 2019 | C18: =C8/$C$5 | D18: - | E18: - | F18: - | G18: -
B19: FY 2020 | C19: =C9/$C$5 | D19: =C9/$C$5 | E19: - | F19: - | G19: -
B20: FY 2021 | C20: =C13/$C$5 | D20: =C13/$C$5 | E20: =C13/$C$5 | F20: - | G20: -
B21: FY 2022 | C21: - | D21: =D13/$C$5 | E21: =D13/$C$5 | F21: =D13/$C$5 | G21: -
B22: FY 2023 | C22: - | D22: - | E22: =E13/$C$5 | F22: =E13/$C$5 | G22: =E13/$C$5
B23: FY 2024 | C23: - | D23: - | E23: - | F23: =F13/$C$5 | G23: =F13/$C$5
B24: FY 2025 | C24: - | D24: - | E24: - | F24: - | G24: =G13/$C$5
B25: Economic Amortization (Total) | C25: =SUM(C18:C24) | D25: =SUM(D18:D24) | E25: =SUM(E18:E24) | F25: =SUM(F18:F24) | G25: =SUM(G18:G24)
B27: RESUMEN S&M CAPITALIZACIÓN
B28: Concepto | C28: FY 2021 | D28: FY 2022 | E28: FY 2023 | F28: FY 2024 | G28: FY 2025
B29: Gasto Marketing (Total) | C29: =C13 | D29: =D13 | E29: =E13 | F29: =F13 | G29: =G13
B30: Economic Amortization | C30: =C25 | D30: =D25 | E30: =E25 | F30: =F25 | G30: =G25
B31: S&M Growth Expense | C31: =C29-C30 | D31: =D29-D30 | E31: =E29-E30 | F31: =F29-F30 | G31: =G29-G30
B32: S&M Asset (Unamortized) | C32: =C9*0.333333+C13*0.666667 | D32: =C13*0.333333+D13*0.666667 | E32: =D13*0.333333+E13*0.666667 | F32: =E13*0.333333+F13*0.666667 | G32: =F13*0.333333+G13*0.666667
B33: Growth Expense % of Marketing | C33: =C31/C29 | D33: =D31/D29 | E33: =E31/E29 | F33: =F31/F29 | G33: =G31/G29
B35: Source: Marketing estimates derived from 10-K + peer benchmarks | DCE Holdings | 03-May-2026

Sheet 7. R&D Cap
B2: CAPITALIZACIÓN DE R&D — Lululemon Athletica Inc. | Vida Útil: N/A
B4: ESTADO: NO APLICA
B6: Lululemon Athletica Inc. NO reporta un gasto de Research & Development (R&D) separado en su
B7: 10-K. La compañía describe inversión en producto y diseño dentro de SG&A pero sin desglose
B8: cuantitativo. Por tanto, no es posible aplicar el método de capitalización por cohortes a R&D.
B10: Implicaciones para el modelo:
B11: • R&D Asset = $0 en todas las hojas downstream (NOPAT, ROIC, RV)
B12: • La inversión en producto/diseño queda implícita dentro del Margen Operativo reportado
B13: • La marca/branding (que es la fuente real de moat) se captura via S&M Capitalization
B15: Decisión DP2 confirmada por CIO: R&D Capitalization = N/A (no capitalizar).
B16: Decisión DP4 confirmada por CIO: R&D Useful Life = N/A.
B18: VALORES PARA SHEETS DOWNSTREAM
B19: R&D Asset (Unamortized) | C19: 0
B20: R&D Economic Amortization | C20: 0
B21: R&D Growth Expense | C21: 0
B23: Source: 10-K Lululemon Athletica Inc. — no separate R&D disclosure | DCE Holdings | 03-May-2026

Sheet 8. RV
B2: REPRODUCTION VALUE — Lululemon Athletica Inc.
B3: Reproduction Value: costo estimado de replicar los activos de LULU desde cero (FY2025)
B5: CONCEPTO | C5: Valor Libro ($M) | D5: % Ajuste | E5: Reproduction Cost ($M) | F5: Método / Justificación
B6: ACTIVOS TANGIBLES (del balance)
B7: Cash and Cash Equivalents | C7: ='3. BS'!H7 | D7: 1 | E7: =C7*D7 | F7: Líquido — 100%
B8: Accounts Receivable | C8: ='3. BS'!H8 | D8: 0.95 | E8: =C8*D8 | F8: Pequeño AR (DTC), riesgo crédito mínimo
B9: Inventories | C9: ='3. BS'!H9 | D9: 0.85 | E9: =C9*D9 | F9: Apparel — riesgo obsolescencia moda; 85%
B10: Other Current Assets | C10: ='3. BS'!H10 | D10: 0.8 | E10: =C10*D10 | F10: Prepaids y otros — 80%
B11: Property and Equipment, net | C11: ='3. BS'!H14 | D11: 1.1 | E11: =C11*D11 | F11: Stores nuevos cuestan ~10% más que valor libro
B12: Subtotal Tangibles | E12: =SUM(E7:E11)
B14: ACTIVOS INTANGIBLES (reconstruir desde cero)
B15: Marca / Brand Equity (acumulado mktg 7yr × 60%) | C15: 0 | D15: N/A | E15: =('6. S&M Cap'!C8+'6. S&M Cap'!C9+'6. S&M Cap'!C13+'6. S&M Cap'!D13+'6. S&M Cap'!E13+'6. S&M Cap'!F13+'6. S&M Cap'!G13)*0.6 | F15: Brand no en BS; reconstruir vía 7yr mktg × 60% efficiency
B16: S&M Asset (Unamortized — del modelo) | C16: ='6. S&M Cap'!G32 | D16: 1 | E16: =C16*D16 | F16: 100% — capitalizado por modelo (cohort matrix)
B17: Goodwill | C17: ='3. BS'!H16 | D17: 0 | E17: =C17*D17 | F17: DP12: 0% — se reconstruye via S&M Asset (doble conteo)
B18: Intangible Assets, net (BS) | C18: ='3. BS'!H17 | D18: 0.3 | E18: =C18*D18 | F18: DP13: 30% — residuos Mirror, no replicables
B19: Subtotal Intangibles (Reproduction) | E19: =SUM(E15:E18)
B21: OTROS ACTIVOS
B22: Right-of-Use Lease Assets | C22: ='3. BS'!H15 | D22: 0.75 | E22: =C22*D22 | F22: 75% — leases activos pero no transferibles directamente
B23: Other Non-Current Assets (incl. DTA) | C23: ='3. BS'!H18 | D23: 0.5 | E23: =C23*D23 | F23: DP14: 50% — DTA y otros con realización incierta
B24: Subtotal Otros | E24: =SUM(E22:E23)
B26: Total Activos (Reproduction) | E26: =E12+E19+E24
B28: PASIVOS
B29: Accounts Payable | C29: ='3. BS'!H22 | D29: 1 | E29: =C29*D29 | F29: Contractual — 100%
B30: Lease Liabilities (Total) | C30: ='3. BS'!H23+'3. BS'!H28 | D30: 1 | E30: =C30*D30 | F30: Contractual lease — 100%
B31: Other Current Liabilities | C31: ='3. BS'!H24 | D31: 1 | E31: =C31*D31 | F31: Contractual — 100%
B32: Other Non-Current Liabilities | C32: ='3. BS'!H29 | D32: 1 | E32: =C32*D32 | F32: Contractual — 100%
B33: Total Pasivos | E33: =SUM(E29:E32)
B35: CÁLCULO REPRODUCTION VALUE
B36: Total Activos (Reproduction) | E36: =E26
B37: (−) Total Pasivos | E37: =-E33
B38: Reproduction Value ($M) | E38: =E36+E37
B39: Acciones Diluidas (M) | E39: ='2. IS'!H29
B40: Reproduction Value por Acción | E40: =E38/E39
B42: NOTA: El Reproduction Value no captura el time-to-build. Replicar Lululemon — la marca premium athleisure, la red de stores propias, y la cultura DTC — tomaría 7-10 años incluso con capital ilimitado. Por ello, este es un estimado conservador del valor de los activos.
B44: Source: SEC 10-K + DCE estimates | DCE Holdings | 03-May-2026

Sheet 9. NOPAT
B2: NOPAT AJUSTADO Y NORMALIZADO — Lululemon Athletica Inc.
B3: En $M USD | Normalizado: Mirror impairment FY2023 eliminado | Tax 28% | Window FY2020-FY2025
B4: CONCEPTO ($M) | C4: Parámetro | D4: FY 2020 | E4: FY 2021 | F4: FY 2022 | G4: FY 2023 | H4: FY 2024 | I4: FY 2025 | J4: Normalizado
B5: PARÁMETROS
B6: Tax Rate Normalizado (DP8) | C6: 0.28
B7: Items a Normalizar (DP7) | C7: Mirror impairment FY2023 ($408M) — eliminar
B8: Ventana Normalización (DP6) | C8: 6yr (FY2020–FY2025)
B9: Revenue Base (No-Growth Scenario) | C9: 11100 | D9: Default = FY2025 Revenue ($11,100M). Override si no-growth difiere.
B10: Margen Op Normalizado | C10: 0.213 | D10: Median Margen Op Limpio FY20-FY25 ~21.3%. Avg ~21.2%. FY2025 21.1%.
B12: INGRESOS
B13: Net Revenue | D13: ='2. IS'!C5 | E13: ='2. IS'!D5 | F13: ='2. IS'!E5 | G13: ='2. IS'!F5 | H13: ='2. IS'!G5 | I13: ='2. IS'!H5 | J13: =$C$9
B15: CÁLCULO — UTILIDAD OPERATIVA AJUSTADA
B16: Operating Income Reportada | D16: ='2. IS'!C13 | E16: ='2. IS'!D13 | F16: ='2. IS'!E13 | G16: ='2. IS'!F13 | H16: ='2. IS'!G13 | I16: ='2. IS'!H13 | J16: ='2. IS'!H13
B17: (+) Mirror Impairment FY2023 (eliminar) | D17: ='2. IS'!C12 | E17: ='2. IS'!D12 | F17: ='2. IS'!E12 | G17: ='2. IS'!F12 | H17: ='2. IS'!G12 | I17: ='2. IS'!H12 | J17: =0
B18: Utilidad Operativa Limpia | D18: =D16+D17 | E18: =E16+E17 | F18: =F16+F17 | G18: =G16+G17 | H18: =H16+H17 | I18: =I16+I17 | J18: =$C$9*$C$10
B19: (+) Marketing Expense (add-back TOTAL) | D19: ='2. IS'!C30 | E19: ='2. IS'!D30 | F19: ='2. IS'!E30 | G19: ='2. IS'!F30 | H19: ='2. IS'!G30 | I19: ='2. IS'!H30 | J19: ='2. IS'!H30
B20: (−) Economic Amortization S&M (Maintenance) | D20: =-('2. IS'!C30) | E20: =-('6. S&M Cap'!C30) | F20: =-('6. S&M Cap'!D30) | G20: =-('6. S&M Cap'!E30) | H20: =-('6. S&M Cap'!F30) | I20: =-('6. S&M Cap'!G30) | J20: =-'6. S&M Cap'!G30
B21: S&M Growth Expense (referencia — no reduce NOPAT) | D21: =D19+D20 | E21: =E19+E20 | F21: =F19+F20 | G21: =G19+G20 | H21: =H19+H20 | I21: =I19+I20 | J21: =J19+J20
B22: (+) R&D Expense (add-back) — N/A | D22: 0 | E22: 0 | F22: 0 | G22: 0 | H22: 0 | I22: 0 | J22: 0
B23: (−) Economic Amortization R&D — N/A | D23: 0 | E23: 0 | F23: 0 | G23: 0 | H23: 0 | I23: 0 | J23: 0
B24: Utilidad Operativa Ajustada (pre-tax) | D24: =D18+D19+D20+D22+D23 | E24: =E18+E19+E20+E22+E23 | F24: =F18+F19+F20+F22+F23 | G24: =G18+G19+G20+G22+G23 | H24: =H18+H19+H20+H22+H23 | I24: =I18+I19+I20+I22+I23 | J24: =J18+J19+J20+J22+J23
B25: × (1 − Tax Rate Normalizado) | D25: =1-$C$6 | E25: =1-$C$6 | F25: =1-$C$6 | G25: =1-$C$6 | H25: =1-$C$6 | I25: =1-$C$6 | J25: =1-$C$6
B26: NOPAT Ajustado | D26: =D24*D25 | E26: =E24*E25 | F26: =F24*F25 | G26: =G24*G25 | H26: =H24*H25 | I26: =I24*I25 | J26: =J24*J25
B28: MÉTRICAS
B29: Margen Op Limpio (OpInc Clean / Revenue) | D29: =D18/D13 | E29: =E18/E13 | F29: =F18/F13 | G29: =G18/G13 | H29: =H18/H13 | I29: =I18/I13 | J29: =$C$10
B30: NOPAT Margin % | D30: =D26/D13 | E30: =E26/E13 | F30: =F26/F13 | G30: =G26/G13 | H30: =H26/H13 | I30: =I26/I13 | J30: =J26/J13
B31: NOPAT YoY Growth % | D31: - | E31: =(E26-D26)/ABS(D26) | F31: =(F26-E26)/ABS(E26) | G31: =(G26-F26)/ABS(F26) | H31: =(H26-G26)/ABS(G26) | I31: =(I26-H26)/ABS(H26)
B33: REFERENCIAS (para EPV)
B34: D&A (Full Company) | D34: ='2. IS'!C10 | E34: ='2. IS'!D10 | F34: ='2. IS'!E10 | G34: ='2. IS'!F10 | H34: ='2. IS'!G10 | I34: ='2. IS'!H10 | J34: ='2. IS'!H10
B35: CapEx | D35: =ABS('4. CF'!C14) | E35: =ABS('4. CF'!D14) | F35: =ABS('4. CF'!E14) | G35: =ABS('4. CF'!F14) | H35: =ABS('4. CF'!G14) | I35: =ABS('4. CF'!H14) | J35: =ABS('4. CF'!H14)
B37: Source: SEC 10-K + DCE normalization | DCE Holdings | 03-May-2026

Sheet 10. EPV
B2: EARNINGS POWER VALUE — Lululemon Athletica Inc.
B3: En $M USD | Zero-growth perpetuity | WACC = Ke (zero LT debt)
B5: SECCIÓN 1: WACC
B6: Risk-Free Rate (10Y UST) | C6: 0.0439 | D6: YCharts 1-May-2026
B7: Beta (5yr) | C7: 1.3 | D7: Median raw 1.51 + alphaspread 0.77
B8: Equity Risk Premium | C8: 0.045 | D8: Damodaran Implied 2026
B9: Cost of Equity (Ke) | C9: =C6+C7*C8 | D9: Rf + Beta × ERP
B10: Cost of Debt (Kd pre-tax) | C10: 0 | D10: LULU sin deuda LP — N/A
B11: Tax Rate | C11: ='9. NOPAT'!C6 | D11: Link a NOPAT DP8
B12: Cost of Debt (Kd post-tax) | C12: =C10*(1-C11) | D12: Kd × (1-t)
B13: WACC | C13: =C9*1+C12*0 | D13: Zero debt → WACC = Ke
B14: E / (D+E) | C14: 1
B15: D / (D+E) | C15: 0
B17: SECCIÓN 2: CÁLCULO EPV
B18: Adj. Operating Income (Normalizado) | C18: ='9. NOPAT'!J24
B19: × (1 − Tax Rate) | C19: =1-C11
B20: NOPAT Normalizado | C20: =C18*C19
B21: (+) D&A | C21: ='9. NOPAT'!J34
B22: (−) Maintenance CapEx (Zero-Growth) | C22: 414 | D22: Default = D&A. Override si Maint CapEx ≠ D&A.
B23: EPV Operaciones | C23: =(C20+C21-C22)/C13
B24: (+) Excess Cash (Cash + STI − 2% Revenue buffer) | C24: ='3. BS'!H7-0.02*'2. IS'!H5
B25: (+) Non-Operating Assets | C25: 0
B26: (−) Total Debt | C26: =-'3. BS'!H37
B27: (−) Lease Liabilities | C27: =-('3. BS'!H23+'3. BS'!H28)
B28: (−) Minority Interest | C28: 0
B29: EPV Equity | C29: =C23+C24+C25+C26+C27+C28
B30: Acciones Diluidas (M) | C30: ='2. IS'!H29
B31: EPV por Acción | C31: =C29/C30
B33: SECCIÓN 3: BRIDGE EPV OPERACIONES → EQUITY EPV
B34: Precio Actual | C34: ='1. Overview'!C17
B35: EPV / Acción | C35: =C31
B36: Descuento / Prima | C36: =(C35-C34)/C35
B38: SENSIBILIDAD EPV/Acción (WACC × NOPAT variation)
B39: WACC \ ΔNOPAT | C39: -0.1 | D39: -0.05 | E39: 0 | F39: 0.05 | G39: 0.1
B40: -0.01 | C40: =((C20*(1+-0.1)+C21-C22)/(C13+-0.01)+C24+C25+C26+C27+C28)/C30 | D40: =((C20*(1+-0.05)+C21-C22)/(C13+-0.01)+C24+C25+C26+C27+C28)/C30 | E40: =((C20*(1+0.0)+C21-C22)/(C13+-0.01)+C24+C25+C26+C27+C28)/C30 | F40: =((C20*(1+0.05)+C21-C22)/(C13+-0.01)+C24+C25+C26+C27+C28)/C30 | G40: =((C20*(1+0.1)+C21-C22)/(C13+-0.01)+C24+C25+C26+C27+C28)/C30
B41: -0.005 | C41: =((C20*(1+-0.1)+C21-C22)/(C13+-0.005)+C24+C25+C26+C27+C28)/C30 | D41: =((C20*(1+-0.05)+C21-C22)/(C13+-0.005)+C24+C25+C26+C27+C28)/C30 | E41: =((C20*(1+0.0)+C21-C22)/(C13+-0.005)+C24+C25+C26+C27+C28)/C30 | F41: =((C20*(1+0.05)+C21-C22)/(C13+-0.005)+C24+C25+C26+C27+C28)/C30 | G41: =((C20*(1+0.1)+C21-C22)/(C13+-0.005)+C24+C25+C26+C27+C28)/C30
B42: 0 | C42: =((C20*(1+-0.1)+C21-C22)/(C13+0.0)+C24+C25+C26+C27+C28)/C30 | D42: =((C20*(1+-0.05)+C21-C22)/(C13+0.0)+C24+C25+C26+C27+C28)/C30 | E42: =((C20*(1+0.0)+C21-C22)/(C13+0.0)+C24+C25+C26+C27+C28)/C30 | F42: =((C20*(1+0.05)+C21-C22)/(C13+0.0)+C24+C25+C26+C27+C28)/C30 | G42: =((C20*(1+0.1)+C21-C22)/(C13+0.0)+C24+C25+C26+C27+C28)/C30
B43: 0.005 | C43: =((C20*(1+-0.1)+C21-C22)/(C13+0.005)+C24+C25+C26+C27+C28)/C30 | D43: =((C20*(1+-0.05)+C21-C22)/(C13+0.005)+C24+C25+C26+C27+C28)/C30 | E43: =((C20*(1+0.0)+C21-C22)/(C13+0.005)+C24+C25+C26+C27+C28)/C30 | F43: =((C20*(1+0.05)+C21-C22)/(C13+0.005)+C24+C25+C26+C27+C28)/C30 | G43: =((C20*(1+0.1)+C21-C22)/(C13+0.005)+C24+C25+C26+C27+C28)/C30
B44: 0.01 | C44: =((C20*(1+-0.1)+C21-C22)/(C13+0.01)+C24+C25+C26+C27+C28)/C30 | D44: =((C20*(1+-0.05)+C21-C22)/(C13+0.01)+C24+C25+C26+C27+C28)/C30 | E44: =((C20*(1+0.0)+C21-C22)/(C13+0.01)+C24+C25+C26+C27+C28)/C30 | F44: =((C20*(1+0.05)+C21-C22)/(C13+0.01)+C24+C25+C26+C27+C28)/C30 | G44: =((C20*(1+0.1)+C21-C22)/(C13+0.01)+C24+C25+C26+C27+C28)/C30
B46: Source: DCE Calculation | DCE Holdings | 03-May-2026

Sheet 11. ROIC
B2: RETURN ON INVESTED CAPITAL — Lululemon Athletica Inc.
B3: En $M USD | NOPAT Ajustado / Capital Invertido
B4: CONCEPTO ($M) | C4: FY 2020 | D4: FY 2021 | E4: FY 2022 | F4: FY 2023 | G4: FY 2024 | H4: FY 2025
B5: SECCIÓN 1: ROIC CONTABLE
B6: NOPAT (numerador) | C6: ='9. NOPAT'!D26 | D6: ='9. NOPAT'!E26 | E6: ='9. NOPAT'!F26 | F6: ='9. NOPAT'!G26 | G6: ='9. NOPAT'!H26 | H6: ='9. NOPAT'!I26
B7: CAPITAL INVERTIDO
B8: Working Capital Operating | C8: =('3. BS'!C11-'3. BS'!C7)-('3. BS'!C25) | D8: =('3. BS'!D11-'3. BS'!D7)-('3. BS'!D25) | E8: =('3. BS'!E11-'3. BS'!E7)-('3. BS'!E25) | F8: =('3. BS'!F11-'3. BS'!F7)-('3. BS'!F25) | G8: =('3. BS'!G11-'3. BS'!G7)-('3. BS'!G25) | H8: =('3. BS'!H11-'3. BS'!H7)-('3. BS'!H25)
B9: (+) PP&E, Net | C9: ='3. BS'!C14 | D9: ='3. BS'!D14 | E9: ='3. BS'!E14 | F9: ='3. BS'!F14 | G9: ='3. BS'!G14 | H9: ='3. BS'!H14
B10: (+) Other LT Operating Assets (ROU + Other NCA) | C10: ='3. BS'!C15+'3. BS'!C18 | D10: ='3. BS'!D15+'3. BS'!D18 | E10: ='3. BS'!E15+'3. BS'!E18 | F10: ='3. BS'!F15+'3. BS'!F18 | G10: ='3. BS'!G15+'3. BS'!G18 | H10: ='3. BS'!H15+'3. BS'!H18
B11: (+) S&M Asset (Unamortized) | C11: =0 | D11: ='6. S&M Cap'!C32 | E11: ='6. S&M Cap'!D32 | F11: ='6. S&M Cap'!E32 | G11: ='6. S&M Cap'!F32 | H11: ='6. S&M Cap'!G32
B12: (+) R&D Asset (N/A) | C12: 0 | D12: 0 | E12: 0 | F12: 0 | G12: 0 | H12: 0
B13: Invested Capital | C13: =SUM(C8:C12) | D13: =SUM(D8:D12) | E13: =SUM(E8:E12) | F13: =SUM(F8:F12) | G13: =SUM(G8:G12) | H13: =SUM(H8:H12)
B14: ROIC | C14: =IF(C13<0,"N/M",IF(C13=0,0,C6/C13)) | D14: =IF(D13<0,"N/M",IF(D13=0,0,D6/D13)) | E14: =IF(E13<0,"N/M",IF(E13=0,0,E6/E13)) | F14: =IF(F13<0,"N/M",IF(F13=0,0,F6/F13)) | G14: =IF(G13<0,"N/M",IF(G13=0,0,G6/G13)) | H14: =IF(H13<0,"N/M",IF(H13=0,0,H6/H13))
B15: Spread vs WACC (10.25%) | C15: =IF(ISTEXT(C14),"N/M",C14-'10. EPV'!$C$13) | D15: =IF(ISTEXT(D14),"N/M",D14-'10. EPV'!$C$13) | E15: =IF(ISTEXT(E14),"N/M",E14-'10. EPV'!$C$13) | F15: =IF(ISTEXT(F14),"N/M",F14-'10. EPV'!$C$13) | G15: =IF(ISTEXT(G14),"N/M",G14-'10. EPV'!$C$13) | H15: =IF(ISTEXT(H14),"N/M",H14-'10. EPV'!$C$13)
B16: WACC (referencia) | C16: ='10. EPV'!C13
B19: SECCIÓN 2: MARGINAL ROIC (DELTAS)
B20: ΔNOPAT | C20: - | D20: =D6-C6 | E20: =E6-D6 | F20: =F6-E6 | G20: =G6-F6 | H20: =H6-G6
B21: ΔInvested Capital | C21: - | D21: =D13-C13 | E21: =E13-D13 | F21: =F13-E13 | G21: =G13-F13 | H21: =H13-G13
B22: ROIC Marginal | C22: - | D22: =IF(D21<0,"N/M",IF(D21=0,0,D20/D21)) | E22: =IF(E21<0,"N/M",IF(E21=0,0,E20/E21)) | F22: =IF(F21<0,"N/M",IF(F21=0,0,F20/F21)) | G22: =IF(G21<0,"N/M",IF(G21=0,0,G20/G21)) | H22: =IF(H21<0,"N/M",IF(H21=0,0,H20/H21))
B25: SECCIÓN 3: MARGINAL ROIC — ACCUMULATED GROWTH CAPEX
B26: Growth CapEx (CapEx − D&A) | C26: =MAX(0,ABS('4. CF'!C14)-'2. IS'!C10) | D26: =MAX(0,ABS('4. CF'!D14)-'2. IS'!D10) | E26: =MAX(0,ABS('4. CF'!E14)-'2. IS'!E10) | F26: =MAX(0,ABS('4. CF'!F14)-'2. IS'!F10) | G26: =MAX(0,ABS('4. CF'!G14)-'2. IS'!G10) | H26: =MAX(0,ABS('4. CF'!H14)-'2. IS'!H10)
B27: S&M Growth Expense | C27: =0 | D27: ='6. S&M Cap'!C31 | E27: ='6. S&M Cap'!D31 | F27: ='6. S&M Cap'!E31 | G27: ='6. S&M Cap'!F31 | H27: ='6. S&M Cap'!G31
B28: Accumulated Growth CapEx (2yr rolling) | C28: - | D28: =D26+D27+C26+C27 | E28: =E26+E27+D26+D27 | F28: =F26+F27+E26+E27 | G28: =G26+G27+F26+F27 | H28: =H26+H27+G26+G27
B29: ΔNOPAT (2yr) | C29: - | D29: =D6-C6 | E29: =E6-D6 | F29: =F6-E6 | G29: =G6-F6 | H29: =H6-G6
B30: Marginal ROIC (Accumulated Growth, 2yr) | C30: - | D30: =IF(D28<=0,0,D29/D28) | E30: =IF(E28<=0,0,E29/E28) | F30: =IF(F28<=0,0,F29/F28) | G30: =IF(G28<=0,0,G29/G28) | H30: =IF(H28<=0,0,H29/H28)
B32: Nota: N/M = Not Meaningful (denominador negativo). 0% = denominador cero o sin growth investment tracked. Standard Marginal ROIC vs Accumulated Growth ROIC pueden diverger por efecto de buybacks, CapEx mantenimiento, o cambios contables.
B34: Source: DCE Calculation | DCE Holdings | 03-May-2026

Sheet 12. Implied IRR
B2: IMPLIED IRR — Lululemon Athletica Inc.
B3: En $M USD | Marco enterprise: EV → Distribuciones → Reinversión → Crecimiento → Múltiplo → Lever to Equity
B5: SECCIÓN 1: ENTERPRISE VALUE
B6: Market Cap ($M) | C6: ='1. Overview'!C19
B7: (+) Total Deuda ($M) | C7: ='3. BS'!H37
B8: (+) Lease Liabilities ($M) | C8: ='3. BS'!H23+'3. BS'!H28
B9: (−) Cash & STI ($M) | C9: =-'3. BS'!H7
B10: Enterprise Value ($M) | C10: =SUM(C6:C9)
B12: SECCIÓN 2: NOPAT AJUSTADO (Normalizado)
B13: NOPAT Ajustado Normalizado ($M) | C13: ='9. NOPAT'!J26
B14: NOPAT Multiple (EV / NOPAT) | C14: =C10/C13
B16: SECCIÓN 3: DISTRIBUCIONES
B17: Dividendos Pagados (FY2025) | C17: 0 | D17: LULU no paga dividendos
B18: (+) Buybacks Sostenibles (DP16) | C18: 727 | D18: Promedio FY2023-FY2025 ($444+$559+$1,180)/3
B19: (+) Gasto por Intereses (pre-tax) | C19: 0 | D19: Sin deuda LP
B20: Total Distribuciones | C20: =SUM(C17:C19)
B21: Distribution Yield (Dist / EV) | C21: =C20/C10
B22: Distribution Rate (Dist / NOPAT) | C22: =C20/C13
B24: SECCIÓN 4: REINVERSIÓN (bottom-up)
B25: CapEx Total (FY2025) | C25: =ABS('4. CF'!H14)
B26: (−) Maintenance CapEx (D&A proxy) | C26: =-'2. IS'!H10
B27: Growth CapEx | C27: =MAX(0,C25+C26)
B28: (+) Δ Capital de Trabajo (est.) | C28: =MAX(0,-'4. CF'!H11)
B29: (+) S&M Growth Expense | C29: =MAX(0,'6. S&M Cap'!G31)
B30: (+) R&D Growth Expense (N/A) | C30: 0
B31: Total Reinversión | C31: =C27+C28+C29+C30
B32: Reinvestment Rate (Reinv / NOPAT) | C32: =C31/C13
B34: SECCIÓN 5: CRECIMIENTO
B35: ROIC Seleccionado (3yr avg, IC>0) | C35: =AVERAGE('11. ROIC'!F14,'11. ROIC'!G14,'11. ROIC'!H14)
B36: Crecimiento por Reinversión (ReinvRate × ROIC) | C36: =C32*C35
B37: Crecimiento Orgánico (DP17) | C37: 0.02
B38: Total Crecimiento | C38: =C36+C37
B40: SECCIÓN 6: COMPORTAMIENTO DEL MÚLTIPLO
B41: NOPAT Multiple (EV / NOPAT) — Actual | C41: =C14
B42: Investment Horizon (años) | C42: 5
B43: Assumed Exit Multiple (DP15: 20x P/E ≈ MCap/NI) | C43: 20
B44: Multiple Expansion / Contraction | C44: =(C43-C41)/C41
B45: Impacto Anualizado del Múltiplo | C45: =(C43/C41)^(1/C42)-1
B47: SECCIÓN 7: RETORNOS Y MARGEN DE SEGURIDAD
B48: Retorno Total Enterprise (Dist + Crec + Múltiplo) | C48: =C21+C38+C45
...

Sheet 13. Summary
B2: RESUMEN DE VALORACIÓN — Lululemon Athletica Inc. | DCE Holdings
B3: Fecha de Valoración: 03-May-2026 | Precio: $137.70
B5: ESCALERA COLUMBIA
B6: Reproduction Value / acción | C6: ='8. RV'!E40
B7: EPV / acción | C7: ='10. EPV'!C31
B8: Precio Actual | C8: ='1. Overview'!C17
B9: EPV / RV ratio | C9: =C7/C6
B10: Precio / EPV ratio | C10: =C8/C7
B11: Implied IRR (Equity) | C11: ='12. Implied IRR'!C51
B12: Hurdle Rate | C12: 0.12
B14: MARGEN DE SEGURIDAD
B15: MoS EPV = (EPV − Price) / EPV | C15: ='10. EPV'!C36
B16: MoS Implied IRR = Ret Equity − Hurdle | C16: ='12. Implied IRR'!C53
B18: WACC / ROIC / SPREAD
B19: WACC | C19: ='10. EPV'!C13
B20: ROIC FY2025 | C20: =IF(ISTEXT('11. ROIC'!H14),"N/M",'11. ROIC'!H14)
B21: Spread (ROIC − WACC) | C21: =IF(ISTEXT('11. ROIC'!H14),"N/M",'11. ROIC'!H14-'10. EPV'!C13)
B22: FCF Margin | C22: ='4. CF'!H22/'2. IS'!H5
B23: Operating Margin | C23: ='2. IS'!H21
B25: NOTAS:
B26: • Lululemon es una compañía asset-light premium athleisure: el moat reside en marca y comunidad, no en activos físicos. Por tanto, EPV >> RV es esperable.
B27: • ROIC sostenido >20% indica franchise value real; la diferencia entre EPV y RV cuantifica el moat brand-driven.
B28: • Mirror impairment FY2023 ($408M) normalizado — fue una M&A fallida, no parte del earning power sostenible.
B29: • Riesgo principal (DP16): pérdida sostenida de cuota US Women's podría comprimir crecimiento; sensibilizar 18x/22x/25x exit multiple.
B30: • Capital Allocation: zero deuda, $1.18B buybacks FY2025 (record); flexibilidad financiera total para responder a shocks.
B32: RESUMEN DE DECISIONES (Decision Points)
B33: # | C33: Decision | D33: Value Chosen | E33: Rationale
B34: DP1 | C34: S&M Proxy | D34: Marketing/Brand Spend (~3.3% Rev) | E34: Estimación basada en peer apparel; LULU no desglosa explícito
B35: DP2 | C35: R&D Capitalization | D35: N/A | E35: LULU no reporta R&D separado; producto/diseño implícito en SG&A
B36: DP3 | C36: S&M Useful Life | D36: 3 años | E36: Ciclo athleisure: brand recall y product LTV ~3yr
B37: DP4 | C37: R&D Useful Life | D37: N/A | E37: Sigue DP2
B38: DP5 | C38: SBC Treatment | D38: Case A — ya en SG&A | E38: No restar de nuevo en NOPAT
B39: DP6 | C39: Ventana Normalización | D39: 6yr (FY2020–FY2025) | E39: Adoptado del PFM Hespérides
B40: DP7 | C40: Items Normalizados | D40: Mirror impair FY2023 $408M | E40: M&A fallida; eliminar para earning power sostenible
B41: DP8 | C41: Tax Rate Normalizado | D41: 28% | E41: Adoptado del PFM (median ETR + uplift)
B42: DP9 | C42: Lease Treatment | D42: ASC 842 aplicado | E42: Usar valores reportados; no double-capitalize
B43: DP10 | C43: Non-Operating Assets | D43: Excess Cash ~$1,585M | E43: Cash − 2% Revenue buffer
B44: DP11 | C44: WACC Inputs | D44: Rf 4.39% + β 1.30 × ERP 4.50% = 10.25% | E44: Zero debt → WACC = Ke
... B49: DP16 | C49: Adverse Shock | D49: Tipo A — Demand Shock | E49: Pérdida US Women's >300bps trigger; rev →0-2%, op margin compresión 200-300bps
B52: Source: DCE Calculation | Modelo construido bajo Columbia Framework v4.1 | DCE Holdings | 03-May-2026

Sheet 14. Audit
B2: AUDIT LOG — Lululemon Athletica Inc. Columbia Model
B3: Verificaciones de integridad en 6 capas (A-F)
B4: Check | C4: Result | D4: Notes
B5: LAYER A: STRUCTURAL INTEGRITY
B6: 14 sheets present | C6: ✓ | D6: Overview, IS, BS, CF, Health, S&M Cap, R&D Cap, RV, NOPAT, EPV, ROIC, Implied IRR, Summary, Audit
B7: Tab order correct | C7: ✓ | D7: Numbered prefix 1-14
B8: Tab colors per spec | C8: ✓ | D8: NAVY/Blue/Green/Purple/Brown/Gray
B9: 6 fiscal years (FY2020-FY2025) | C9: ✓ | D9: Per DP6
B11: LAYER B: BALANCE SHEET CHECK
B12: BS Balance FY2020: Total Assets − (Total Liab + Equity) | C12: ='3. BS'!C19-'3. BS'!C33 | D12: Must = 0
B13: BS Balance FY2021: Total Assets − (Total Liab + Equity) | C13: ='3. BS'!D19-'3. BS'!D33 | D13: Must = 0
B14: BS Balance FY2022: Total Assets − (Total Liab + Equity) | C14: ='3. BS'!E19-'3. BS'!E33 | D14: Must = 0
B15: BS Balance FY2023: Total Assets − (Total Liab + Equity) | C15: ='3. BS'!F19-'3. BS'!F33 | D15: Must = 0
B16: BS Balance FY2024: Total Assets − (Total Liab + Equity) | C16: ='3. BS'!G19-'3. BS'!G33 | D16: Must = 0
B17: BS Balance FY2025: Total Assets − (Total Liab + Equity) | C17: ='3. BS'!H19-'3. BS'!H33 | D17: Must = 0
B19: LAYER C: CASH FLOW RECONCILIATION
B20: CFO + CFI + CFF Net Change (FY2020) | C20: ='4. CF'!C21 | D20: Net change in cash
B21: CFO + CFI + CFF Net Change (FY2021) | C21: ='4. CF'!D21 | D21: Net change in cash
B22: CFO + CFI + CFF Net Change (FY2022) | C22: ='4. CF'!E21 | D22: Net change in cash
B23: CFO + CFI + CFF Net Change (FY2023) | C23: ='4. CF'!F21 | D23: Net change in cash
B24: CFO + CFI + CFF Net Change (FY2024) | C24: ='4. CF'!G21 | D24: Net change in cash
B25: CFO + CFI + CFF Net Change (FY2025) | C25: ='4. CF'!H21 | D25: Net change in cash
B27: LAYER D: 10-K RECONCILIATION (FY2025)
B28: Revenue FY2025 = $11,100M | C28: ='2. IS'!H5 | D28: Match: $11100M
B29: Operating Income FY2025 = $2,346M | C29: ='2. IS'!H13 | D29: Match: $2346M
B30: Net Income FY2025 = $1,686M | C30: ='2. IS'!H17 | D30: Match: $1686M
B31: Total Assets FY2025 = $8,400M | C31: ='3. BS'!H19 | D31: Match: $8400M
B32: Total Liabilities FY2025 = $3,513M | C32: ='3. BS'!H30 | D32: Match: $3513M
B33: CFO FY2025 = $1,603M | C33: ='4. CF'!H12 | D33: Match: $1603M
B35: LAYER E: WACC VERIFICATION
B36: Risk-Free Rate 4.39% | C36: ='10. EPV'!C6 | D36: YCharts 1-May-2026
B37: Beta 1.30 | C37: ='10. EPV'!C7 | D37: Median raw + alphaspread
B38: ERP 4.50% | C38: ='10. EPV'!C8 | D38: Damodaran 2026
B39: Cost of Equity = Rf + β×ERP | C39: ='10. EPV'!C9 | D39: Should ≈ 10.24%
B40: WACC = Ke (zero debt) | C40: ='10. EPV'!C13 | D40: Should ≈ 10.25%
B42: LAYER F: DECISION POINT CONSISTENCY
B43: Tax Rate Normalizado (DP8) | C43: ='9. NOPAT'!C6 | D43: 28% per DP8
B44: S&M Useful Life (DP3) | C44: ='6. S&M Cap'!C5 | D44: 3 years per DP3
B45: Exit Multiple (DP15) | C45: ='12. Implied IRR'!C43 | D45: 22x per DP15
B46: NOPAT Normalizado > 0 | C46: =IF('9. NOPAT'!J26>0,"✓","✗") | D46: Sanity check
...
