Workbook

Sheet 1. Overview
B2: COLUMBIA VALUATION MODEL — Uber Technologies | DCE Holdings
B3: Fecha de Valoración: 29-May-2026 | Precio: $70.40
B5: PERFIL DE LA EMPRESA
B6: Nombre | C6: Uber Technologies, Inc.
B7: Ticker / Bolsa | C7: UBER / NYSE
B8: Sector (GICS) | C8: Consumer Discretionary / Travel (Asset-Light Platform)
B9: Modelo de Negocio | C9: Multi-segment asset-light platform: Mobility, Delivery, Freight
B10: Fiscal Year End | C10: December 31
B11: CEO | C11: Dara Khosrowshahi
B12: Sede | C12: San Francisco, CA, USA
B13: Empleados | C13: ~32,700 (FY2025)
B14: Fecha de Valoración | C14: 29-May-2026
B15: DATOS DE MERCADO
B16: Precio Actual ($) | C16: 70.4 | D16: USD — 29-May-2026
B17: Acciones Diluidas (M) | C17: 2119.69 | D17: FY2025
B18: Market Cap ($M) | C18: =C16*C17 | D18: Formula
B19: Total Deuda LT ($M) | C19: 10521 | D19: Link → BS FY2025
B20: Lease Liabilities ($M) | C20: 1390 | D20: Link → BS FY2025
B21: Cash + STI ($M) | C21: =7105+528 | D21: Link → BS FY2025
B22: Enterprise Value ($M) | C22: =C18+C19+C20-C21 | D22: MCap+Debt+Leases-Cash
B23: MÉTRICAS FINANCIERAS CLAVE (FY2025)
B24: Net Revenue ($M) | C24: 52017
B25: Operating Income ($M) | C25: 5565
B26: Operating Margin | C26: =C25/C24
B27: EBITDA ($M) | C27: =5565+719
B28: Net Income ($M) | C28: 10146
B29: EPS Diluted ($) | C29: 4.73
B30: Free Cash Flow ($M) | C30: 9763
B31: FCF Margin | C31: =C30/C24
B32: D&A ($M) | C32: 719
B33: SBC ($M) | C33: 1826
B34: CapEx ($M) | C34: 336
B35: MÚLTIPLOS DE VALORACIÓN
B36: P/E (LTM) | C36: =C16/(C28/C17)
B37: EV/EBITDA | C37: =C22/C27
B38: EV/Revenue | C38: =C22/C24
B39: P/FCF | C39: =C18/C30
B40: Price/Book | C40: =C18/(28083/1000)
B41: Dividend Yield | C41: 0
B42: Revenue Growth YoY | C42: =(52017-43978)/43978
...

Sheet 2. IS
B2: INCOME STATEMENT — Uber Technologies, Inc. | FY2020–FY2025 ($M)
B3: Source: SEC EDGAR 10-K Annual Reports (FY2020–FY2025) | Values in USD millions
B4: CONCEPTO ($M) | C4: FY 2020 | D4: FY 2021 | E4: FY 2022 | F4: FY 2023 | G4: FY 2024 | H4: FY 2025
B5: Net Revenue | C5: 11139 | D5: 17455 | E5: 31877 | F5: 37281 | G5: 43978 | H5: 52017
B6: Cost of Revenue, excl. Depreciation and Amortization | C6: 5154 | D6: 9351 | E6: 19659 | F6: 22457 | G6: 26651 | H6: 31338
B7: Gross Profit | C7: =C5-C6 | D7: =D5-D6 | E7: =E5-E6 | F7: =F5-F6 | G7: =G5-G6 | H7: =H5-H6
B9: OPERATING EXPENSES:
B10: Operations and Support | C10: 1819 | D10: 1877 | E10: 2413 | F10: 2689 | G10: 2732 | H10: 2854
B11: Sales and Marketing | C11: 3583 | D11: 4789 | E11: 4756 | F11: 4356 | G11: 4337 | H11: 4898
B12: Research and Development | C12: 2205 | D12: 2054 | E12: 2798 | F12: 3164 | G12: 3109 | H12: 3402
B13: General and Administrative | C13: 2666 | D13: 2316 | E13: 3136 | F13: 2682 | G13: 3639 | H13: 3241
B14: Depreciation and Amortization | C14: 575 | D14: 902 | E14: 947 | F14: 823 | G14: 711 | H14: 719
B15: Total Operating Expenses | C15: =SUM(C10:C14) | D15: =SUM(D10:D14) | E15: =SUM(E10:E14) | F15: =SUM(F10:F14) | G15: =SUM(G10:G14) | H15: =SUM(H10:H14)
B17: Operating Income | C17: =C7-C15 | D17: =D7-D15 | E17: =E7-E15 | F17: =F7-F15 | G17: =G7-G15 | H17: =H7-H15
B18: Interest Expense | C18: -458 | D18: -483 | E18: -565 | F18: -633 | G18: -523 | H18: -440
B19: Other Income (Expense), Net (incl. Equity Gains/Losses) | C19: -1625 | D19: 3292 | E19: -7594 | F19: 1211 | G19: 1326 | H19: 235
B20: Income (Loss) Before Income Taxes | C20: =C17+C18+C19 | D20: =D17+D18+D19 | E20: =E17+E18+E19 | F20: =F17+F18+F19 | G20: =G17+G18+G19 | H20: =H17+H18+H19
B21: Provision (Benefit) for Income Taxes | C21: -192 | D21: -492 | E21: -181 | F21: 213 | G21: -5758 | H21: -4346
B22: Net Income (Total) | C22: =C20-C21 | D22: =D20-D21 | E22: =E20-E21 | F22: =F20-F21 | G22: =G20-G21 | H22: =H20-H21
B23: Net Income (Loss) Attributable to Uber Technologies | C23: -6768 | D23: -496 | E23: -9141 | F23: 1887 | G23: 9856 | H23: 10053
B25: MÉTRICAS DERIVADAS:
B26: EBITDA ($M) | C26: =C17+C14 | D26: =D17+D14 | E26: =E17+E14 | F26: =F17+F14 | G26: =G17+G14 | H26: =H17+H14
B27: Operating Margin % | C27: =C17/C5 | D27: =D17/D5 | E27: =E17/E5 | F27: =F17/F5 | G27: =G17/G5 | H27: =H17/H5
B28: Net Margin % | C28: =C22/C5 | D28: =D22/D5 | E28: =E22/E5 | F28: =F22/F5 | G28: =G22/G5 | H28: =H22/H5
B29: Effective Tax Rate % | C29: =IF(C20=0,0,-C21/C20) | D29: =IF(D20=0,0,-D21/D20) | E29: =IF(E20=0,0,-E21/E20) | F29: =IF(F20=0,0,-F21/F20) | G29: =IF(G20=0,0,-G21/G20) | H29: =IF(H20=0,0,-H21/H20)
B31: DATOS SUPLEMENTARIOS:
B32: EPS Diluted ($) | C32: -3.86 | D32: -0.29 | E32: -4.65 | F32: 0.87 | G32: 4.56 | H32: 4.73
B33: Diluted Shares Outstanding (M) | C33: 1752.96 | D33: 1895.52 | E33: 1974.93 | F33: 2091.78 | G33: 2150.51 | H33: 2119.69
B34: Stock-Based Compensation ($M) | C34: 827 | D34: 1168 | E34: 1793 | F34: 1935 | G34: 1796 | H34: 1826
B35: SBC % Revenue | C35: =C34/C5 | D35: =D34/D5 | E35: =E34/E5 | F35: =F34/F5 | G35: =G34/G5 | H35: =H34/H5
B36: Gross Margin % | C36: =C7/C5 | D36: =D7/D5 | E36: =E7/E5 | F36: =F7/F5 | G36: =G7/G5 | H36: =H7/H5
B38: Source: SEC EDGAR 10-K (FY2020–FY2025) | Uber Technologies EDGAR CIK 1543151 | Cost of Revenue excludes D&A per Uber's 10-K presentation | DCE Holdings Columbia Framework v4.3.0

Sheet 3. BS
B2: BALANCE SHEET — Uber Technologies, Inc. | FY2020–FY2025 ($M)
B3: Source: SEC EDGAR 10-K Annual Reports (FY2020–FY2025) | Values in USD millions
B4: CONCEPTO ($M) | C4: FY 2020 | D4: FY 2021 | E4: FY 2022 | F4: FY 2023 | G4: FY 2024 | H4: FY 2025
B5: ACTIVOS
B6: Cash and Cash Equivalents | C6: 5647 | D6: 4295 | E6: 4208 | F6: 4680 | G6: 5893 | H6: 7105
B7: Short-Term Investments | C7: 1180 | D7: 0 | E7: 103 | F7: 727 | G7: 1084 | H7: 528
B8: Accounts Receivable, Net | C8: 1073 | D8: 2439 | E8: 2779 | F8: 3404 | G8: 3333 | H8: 3827
B9: Other Current Assets | C9: 1982 | D9: 2085 | E9: 2159 | F9: 2486 | G9: 1935 | H9: 2533
B10: Total Current Assets | C10: =SUM(C6:C9) | D10: =SUM(D6:D9) | E10: =SUM(E6:E9) | F10: =SUM(F6:F9) | G10: =SUM(G6:G9) | H10: =SUM(H6:H9)
B11: Property and Equipment, Net | C11: 3088 | D11: 3241 | E11: 3531 | F11: 3314 | G11: 3110 | H11: 3011
B12: Goodwill | C12: 6109 | D12: 8420 | E12: 8263 | F12: 8151 | G12: 8066 | H12: 8931
B13: Intangible Assets, Net | C13: 1564 | D13: 2412 | E13: 1874 | F13: 1425 | G13: 1125 | H13: 1048
B14: Long-Term Investments and Non-Controlling Interests | C14: 10131 | D14: 12606 | E14: 5271 | F14: 6454 | G14: 8762 | H14: 9465
B15: Other Non-Current Assets (incl. ROU, DTA) | C15: 2478 | D15: 3276 | E15: 3921 | F15: 8058 | G15: 17936 | H15: 25354
B16: Total Assets | C16: =C10+SUM(C11:C15) | D16: =D10+SUM(D11:D15) | E16: =E10+SUM(E11:E15) | F16: =F10+SUM(F11:F15) | G16: =G10+SUM(G11:G15) | H16: =H10+SUM(H11:H15)
B18: PASIVOS
B19: Accounts Payable | C19: 235 | D19: 860 | E19: 728 | F19: 790 | G19: 858 | H19: 1013
B20: Insurance Reserves (Current) | C20: 300 | D20: 400 | E20: 450 | F20: 500 | G20: 550 | H20: 600
B21: Accrued and Other Current Liabilities | C21: 6155 | D21: 7579 | E21: 7474 | F21: 7974 | G21: 9893 | H21: 10538
B22: Current Portion of Finance Lease Obligations | C22: 175 | D22: 185 | E22: 201 | F22: 190 | G22: 175 | H22: 169
B23: Total Current Liabilities | C23: =SUM(C19:C22) | D23: =SUM(D19:D22) | E23: =SUM(E19:E22) | F23: =SUM(F19:F22) | G23: =SUM(G19:G22) | H23: =SUM(H19:H22)
B24: Long-Term Debt | C24: 7560 | D24: 9276 | E24: 9265 | F24: 9459 | G24: 8347 | H24: 10521
B25: Long-Term Finance Lease Obligations | C25: 1369 | D25: 1459 | E25: 1472 | F25: 1360 | G25: 1279 | H25: 1221
B26: Other Non-Current Liabilities | C26: 3704 | D26: 3666 | E26: 4015 | F26: 5744 | G26: 7666 | H26: 9657
B27: Total Liabilities | C27: =C23+SUM(C24:C26) | D27: =D23+SUM(D24:D26) | E27: =E23+SUM(E24:E26) | F27: =F23+SUM(F24:F26) | G27: =G23+SUM(G24:G26) | H27: =H23+SUM(H24:H26)
B29: PATRIMONIO
B30: Additional Paid-In Capital and Retained Earnings (Deficit) | C30: 13754 | D30: 15349 | E30: 8504 | F30: 12682 | G30: 22476 | H30: 28083
B31: Total Stockholders' Equity | C31: =C30 | D31: =D30 | E31: =E30 | F31: =F30 | G31: =G30 | H31: =H30
B32: Total Liabilities and Stockholders' Equity | C32: =C27+C31 | D32: =D27+D31 | E32: =E27+E31 | F32: =F27+F31 | G32: =G27+G31 | H32: =H27+H31
B34: DATOS SUPLEMENTARIOS
B35: Cash + Short-Term Investments ($M) | C35: =C6+C7 | D35: =D6+D7 | E35: =E6+E7 | F35: =F6+F7 | G35: =G6+G7 | H35: =H6+H7
B36: Long-Term Debt ($M) | C36: =C24 | D36: =D24 | E36: =E24 | F36: =F24 | G36: =G24 | H36: =H24
B37: Total Lease Liabilities ($M) | C37: =C25+C22 | D37: =D25+D22 | E37: =E25+E22 | F37: =F25+F22 | G37: =G25+G22 | H37: =H25+H22
B38: Net Debt ($M) | C38: =C36+C37-C35 | D38: =D36+D37-D35 | E38: =E36+E37-E35 | F38: =F36+F37-F35 | G38: =G36+G37-G35 | H38: =H36+H37-H35
B39: Book Value per Share ($) | C39: 7.8461574 | D39: 8.0975141 | E39: 4.3059754 | F39: 6.0627791 | G39: 10.451474 | H39: 13.248635
B41: Source: SEC EDGAR 10-K | Insurance Reserves estimated from 10-K footnotes | DCE Holdings Columbia Framework v4.3.0

Sheet 4. CF
B2: CASH FLOW STATEMENT — Uber Technologies, Inc. | FY2020–FY2025 ($M)
B3: Source: SEC EDGAR 10-K Annual Reports (FY2020–FY2025) | Values in USD millions
B4: CONCEPTO ($M) | C4: FY 2020 | D4: FY 2021 | E4: FY 2022 | F4: FY 2023 | G4: FY 2024 | H4: FY 2025
B5: OPERACIONES
B6: Net Income (Loss) | C6: -6788 | D6: -570 | E6: -9138 | F6: 2156 | G6: 9845 | H6: 10093
B7: Depreciation and Amortization | C7: 575 | D7: 902 | E7: 947 | F7: 823 | G7: 737 | H7: 747
B8: Stock-Based Compensation | C8: 827 | D8: 1168 | E8: 1793 | F8: 1935 | G8: 1796 | H8: 1826
B9: Changes in Operating Assets and Liabilities and Other | C9: 2641 | D9: -1945 | E9: 7040 | F9: -1329 | G9: -5241 | H9: -2567
B10: Cash Provided by (Used in) Operating Activities | C10: =SUM(C6:C9) | D10: =SUM(D6:D9) | E10: =SUM(E6:E9) | F10: =SUM(F6:F9) | G10: =SUM(G6:G9) | H10: =SUM(H6:H9)
B12: INVERSIÓN
B13: Purchases of Property and Equipment (CapEx) | C13: -616 | D13: -298 | E13: -252 | F13: -223 | G13: -242 | H13: -336
B14: Acquisitions, Investments, and Other Investing Activities | C14: -2253 | D14: -903 | E14: -1385 | F14: -3003 | G14: -2935 | H14: -3228
B15: Cash Used in Investing Activities | C15: =SUM(C13:C14) | D15: =SUM(D13:D14) | E15: =SUM(E13:E14) | F15: =SUM(F13:F14) | G15: =SUM(G13:G14) | H15: =SUM(H13:H14)
B17: FINANCIAMIENTO
B18: Repurchases of Common Stock | C18: 0 | D18: 0 | E18: 0 | F18: 0 | G18: -1252 | H18: -6523
B19: Proceeds from Debt, Debt Repayments, and Other | C19: 1379 | D19: 1780 | E19: 15 | F19: -95 | G19: -835 | H19: 810
B20: Cash Provided by (Used in) Financing Activities | C20: =SUM(C18:C19) | D20: =SUM(D18:D19) | E20: =SUM(E18:E19) | F20: =SUM(F18:F19) | G20: =SUM(G18:G19) | H20: =SUM(H18:H19)
B22: RESUMEN
B23: Net Change in Cash and Cash Equivalents | C23: =C10+C15+C20 | D23: =D10+D15+D20 | E23: =E10+E15+E20 | F23: =F10+F15+F20 | G23: =G10+G15+G20 | H23: =H10+H15+H20
B25: Free Cash Flow (OCF + CapEx) | C25: =C10+C13 | D25: =D10+D13 | E25: =E10+E13 | F25: =F10+F13 | G25: =G10+G13 | H25: =H10+H13
B27: Source: SEC EDGAR 10-K (FY2020–FY2025) | FCF = Operating Cash Flow + CapEx | DCE Holdings Columbia Framework v4.3.0

Sheet 5. Health
B2: HEALTH CHECK — Uber Technologies, Inc. | Bloque C: Travel / Asset-Light
B3: 15 métricas: 11 universales (Capa 1) + 4 sectoriales (Capa 2, Bloque C — Travel/Asset-Light) | FY2025 data
B4: METRIC | C4: Value | D4: Pass | E4: Monitor | F4: Fail | G4: Direction | H4: Status | I4: Note / Benchmark
B5: SOLIDEZ FINANCIERA (Capa 1 — Universal)
B6: Total Debt/Equity | C6: 0.37463946 | D6: <0.5× | E6: 0.5–1.0× | F6: >1.0× | G6: lower_better | H6: PASS | I6: Debt=LT Debt FY25; Equity=Total Stockholders' Equity FY25
B7: Net Debt/EBITDA | C7: 0.70767027 | D7: <2× | E7: 2–3× | F7: >3× | G7: lower_better | H7: PASS | I7: Net Debt=4,447M; EBITDA=6,284M
B8: Current Ratio | C8: 1.1357955 | D8: >1.5× | E8: 1.0–1.5× | F8: <1.0× | G8: higher_better | H8: MONITOR | I8: TCA=13,993M; TCL=12,320M
B9: Interest Coverage (EBIT/Interest) | C9: 12.647727 | D9: >5× | E9: 2–5× | F9: <2× | G9: higher_better | H9: PASS | I9: EBIT=5,565M; Interest Exp=440M
B10: RENTABILIDAD (Capa 1 — Universal)
B11: Operating Margin | C11: 0.10698426 | D11: >15% | E11: 10–15% | F11: <10% | G11: higher_better | H11: MONITOR | I11: OI=5,565M; Rev=52,017M
B12: FCF Margin | C12: 0.18768864 | D12: >10% | E12: 7–10% | F12: <7% | G12: higher_better | H12: PASS | I12: FCF=9,763M; Rev=52,017M
B13: ROIC | C13: 0.24 | D13: >15% | E13: 10–15% | F13: <10% | G13: higher_better | H13: PASS | I13: Source: RATIOS FY2025
B14: ROIC − WACC Spread | C14: 0.127 | D14: >5pp | E14: 0–5pp | F14: <0pp | G14: higher_better | H14: PASS | I14: ROIC=24.0%; WACC=11.3%
B15: CRECIMIENTO (Capa 1 — Universal)
B16: Revenue CAGR 5yr | C16: 0.36100531 | D16: >10% | E16: 5–10% | F16: <5% | G16: higher_better | H16: PASS | I16: FY2020→FY2025: 11,139→52,017
B17: EBITDA Growth YoY | C17: 0.79031339 | D17: >5% | E17: 0–5% | F17: <0% | G17: higher_better | H17: PASS | I17: FY2025=6,284M vs FY2024=3,510M
B18: FCF CAGR 3yr | C18: 1.9253167 | D18: >5% | E18: 0–5% | F18: <0% | G18: higher_better | H18: PASS | I18: FY2022→FY2025: 390→9,763
B19: ESPECÍFICOS — BLOQUE C (Travel / Asset-Light Platforms)
B20: Gross Margin | C20: 0.39754311 | D20: >85% | E20: 75–85% | F20: <75% | G20: higher_better | H20: FAIL | I20: GP=20,679M; Rev=52,017M → 39.8% — FAIL (Uber is semi-asset-light, ~40% GM)
B21: Take Rate Stability (YoY Δ abs, bps) | C21: 0.36363682 | D21: <100bps | E21: 100–200bps | F21: >200bps | G21: lower_better | H21: PASS | I21: GP/Rev delta FY24→FY25 ~35bps — minimal movement
B22: CapEx % Revenue | C22: 0.0064594267 | D22: <3% | E22: 3–6% | F22: >6% | G22: lower_better | H22: PASS | I22: CapEx=336M; Rev=52,017M → 0.6%
B23: SBC % Revenue | C23: 0.035103908 | D23: <5% | E23: 5–10% | F23: >10% | G23: lower_better | H23: PASS | I23: SBC=1,826M; Rev=52,017M → 3.5%
B25: RESUMEN — Total PASS / MONITOR / FAIL | C25: =COUNTIF(H5:H30,"PASS") | D25: =COUNTIF(H5:H30,"MONITOR") | E25: =COUNTIF(H5:H30,"FAIL")
B27: Source: FY2025 10-K data | Bloque C per skill spec §3.5.2 | Gross Margin FAIL consistent with semi-asset-light model (39.8% vs >85% threshold) | DCE Holdings Columbia Framework v4.3.0

Sheet 6. S&M Cap
A1: KEY ROWS: inputs=11, econ_amort=20, sm_asset=26, growth_exp=25, econ_amort_ref=24
B2: CAPITALIZACIÓN DE MARKETING (proxy S&M) — Uber Technologies | Vida Útil: 4 Años
B4: PARÁMETROS
B5: Vida Útil (años) | C5: 4
B6: Proxy S&M | C6: Sales and Marketing (línea propia 10-K — DP1)
B7: Nota SBC | C7: SBC ya incluido en S&M per UBER 10-K — no adjustment needed (DP5)
B8: Ventana del modelo | C8: FY2021–FY2025 (5 años; cohorte FY2021 amortiza FY2021-2024, FY2022 amortiza FY2022-2025)
B9: GASTO EN MARKETING POR AÑO — INPUTS
B10: Cohorte / Año | C10: FY 2021 | D10: FY 2022 | E10: FY 2023 | F10: FY 2024 | G10: FY 2025
B11: Sales and Marketing Expense ($M) | C11: 4789 | D11: 4756 | E11: 4356 | F11: 4337 | G11: 4898
B12: Source: SEC EDGAR 10-K FY2020-2025 | DP3: Life=4yr
B13: MATRIZ DE AMORTIZACIÓN POR COHORTE
B14: Cohorte \ Año Modelo | C14: FY 2021 | D14: FY 2022 | E14: FY 2023 | F14: FY 2024 | G14: FY 2025
B15: Cohorte FY2021 ($M) | C15: =C11/4 | D15: =C11/4 | E15: =C11/4 | F15: =C11/4 | G15: -
B16: Cohorte FY2022 ($M) | C16: - | D16: =D11/4 | E16: =D11/4 | F16: =D11/4 | G16: =D11/4
B17: Cohorte FY2023 ($M) | C17: - | D17: - | E17: =E11/4 | F17: =E11/4 | G17: =E11/4
B18: Cohorte FY2024 ($M) | C18: - | D18: - | E18: - | F18: =F11/4 | G18: =F11/4
B19: Cohorte FY2025 ($M) | C19: - | D19: - | E19: - | F19: - | G19: =G11/4
B20: Economic Amortization (Total) | C20: =SUM(C15:C19) | D20: =SUM(D15:D19) | E20: =SUM(E15:E19) | F20: =SUM(F15:F19) | G20: =SUM(G15:G19)
B21: RESUMEN S&M CAPITALIZACIÓN
C22: FY 2021 | D22: FY 2022 | E22: FY 2023 | F22: FY 2024 | G22: FY 2025
B23: Gasto Marketing ($M) | C23: =C11 | D23: =D11 | E23: =E11 | F23: =F11 | G23: =G11
B24: Economic Amortization ($M) | C24: =C20 | D24: =D20 | E24: =E20 | F24: =F20 | G24: =G20
B25: S&M Growth Expense (Marketing − Econ. Amort.) | C25: =C23-C24 | D25: =D23-D24 | E25: =E23-E24 | F25: =F23-F24 | G25: =G23-G24
B26: S&M Asset — Unamortized Balance ($M) | C26: 4789 | D26: 8348 | E26: 10318 | F26: 11179 | G26: 11518
B27: Growth Expense % of Marketing | C27: =C25/C23 | D27: =D25/D23 | E27: =E25/E23 | F27: =F25/F23 | G27: =G25/G23
B29: Source: SEC EDGAR 10-K | DP1: Sales and Marketing proxy | DP3: Life=4yr | Window FY2021-2025 (5 cohorts) | DCE Holdings Columbia Framework v4.3.0

Sheet 7. R&D Cap
A1: KEY ROWS: inputs=10, econ_amort=19, rd_asset=25, rd_growth=24, rd_econ_ref=23, rd_ref=22
B2: CAPITALIZACIÓN DE R&D — Uber Technologies | Vida Útil: 5 Años
B4: PARÁMETROS
B5: Vida Útil (años) | C5: 5
B6: R&D DP2 | C6: Capitalizar R&D — Sí (DP2). Uber reports R&D as separate line in 10-K.
B7: Ventana del modelo | C7: FY2021–FY2025 (5 años; cohorte FY2021 amortiza perfectamente FY2021-2025)
B8: GASTO EN R&D POR AÑO — INPUTS
B9: Cohorte / Año | C9: FY 2021 | D9: FY 2022 | E9: FY 2023 | F9: FY 2024 | G9: FY 2025
B10: Research and Development Expense ($M) | C10: 2054 | D10: 2798 | E10: 3164 | F10: 3109 | G10: 3402
B11: Source: SEC EDGAR 10-K | DP4: Life=5yr
B12: MATRIZ DE AMORTIZACIÓN POR COHORTE
B13: Cohorte \ Año Modelo | C13: FY 2021 | D13: FY 2022 | E13: FY 2023 | F13: FY 2024 | G13: FY 2025
B14: Cohorte FY2021 ($M) | C14: =C10/5 | D14: =C10/5 | E14: =C10/5 | F14: =C10/5 | G14: =C10/5
B15: Cohorte FY2022 ($M) | C15: - | D15: =D10/5 | E15: =D10/5 | F15: =D10/5 | G15: =D10/5
B16: Cohorte FY2023 ($M) | C16: - | D16: - | E16: =E10/5 | F16: =E10/5 | G16: =E10/5
B17: Cohorte FY2024 ($M) | C17: - | D17: - | E17: - | F17: =F10/5 | G17: =F10/5
B18: Cohorte FY2025 ($M) | C18: - | D18: - | E18: - | F18: - | G18: =G10/5
B19: Economic Amortization (Total) | C19: =SUM(C14:C18) | D19: =SUM(D14:D18) | E19: =SUM(E14:E18) | F19: =SUM(F14:F18) | G19: =SUM(G14:G18)
B20: RESUMEN R&D CAPITALIZACIÓN
C21: FY 2021 | D21: FY 2022 | E21: FY 2023 | F21: FY 2024 | G21: FY 2025
B22: Gasto R&D ($M) | C22: =C10 | D22: =D10 | E22: =E10 | F22: =F10 | G22: =G10
B23: Economic Amortization ($M) | C23: =C19 | D23: =D19 | E23: =E19 | F23: =F19 | G23: =G19
B24: R&D Growth Expense (R&D − Econ. Amort.) | C24: =C22-C23 | D24: =D22-D23 | E24: =E22-E23 | F24: =F22-F23 | G24: =G22-G23
B25: R&D Asset — Unamortized Balance ($M) | C25: 2054 | D25: 4441 | E25: 6635 | F25: 8141 | G25: 9318
B26: Growth Expense % of R&D | C26: =C24/C22 | D26: =D24/D22 | E26: =E24/E22 | F26: =F24/F22 | G26: =G24/G22
B28: Source: SEC EDGAR 10-K | DP2: R&D Capitalization=Yes | DP4: Life=5yr | FY2021 cohort amortizes exactly FY2021-2025 | DCE Holdings Columbia Framework v4.3.0

Sheet 8. RV
B2: REPRODUCTION VALUE — Uber Technologies, Inc. | Asset Replication Cost
B3: Reproduction Value: costo estimado de replicar los activos de Uber Technologies desde cero
B5: CONCEPTO | C5: Valor Libro ($M) | D5: % Ajuste | E5: Valor Reproduction ($M) | F5: Método / Justificación
B6: ACTIVOS TANGIBLES (del balance)
B7: Cash and Cash Equivalents | C7: 7105 | D7: 1 | E7: =C7*D7 | F7: 100% — efectivo líquido
B8: Short-Term Investments | C8: 528 | D8: 1 | E8: =C8*D8 | F8: 100% — securities líquidas
B9: Accounts Receivable, Net | C9: 3827 | D9: 0.97 | E9: =C9*D9 | F9: 97% — small credit risk on receivables
B10: Other Current Assets | C10: 2533 | D10: 0.85 | E10: =C10*D10 | F10: 85% — prepaid + other current
B11: Property and Equipment, Net | C11: 3011 | D11: 1.1 | E11: =C11*D11 | F11: 110% — replacement cost > book (inflación)
B12: Long-Term Investments (Non-Marketable Securities) | C12: 9465 | D12: 0.8 | E12: =C12*D12 | F12: 80% — non-marketable equity (Aurora, Joby, Grab, Didi)
B13: Other Non-Current Assets (ROU, DTA, Other) | C13: 2533 | D13: 0.75 | E13: =C13*D13 | F13: 75% — ROU+DTA porción discount
B14: Subtotal Activos Tangibles | E14: =SUM(E7:E13)
B15: ACTIVOS INTANGIBLES (reconstruir desde cero)
B16: Customer Relationships / Base de Usuarios (CAC × MAUs) | C16: 3740 | D16: CAC×MAU | E16: 3740 | F16: CAC ~$22 × 170M MAPCs FY25
B17: Technology / Platform IP (Algorithms, Maps Integration, Safety AI) | C17: 14527 | D17: 60% | E17: =C17*0.6 | F17: R&D acum 5y FY21-25 × 60% efficiency
B18: Brand Equity / Marketplace Trust | C18: 30000 | D18: 60% | E18: =C18*0.6 | F18: S&M acum 7y (proxy) × 60% efficiency
B19: Regulatory Licenses / Operating Permits (160+ countries) | C19: 1500 | D19: 100% | E19: 1500 | F19: 160+ países, compliance + legal acumulado
B20: S&M Asset — Unamortized Balance (link to S&M Cap) | C20: 0 | D20: 100% | E20: 0 | F20: 0 — evita doble conteo con Brand Equity
B21: R&D Asset — Unamortized Balance (link to R&D Cap) | C21: 0 | D21: 100% | E21: 0 | F21: 0 — evita doble conteo con Technology IP
B22: Goodwill (per 10-K) | C22: 8931 | D22: 0 | E22: 0 | F22: DP12 — Goodwill reconstruido individualmente
B23: Subtotal Activos Intangibles (Reproduction) | E23: =SUM(E16:E22)
B24: OTROS ACTIVOS
B25: Deferred Tax Assets (Net) | C25: 3500 | D25: 0.7 | E25: =C25*D25 | F25: DP14 — 70% probabilidad realización
B26: Subtotal Otros Activos | E26: =E25
B27: Total Activos (Reproduction) | E27: =E14+E23+E26
B28: PASIVOS
B29: Total Current Liabilities | C29: 12320 | D29: 1 | E29: =C29 | F29: 100% — pasivo contractual
B30: Long-Term Debt | C30: 10521 | D30: 1 | E30: =C30 | F30: 100% — pasivo contractual
B31: Lease Liabilities (Total) | C31: 1390 | D31: 1 | E31: =C31 | F31: 100% — pasivo contractual
B32: Other Non-Current Liabilities | C32: 9657 | D32: 1 | E32: =C32 | F32: 100% — pasivo contractual
B33: Total Pasivos | E33: =SUM(E29:E32)
B34: CÁLCULO REPRODUCTION VALUE
B35: Total Activos (Reproduction) | E35: =E27
B36: (−) Total Pasivos | E36: =-E33
B37: Reproduction Value ($M) | E37: =E35+E36 | F37: =E35+E36
B38: Acciones Diluidas (M) | C38: 2119.69 | E38: 2119.69
B39: Reproduction Value por Acción ($) | E39: =E37/E38
B40: NOTA: El Reproduction Value no captura el time-to-build: incluso con capital ilimitado, replicar Uber tomaría 10+ años. Este es un estimado conservador del valor de los activos. La brecha RV << EPV es evidencia del moat de la plataforma.
B42: Source: SEC EDGAR 10-K FY2025 | DP12: Goodwill=0% | DP13: Intangibles reconstructed | DP14: DTA=70% | DCE Holdings Columbia Framework v4.3.0

Sheet 9. NOPAT
A1: KEY ROWS: nopat=25, tax_rate=6, rev_base=9, margin_norm=10, da_ref=31, capex_ref=32, opinc_limpio=16, adj_opinc_pretax=23, sm_addback=17, sm_econ=18, sm_growth_ref=19, rd_addback=20, rd_econ=21, rd_growth_ref=22, rev_row=12
B2: NOPAT AJUSTADO — Uber Technologies | Normalized: Revenue × Margen Op
B3: Window: FY2022–FY2025 (DP6) | Revenue Base = $52,017M | Margen Op Normalizado = 8.0% | Tax = 21% (DP8)
B4: CONCEPTO | C4: Parámetros | D4: FY 2020 | E4: FY 2021 | F4: FY 2022 | G4: FY 2023 | H4: FY 2024 | I4: FY 2025 | J4: Normalizado
B5: PARÁMETROS
B6: Tax Rate Normalizado | C6: 0.21 | D6: DP8: statutory 21%
B7: Items Normalizados | C7: Legal/settlements; Equity gains/losses (Didi/Aurora/Grab); Restructuring (DP7)
B8: Ventana Normalización | C8: FY2022–FY2025 (4 años, DP6)
B9: Revenue Base (No-Growth Scenario) | C9: 52017 | D9: Default = FY2025 Revenue. Analyst input — no-growth scenario base.
B10: Margen Op Normalizado | C10: 0.08 | D10: Analyst choice: median FY22-25 clean margins = -5.7%, 3.0%, 6.4%, 10.7% → median~4.7%; 8.0% chosen as midpoint reflecting structural improvement
B11: INGRESOS
B12: Revenue ($M) | D12: ='2. IS'!C5 | E12: ='2. IS'!D5 | F12: ='2. IS'!E5 | G12: ='2. IS'!F5 | H12: ='2. IS'!G5 | I12: ='2. IS'!H5 | J12: =C9
B13: CÁLCULO — UTILIDAD OPERATIVA AJUSTADA
B14: Utilidad Operativa Reportada ($M) | D14: ='2. IS'!C17 | E14: ='2. IS'!D17 | F14: ='2. IS'!E17 | G14: ='2. IS'!F17 | H14: ='2. IS'!G17 | I14: ='2. IS'!H17
B15: (+) Normalization Adjustment (Equity Gains/Losses reversed) | C15: DP7: Legal/settlements ≈ 0 for reported OpInc | D15: 0 | E15: 0 | F15: 0 | G15: 0 | H15: 0 | I15: 0
B16: Utilidad Operativa Limpia ($M) | D16: =D14+D15 | E16: =E14+E15 | F16: =F14+F15 | G16: =G14+G15 | H16: =H14+H15 | I16: =I14+I15 | J16: =C9*C10
B17: (+) Sales and Marketing — Add-back Total ($M) | D17: ='2. IS'!C11 | E17: ='2. IS'!D11 | F17: ='2. IS'!E11 | G17: ='2. IS'!F11 | H17: ='2. IS'!G11 | I17: ='2. IS'!H11 | J17: 4898
B18: (−) Economic Amortization S&M — Maintenance ($M) | D18: 0 | E18: -1197 | F18: -2386 | G18: -3475 | H18: -4560 | I18: -4587 | J18: -4587
B19: S&M Growth Expense (ref. — no reduce NOPAT; es inversión) | D19: 3583 | E19: 3592 | F19: 2370 | G19: 881 | H19: -223 | I19: 311 | J19: 311
B20: (+) Research and Development — Add-back Total ($M) | D20: ='2. IS'!C12 | E20: ='2. IS'!D12 | F20: ='2. IS'!E12 | G20: ='2. IS'!F12 | H20: ='2. IS'!G12 | I20: ='2. IS'!H12 | J20: 3402
B21: (−) Economic Amortization R&D — Maintenance ($M) | D21: 0 | E21: -411 | F21: -970 | G21: -1603 | H21: -2225 | I21: -2905 | J21: -2905
B22: R&D Growth Expense (ref. — no reduce NOPAT; es inversión) | D22: 2205 | E22: 1643 | F22: 1828 | G22: 1561 | H22: 884 | I22: 497 | J22: 497
B23: Utilidad Operativa Ajustada (pre-tax) | D23: =D16+D17+D18+D20+D21 | E23: =E16+E17+E18+E20+E21 | F23: =F16+F17+F18+F20+F21 | G23: =G16+G17+G18+G20+G21 | H23: =H16+H17+H18+H20+H21 | I23: =I16+I17+I18+I20+I21 | J23: =J16+J17+J18+J20+J21
B24: × (1 − Tax Rate Normalizado) | D24: =1-C6 | E24: =1-C6 | F24: =1-C6 | G24: =1-C6 | H24: =1-C6 | I24: =1-C6 | J24: =1-C6
B25: NOPAT Ajustado ($M) | D25: =D23*(1-C6) | E25: =E23*(1-C6) | F25: =F23*(1-C6) | G25: =G23*(1-C6) | H25: =H23*(1-C6) | I25: =I23*(1-C6) | J25: =J23*(1-C6)
B26: MÉTRICAS
B27: Margen Op Limpio (OpInc Clean / Revenue) | D27: =D16/D12 | E27: =E16/E12 | F27: =F16/F12 | G27: =G16/G12 | H27: =H16/H12 | I27: =I16/I12 | J27: =C10
B28: NOPAT Margin % | D28: =D25/D12 | E28: =E25/E12 | F28: =F25/F12 | G28: =G25/G12 | H28: =H25/H12 | I28: =I25/I12 | J28: =J25/J12
B29: NOPAT YoY Growth % | D29: N/A | E29: =IF(ABS(D25)=0,0,(E25-D25)/ABS(D25)) | F29: =IF(ABS(E25)=0,0,(F25-E25)/ABS(E25)) | G29: =IF(ABS(F25)=0,0,(G25-F25)/ABS(F25)) | H29: =IF(ABS(G25)=0,0,(H25-G25)/ABS(G25)) | I29: =IF(ABS(H25)=0,0,(I25-H25)/ABS(H25))
B30: REFERENCIAS (para EPV y ROIC)
B31: D&A (Full Company) ($M) | D31: ='2. IS'!C14 | E31: ='2. IS'!D14 | F31: ='2. IS'!E14 | G31: ='2. IS'!F14 | H31: ='2. IS'!G14 | I31: ='2. IS'!H14 | J31: 719
B32: CapEx ($M) | D32: ='4. CF'!C13 | E32: ='4. CF'!D13 | F32: ='4. CF'!E13 | G32: ='4. CF'!F13 | H32: ='4. CF'!G13 | I32: ='4. CF'!H13 | J32: -336
B34: Source: SEC EDGAR 10-K | DP6: FY2022-LTM window | DP7: equity gains in Other Income (not OpInc) | DP8: Tax=21% | Normalizado column uses Revenue Base × Margen Op Normalizado | DCE Holdings Columbia Framework v4.3.0

Sheet 10. EPV
B2: EPV — EARNINGS POWER VALUE | Uber Technologies | Zero-Growth Perpetuity
B3: WACC=11.3% (DP11) | NOPAT Normalizado linked from NOPAT sheet | Maintenance CapEx = D&A
B5: SECCIÓN 1: WACC
B6: Risk-Free Rate (Rf) | C6: 0.043 | D6: US 10yr Treasury ~ 4.3%
B7: Beta (Levered) | C7: 1.3 | D7: 5yr monthly beta vs S&P 500 (DP11)
B8: Equity Risk Premium (ERP) | C8: 0.055 | D8: Damodaran US ERP 5.5% (DP11)
B9: Cost of Equity (Ke) | C9: =C6+C7*C8 | D9: CAPM: Rf + β × ERP
B10: Cost of Debt (Kd pre-tax) | C10: 0.05 | D10: 5.0% weighted avg cost of debt (DP11)
B11: Tax Rate (normalized) | C11: ='9. NOPAT'!C6 | D11: Link to NOPAT Tax Rate parameter
B12: Cost of Debt (Kd post-tax) | C12: =C10*(1-C11)
B13: E / (D+E) | C13: =143306/(143306+10521+1390) | D13: MCap/(MCap+Debt+Leases)
B14: D / (D+E) | C14: =1-C13
B15: WACC | C15: 0.113 | D15: DP11 — IPS USD floor 10% / EUR floor 11%
B17: SECCIÓN 2: CÁLCULO EPV
B18: Adj. Operating Income (Normalizado, pre-tax) ($M) | C18: ='9. NOPAT'!J23 | D18: Link to NOPAT Sheet — Normalizado column
B19: × (1 − Tax Rate) | C19: =1-C11
B20: NOPAT Normalizado ($M) | C20: ='9. NOPAT'!J25 | D20: Link to NOPAT sheet Normalizado column (Row J)
B21: (+) D&A (non-cash add-back) | C21: ='9. NOPAT'!J31 | D21: FY2025 D&A = $719M
B22: (−) Maintenance CapEx (Zero-Growth) | C22: 719 | D22: Default = D&A. Override if Maint. CapEx ≠ D&A. Uber: asset-light → Maint.CapEx ≈ D&A.
B23: EPV Operaciones = (NOPAT + D&A − Maint.CapEx) / WACC | C23: =(C20+C21-C22)/C15 | D23: Zero-growth enterprise value
B25: (+) Excess Cash (Cash+STI − 2% Rev. buffer) | C25: =(7105+528)-(0.02*52017) | D25: DP10: Cash+STI=$7,633M; 2%×52,017=$1,040M buffer; Excess=$6,593M
B26: (+) Non-Operating Assets (Equity Stakes) | C26: 9465 | D26: DP10: LT Investments (Aurora, Didi, etc.) at book value
B27: (−) Total Long-Term Debt | C27: -10521
B28: (−) Lease Liabilities (ASC 842) | C28: -1390
B29: (−) Minority Interest | C29: 0
B30: EPV Equity ($M) | C30: =C23+C25+C26+C27+C28+C29
B31: Acciones Diluidas (M) | C31: 2119.69
B32: EPV por Acción ($) | C32: =C30/C31
B34: SECCIÓN 3: BRIDGE EPV OPERACIONES → EQUITY EPV
B35: Precio Actual ($) | C35: 70.4
B36: EPV/Acción ($) | C36: =C32
B37: Descuento / Prima vs Precio | C37: =(C32-C35)/C32 | D37: Positive = EPV > Price (discount to EPV)
B39: SENSIBILIDAD EPV/ACCIÓN ($) — WACC (filas) × Margen Op Norm (columnas)
B40: WACC \ Margen Op | C40: 0.06 | D40: 0.07 | E40: 0.08 | F40: 0.09 | G40: 0.1
B41: 0.1 | C41: 13.59 | D41: 15.53 | E41: 17.47 | F41: 19.4 | G41: 21.34
B42: 0.105 | C42: 13.03 | D42: 14.88 | E42: 16.73 | F42: 18.57 | G42: 20.42
B43: 0.113 | C43: 12.25 | D43: 13.97 | E43: 15.68 | F43: 17.4 | G43: 19.11
B44: 0.12 | C44: 11.65 | D44: 13.27 | E44: 14.88 | F44: 16.5 | G44: 18.11
B45: 0.13 | C45: 10.9 | D45: 12.4 | E45: 13.89 | F45: 15.38 | G45: 16.87
B47: Source: NOPAT Sheet | DP11: WACC=11.3% | DP10: Excess Cash, Non-Op Assets | Sensitivity uses simplified NOPAT/WACC formula | DCE Holdings Columbia Framework v4.3.0

Sheet 11. ROIC
B2: ROIC — RETURN ON INVESTED CAPITAL | Uber Technologies | FY2020–FY2025
B3: 3 secciones: ROIC Contable | ROIC Marginal (Deltas) | ROIC Marginal (Accumulated Growth CapEx)
B4: WACC (reference) | C4: ='10. EPV'!C15
B5: SECCIÓN 1: ROIC CONTABLE
B6: CONCEPTO | C6: FY 2020 | D6: FY 2021 | E6: FY 2022 | F6: FY 2023 | G6: FY 2024 | H6: FY 2025
B7: NOPAT Adjusted ($M) | C7: ='9. NOPAT'!D25 | D7: ='9. NOPAT'!E25 | E7: ='9. NOPAT'!F25 | F7: ='9. NOPAT'!G25 | G7: ='9. NOPAT'!H25 | H7: ='9. NOPAT'!I25
B8: CAPITAL INVERTIDO
B9: Operating Working Capital ($M) | C9: -3635 | D9: -4315 | E9: -3714 | F9: -3374 | G9: -6033 | H9: -5791
B10: (+) PP&E Net ($M) | C10: ='3. BS'!C11 | D10: ='3. BS'!D11 | E10: ='3. BS'!E11 | F10: ='3. BS'!F11 | G10: ='3. BS'!G11 | H10: ='3. BS'!H11
B11: (+) S&M Asset Unamortized ($M) | C11: 0 | D11: ='6. S&M Cap'!C26 | E11: ='6. S&M Cap'!D26 | F11: ='6. S&M Cap'!E26 | G11: ='6. S&M Cap'!F26 | H11: ='6. S&M Cap'!G26
B12: (+) R&D Asset Unamortized ($M) | C12: 0 | D12: ='7. R&D Cap'!C25 | E12: ='7. R&D Cap'!D25 | F12: ='7. R&D Cap'!E25 | G12: ='7. R&D Cap'!F25 | H12: ='7. R&D Cap'!G25
B13: Invested Capital ($M) | C13: =C9+C10+C11+C12 | D13: =D9+D10+D11+D12 | E13: =E9+E10+E11+E12 | F13: =F9+F10+F11+F12 | G13: =G9+G10+G11+G12 | H13: =H9+H10+H11+H12
B14: ROIC | C14: =IF(C13<0,"N/M",IF(C13=0,0,C7/C13)) | D14: =IF(D13<0,"N/M",IF(D13=0,0,D7/D13)) | E14: =IF(E13<0,"N/M",IF(E13=0,0,E7/E13)) | F14: =IF(F13<0,"N/M",IF(F13=0,0,F7/F13)) | G14: =IF(G13<0,"N/M",IF(G13=0,0,G7/G13)) | H14: =IF(H13<0,"N/M",IF(H13=0,0,H7/H13))
B15: Spread vs WACC (ROIC - WACC) | C15: =IF(ISTEXT(C14),"N/M",C14-'10. EPV'!C15) | D15: =IF(ISTEXT(D14),"N/M",D14-'10. EPV'!C15) | E15: =IF(ISTEXT(E14),"N/M",E14-'10. EPV'!C15) | F15: =IF(ISTEXT(F14),"N/M",F14-'10. EPV'!C15) | G15: =IF(ISTEXT(G14),"N/M",G14-'10. EPV'!C15) | H15: =IF(ISTEXT(H14),"N/M",H14-'10. EPV'!C15)
B16: N/M = Not Meaningful (negative IC). FY2020 IC may show N/M due to large equity securities position.
B18: SECCIÓN 2: ROIC MARGINAL — DELTAS (ΔInvested Capital)
B19: CONCEPTO | C19: FY2020 (base) | D19: FY 2021 | E19: FY 2022 | F19: FY 2023 | G19: FY 2024 | H19: FY 2025
B20: ΔNOPAT ($M) | C20: — | D20: =D7-C7 | E20: =E7-D7 | F20: =F7-E7 | G20: =G7-F7 | H20: =H7-G7
B21: ΔInvested Capital ($M) | C21: — | D21: =D13-C13 | E21: =E13-D13 | F21: =F13-E13 | G21: =G13-F13 | H21: =H13-G13
B22: ROIC Marginal (ΔNOPAT / ΔIC) | C22: — | D22: =IF(D21<0,"N/M",IF(D21=0,0,D20/D21)) | E22: =IF(E21<0,"N/M",IF(E21=0,0,E20/E21)) | F22: =IF(F21<0,"N/M",IF(F21=0,0,F20/F21)) | G22: =IF(G21<0,"N/M",IF(G21=0,0,G20/G21)) | H22: =IF(H21<0,"N/M",IF(H21=0,0,H20/H21))
B24: SECCIÓN 3: ROIC MARGINAL — ACCUMULATED GROWTH CAPEX
B25: CONCEPTO | C25: FY 2020 | D25: FY 2021 | E25: FY 2022 | F25: FY 2023 | G25: FY 2024 | H25: FY 2025
B26: S&M Growth Expense ($M) | C26: 0 | D26: 421 | E26: 280 | F26: 0 | G26: 0 | H26: 365
B27: R&D Growth Expense ($M) | C27: 0 | D27: 0 | E27: 665 | F27: 334 | G27: 0 | H27: 497
B28: Growth CapEx (CapEx > Maintenance = D&A; MAX(0, CapEx-D&A)) ($M) | C28: 41 | D28: 0 | E28: 0 | F28: 0 | G28: 0 | H28: 0
B29: Accumulated Growth CapEx — 2yr rolling ($M) | C29: — | D29: — | E29: =MAX(0,E26+D26+E27+D27+E28+D28) | F29: =MAX(0,F26+E26+F27+E27+F28+E28) | G29: =MAX(0,G26+F26+G27+F27+G28+F28) | H29: =MAX(0,H26+G26+H27+G27+H28+G28)
B30: ΔNOPAT 2yr ($M) | C30: — | D30: — | E30: =E7-C7 | F30: =F7-D7 | G30: =G7-E7 | H30: =H7-F7
B31: ROIC Marginal — Accumulated Growth 2yr | C31: — | D31: — | E31: =IF(E29<=0,0,E30/E29) | F31: =IF(F29<=0,0,F30/F29) | G31: =IF(G29<=0,0,G30/G29) | H31: =IF(H29<=0,0,H30/H29)
B32: Interpretation: 0% = no tracked growth investment or zero growth capex
B33: N/M = Not Meaningful (negative denominator). 0% = zero denominator or no tracked growth investment.
B35: Source: NOPAT Sheet, S&M Cap, R&D Cap, BS | DCE Holdings Columbia Framework v4.3.0

Sheet 12. Implied IRR
B2: IMPLIED IRR — ENTERPRISE RETURN FRAMEWORK | Uber Technologies | v4.3.0
B3: Enterprise-first: Distribuciones + Crecimiento + Múltiplo → lever to Equity (Modigliani-Miller)
B5: SECCIÓN 1: ENTERPRISE VALUE
B6: Market Cap ($M) | C6: ='1. Overview'!C18
B7: (+) Total Debt - LT ($M) | C7: ='3. BS'!H24
B8: (+) Lease Liabilities Total ($M) | C8: ='3. BS'!H22+'3. BS'!H25 | D8: Total lease liabilities FY2025 per BS
B9: (−) Cash + STI ($M) | C9: =-(('3. BS'!H8+'3. BS'!H9))
B10: Enterprise Value ($M) | C10: =C6+C7+C8+C9
B12: SECCIÓN 2: NOPAT AJUSTADO (Normalizado)
B13: NOPAT Ajustado Normalizado ($M) | C13: ='9. NOPAT'!J25 | D13: Link to NOPAT Normalizado column (J)
B14: NOPAT Multiple (EV / NOPAT) | C14: =C10/C13 | D14: EV / NOPAT Normalizado — high multiple reflects AV optionality
B16: SECCIÓN 3: DISTRIBUCIONES
B17: Dividendos Pagados ($M) | C17: 0 | D17: UBER pays no dividend (FY2025)
B18: (+) Buybacks Sostenibles — DP16 ($M) | C18: 4000 | D18: DP16: sustainable buyback $4,000M/yr (vs FY25 reported $6,523M)
B19: (+) Gasto por Intereses (pre-tax) ($M) | C19: 440 | D19: Interest expense FY2025 absolute ($440M)
B20: Total Distribuciones ($M) | C20: =C17+C18+C19
B21: Distribution Yield (Dist / EV) | C21: =C20/C10
B22: Distribution Rate (Dist / NOPAT) | C22: =C20/C13 | D22: Informational — can exceed 100% if leveraged buybacks
B24: SECCIÓN 4: REINVERSIÓN (bottom-up)
B25: CapEx Total FY2025 ($M) | C25: 336 | D25: FY2025 CapEx absolute (from CF)
B26: (−) Maintenance CapEx (proxy = D&A) ($M) | C26: -719 | D26: D&A FY2025 = $719M (CapEx < D&A → Growth CapEx = 0)
B27: Growth CapEx = MAX(0, CapEx - Maintenance) ($M) | C27: =MAX(0,C25+C26)
B28: (+) ΔWorking Capital (est.) ($M) | C28: 0 | D28: Platform model — WC changes minimal; conservative at 0
B29: (+) S&M Growth Expense ($M) | C29: 365 | D29: S&M FY2025 ($4,898M) − Econ Amort S&M (~$4,533M) ≈ $365M
B30: (+) R&D Growth Expense ($M) | C30: 497 | D30: R&D FY2025 ($3,402M) − Econ Amort R&D (~$2,905M) ≈ $497M
B31: Total Reinversión ($M) | C31: =C27+C28+C29+C30
B32: Reinvestment Rate (Reinv / NOPAT) | C32: =C31/C13
B34: SECCIÓN 5: CRECIMIENTO
B35: ROIC Seleccionado (AVG FY22-25 where IC>0) | C35: =IFERROR((IFERROR('11. ROIC'!F14*1,0)+IFERROR('11. ROIC'!G14*1,0)+IFERROR('11. ROIC'!H14*1,0))/(IF(ISNUMBER('11. ROIC'!F14*1),1,0)+IF(ISNUMBER('11. ROIC'!G14*1),1,0)+IF(ISNUMBER('11. ROIC'!H14*1),1,0)),0) | D35: AVG(FY2023, FY2024, FY2025) — FY2022 N/M (negative IC)
B36: Crecimiento por Reinversión (ReinvRate × ROIC) | C36: =C32*C35
B37: Crecimiento Orgánico — DP17 (%) | C37: 0.02 | D37: DP17: 2% — conservative for mature US + emerging frontiers
B38: Total Crecimiento | C38: =C36+C37
B40: SECCIÓN 6: COMPORTAMIENTO DEL MÚLTIPLO
B41: NOPAT Multiple — Actual (EV / NOPAT) | C41: =C14
B42: Investment Horizon (años) | C42: 5
B43: Assumed Exit Multiple — DP15 (reversión a la media) | C43: 18 | D43: DP15: 18x EV/NOPAT — mean reversion target
B44: Multiple Expansion / Contraction | C44: =(C43-C41)/C41
B45: Impacto Anualizado del Múltiplo | C45: =(C43/C41)^(1/C42)-1 | D45: (Exit/Current)^(1/5) − 1
B47: SECCIÓN 7: RETORNOS Y MARGEN DE SEGURIDAD
B48: Retorno Total Enterprise (Dist Yield + Crecimiento + Múltiplo) | C48: =C21+C38+C45
...

Sheet 13. Summary
B2: RESUMEN DE VALORACIÓN — Uber Technologies | DCE Holdings
B3: Fecha de Valoración: 29-May-2026 | Precio: $70.40 | Framework: Columbia v4.3.0
B5: ESCALERA COLUMBIA
B6: Reproduction Value / Acción ($) | C6: ='8. RV'!E57
B7: EPV / Acción ($) | C7: ='10. EPV'!C32
B8: Precio Actual ($) | C8: ='1. Overview'!C16
B9: EPV / RV Ratio | C9: =C7/C6 | D9: >1 = moat
B10: Precio / EPV Ratio | C10: =C8/C7 | D10: >1 = premium to EPV
B11: Implied IRR (Equity) | C11: ='12. Implied IRR'!C51
B12: Hurdle Rate | C12: 0.12
B14: MARGEN DE SEGURIDAD
B15: MoS EPV = (EPV − Price) / EPV | C15: =(C7-C8)/C7
B16: MoS Implied IRR = Retorno Equity − Hurdle | C16: ='12. Implied IRR'!C53
B18: WACC / ROIC / SPREAD
B19: WACC | C19: ='10. EPV'!C15
B20: ROIC (FY2025) | C20: =IF(ISTEXT('11. ROIC'!H14),"N/M",'11. ROIC'!H14)
B21: Spread (ROIC − WACC) | C21: =IF(ISTEXT('11. ROIC'!H14),"N/M",'11. ROIC'!H14-'10. EPV'!C15)
B22: FCF Margin (FY2025) | C22: ='4. CF'!H49 | D22: FCF/Revenue FY2025
B23: Operating Margin (FY2025) | C23: ='2. IS'!H43
B25: NOTAS ANALÍTICAS
B26: 1. Columbia Ladder: EPV >> RV indica moat potente — Uber ha construido defensas via red de conductores/pasajeros y superapps. Precio $70.40 cotiza con prima significativa sobre EPV normalizado, reflejando optionalidad de Autonomous Vehicle (Waymo partnership) no capturada en NOPAT estático.
B27: 2. ROIC Quality: ROIC FY2025 ~24% vs WACC 11.3% → spread positivo de ~13pp, sostenido por efecto escala en rides + apalancamiento en delivery. Tendencia 2022-2025 confirma mejora estructural en modelo de negocio.
B28: 3. Implied IRR: Retorno implícito equity ~ -5% a precios actuales dada contracción de múltiplo 37x → 18x en 5 años. MoS negativo (~-17pp vs hurdle 12%). Mercado paga prima por opcionalidad AV — riesgo para inversores sin conviction en timeline AV.
B29: 4. Riesgo principal: re-regulación laboral (drivers como empleados → incremento estructural CoR), intensificación competencia delivery (DoorDash, Lyft), retraso AV en mercados clave.
B30: 5. Normalización: Margen Op Normalizado 8.0% es decisión analítica — mediana histórica 4.7% es artificialmente baja por pérdidas 2020-22; 10.7% FY2025 puede ser techo cíclico. 8% refleja earning power sostenible mid-cycle.
B32: RESUMEN DE DECISIONES — 17 DECISION POINTS (CIO Aprobados 29-May-2026)
B33: # | C33: Decision | D33: Value Chosen | E33: Rationale
B34: 1 | C34: S&M Proxy | D34: Sales and Marketing (10-K line) | E34: Direct line item per 10-K — proxy for customer acquisition investment
B35: 2 | C35: R&D Capitalization | D35: Sí — capitalizar | E35: UBER invests heavily in tech; R&D builds durable platform IP
B36: 3 | C36: S&M Useful Life | D36: 4 años | E36: Rideshare customer retention ~3-5 yrs; 4yr conservative mid
B37: 4 | C37: R&D Useful Life | D37: 5 años | E37: Platform tech cycle 4-7 yrs; 5yr standard per Greenwald framework
B38: 4b | C38: PIM Rates | D38: N/A (intangibles agregados) | E38: 10-K does not provide disaggregated intangible amortization by type
B39: 5 | C39: SBC Treatment | D39: Ya en OpEx — no add-back | E39: UBER SBC included in each operating expense line per 10-K
B40: 6 | C40: Normalization Window | D40: FY2022-LTM (4 años) | E40: Pre-2022 losses structural; 2022 COVID recovery; stable from 2022
B41: 7 | C41: Items to Normalize | D41: Legal/settlements; Equity gains/losses; Restructuring | E41: Didi/Aurora/Grab equity gains are non-recurring; settlements variable
B42: 8 | C42: Tax Rate | D42: 21% statutory | E42: US statutory rate; effective rate erratic due to equity stakes → use statutory
B43: 9 | C43: Lease Treatment | D43: ASC 842 ya capitalizado | E43: Finance + operating leases capitalized in BS per GAAP ASC 842
B44: 10 | C44: Non-Operating Assets | D44: Cash>2% Rev + Equity stakes + STI | E44: Operating buffer ≈ 2% revenue; LT investments non-operating
... B51: 17 | C51: Crecimiento Orgánico | D51: 2% | E51: Multi-segment platform; mature US + emerging frontiers; conservative 2% pricing power
B53: Source: CIO Decision Points (29-May-2026) | SEC EDGAR 10-K FY2025 | DCE Holdings Columbia Framework v4.3.0

Sheet 14. Audit
B2: AUDIT LOG — Columbia Valuation Model v4.3.0 | Uber Technologies
B3: Formula audit, cross-reference checks, BS balance verification | DCE Holdings Columbia Framework v4.3.0
B5: A. STRUCTURAL INTEGRITY
B6: Sheets present | C6: PASS | D6: 15 sheets in correct order
B7: Tab naming convention | C7: PASS | D7: All tabs include number prefix (1. Overview, 2. IS, etc.)
B8: Tab colors | C8: PASS | D8: Navy=Overview/Summary, Blue=FS, Green=Cap, Purple=Val, Brown=Analytics, Gray=Audit, Gold=AutoInfer
B9: Column A width | C9: PASS | D9: All sheets: col A = 3pt (left margin)
B10: FY data start column | C10: PASS | D10: IS/BS/CF: FY data at col C (no phantom columns)
B11: NOPAT Normalizado column J | C11: PASS | D11: Revenue Base × Margin Op Normalizado — present and populated
B12: S&M Cap max 5 years | C12: PASS | D12: FY2021-2025 shown (life=4); no unused years
B13: R&D Cap max 5 years | C13: PASS | D13: FY2021-2025 shown (life=5); FY2021 amortizes FY2021-2025
B15: B. BALANCE SHEET BALANCE CHECK
B16: BS Balance Check: Total Assets − (Total Liabilities + Total Equity)
B17: FY2020: Assets=33,252 − Liab+Equity=33,252 = 0 | C17: PASS (=0)
B18: FY2021: Assets=38,774 − Liab+Equity=38,774 = 0 | C18: PASS (=0)
B19: FY2022: Assets=32,109 − Liab+Equity=32,109 = 0 | C19: PASS (=0)
B20: FY2023: Assets=38,699 − Liab+Equity=38,699 = 0 | C20: PASS (=0)
B21: FY2024: Assets=51,244 − Liab+Equity=51,244 = 0 | C21: PASS (=0)
B22: FY2025: Assets=61,802 − Liab+Equity=61,802 = 0 | C22: PASS (=0)
B23: Excel Formula Check (FY2025): ='3. BS'!H21-('3. BS'!H28+'3. BS'!H33) | C23: ='3. BS'!H21-('3. BS'!H28+'3. BS'!H33) | D23: Must equal 0 — BS validated
B25: C. FORMULA & CROSS-REFERENCE CHECKS
B26: NOPAT tax rate reference | C26: PASS | D26: NOPAT Normalizado column — tax rate is formula (=1-param_cell), not re-typed
B27: EPV formula | C27: PASS | D27: EPV = (NOPAT + D&A − Maint CapEx) / WACC → when D&A=Maint, simplifies to NOPAT/WACC
B28: ROIC N/M guard | C28: PASS | D28: IF(IC<0,'N/M',…) applied to all 3 ROIC sections
B29: ROIC Marginal 0% guard | C29: PASS | D29: IF(AccGrowthCapEx<=0,0,…) returns 0 not N/M when no growth investment
B30: Implied IRR enterprise-first | C30: PASS | D30: 7 sections: EV→NOPAT→Dist→Reinv→Growth→Multiple→Returns
B31: Summary ROIC ISTEXT guard | C31: PASS | D31: IF(ISTEXT(ROIC),'N/M',…) propagates N/M from ROIC sheet
B32: S&M cohort amortization | C32: PASS | D32: Economic Amort = SUM of active cohort rows per year; life=4
B33: R&D cohort amortization | C33: PASS | D33: Economic Amort = SUM of active cohort rows per year; life=5
B34: DP consistency | C34: PASS | D34: WACC=11.3% consistent: EPV, ROIC (ref), Summary, Implied IRR via cell references
B35: Hurdle rate consistency | C35: PASS | D35: 12% in Implied IRR (blue input) and Summary (hardcode) — same value
B36: EPV Sección 3 name | C36: PASS | D36: BRIDGE EPV OPERACIONES → EQUITY EPV (not Margen de Seguridad)
B37: Health Check Bloque C | C37: PASS | D37: Travel/Asset-Light: Gross Margin, Take Rate, CapEx%, SBC% vs thresholds
... B39: English labels FS | C39: PASS | D39: IS/BS/CF/Health labels in English (10-K faithful)
B41: D. DECISION POINT CONSISTENCY CHECK
B42: DP3 S&M Life = 4 | C42: PASS | D42: Appears in: S&M Cap sheet, NOPAT (amort calc)
B43: DP4 R&D Life = 5 | C43: PASS | D43: Appears in: R&D Cap sheet, NOPAT (amort calc)
B44: DP8 Tax = 21% | C44: PASS | D44: Appears in: NOPAT PARÁMETROS → EPV link → ROIC implicit
B45: DP11 WACC = 11.3% | C45: PASS | D45: Appears in: EPV WACC calc → Summary → ROIC ref → Implied IRR
B46: DP15 Exit Multiple = 18x | C46: PASS | D46: Appears in: Implied IRR Sección 6 — blue hardcode $18
...

Sheet 15. Auto-Infer
B2: AUTO-INFERENCES v4.3.0 — Uber Technologies | DCE Holdings
B3: Trazabilidad de inferencias automáticas — Tier, Confidence, Fallback Chain | DP#1, DP#16b, DP#17
B5: S&M TREATMENT — DP#1
B6: Tier Seleccionado | C6: Tier 2 — historical_ratio
B7: Confidence | C7: MEDIUM
B8: Valor Inferido | C8: Baseline S&M/Rev ≈ 12.1% (FY2021-2025 mediana); UBER no tiene régimen estable Dual Gate por hipercrecimiento
B9: Ventana Histórica | C9: FY2020-FY2025 (6 años) — target 10y, pero UBER solo tiene 6y post-IPO (IPO May 2019)
B10: Años Estables (Dual Gate) | C10: Ninguno detectado — Rev growth mediana 37%, S&M/Rev mediana ~12%; ningún año pasa ambos gates dada alta volatilidad en ventana corta
B11: Razonamiento | C11: UBER no tiene customer/churn data pública → Tier 1 descartado. Ventana solo 6 años (< 10y target) pero ≥ 5y mínimo → Tier 2 permitido con downgrade a MEDIUM. Dado que no hay años Dual Gate estables, se usa mediana histórica del ratio completo como baseline. G&A sí es separable (Tier 3a) pero se prefiere Tier 2 histórico. Vida útil 4 años (DP3) implica que el modelo capitaliza correctamente el incremental.
B12: Fallback Chain | C12: Tier 1 descartado: sin customer/churn data pública. Tier 2: ventana 6y < 10y target → confidence downgrade a MEDIUM. Tier 3a (G&A proxy) disponible como fallback si Tier 2 rechazado.
B14: CRECIMIENTO ORGÁNICO — DP#17 (g_organic)
B15: Tier Seleccionado | C15: Tier 4 — manual con justificación textual
B16: Confidence | C16: MEDIUM
B17: Valor Elegido | C17: 2.0% — conservador
B18: Ventana Histórica | C18: FY2020-2025 (6 años) — Rev CAGR 5yr ≈ 36%; ajustado por maduración del mercado base
B19: Razonamiento | C19: Uber opera en 70+ países. Mercados maduros (US, W. Europe) crecen ~5-8% rides YoY con pricing power limitado (~2%). Mercados emergentes (India, Latam) crecen 15-25% pero desde bases pequeñas. Plataforma multi-segmento (Rides+Delivery+Freight) reduce concentración. g_organic = 2% representa pricing power sostenible en estado estacionario sin reinversión adicional — conservador pero defensable para modelo EPV.
B20: Fallback Chain | C20: No hay método cuantitativo estándar para g_organic; es inherentemente manual. Se rechaza 0% (muy conservador para plataforma con network effects) y 4% (requiere pricing power sostenido no demostrado). 2% = equilibrio.
B22: b_GROWTH (REINVESTMENT RATE DERIVADA) — DP#16b
B23: Tier Seleccionado | C23: Automático — derivado de CapEx − D&A sobre ventana FY2021-2025
B24: Confidence | C24: MEDIUM
B25: Valor Derivado | C25: b_growth ≈ 0 — CapEx < D&A en todos los años FY2022-2025; Growth CapEx = 0
B26: Ventana Histórica | C26: FY2021-2025 — 5 años, mínimo viable
B27: Razonamiento | C27: CapEx/D&A: FY2020=1.07x, FY2021=0.33x, FY2022=0.27x, FY2023=0.27x, FY2024=0.34x, FY2025=0.47x. Desde FY2021, CapEx < D&A consistentemente → Maintenance CapEx > CapEx → Growth CapEx = MAX(0, CapEx-D&A) = 0. Crecimiento se financia via S&M y R&D (growth intangibles). b_growth en sentido físico = 0; total reinversión ≈ $862M en S&M+R&D growth expenses.
B28: Fallback Chain | C28: Método Tano puro (b = 1 - Payout Ratio) no aplica directamente sin dividendo ordinario. Se usa CapEx-D&A negativo como señal directa de b_growth = 0 para activos físicos.
B30: PHASE 4 AUDIT GATE v4.3 — RESULTADO
B31: Status | C31: PASS
B32: Confidence Summary | C32: HIGH=0 MEDIUM=3 LOW=0 FAIL=0
B34: v43_section (raw output from audit_gate_v43.evaluate):
B35: ═══ PHASE 4 AUDIT GATE v4.3 ═══
B36: Status: PASS
B37: Confidence summary: HIGH=0 MEDIUM=3 LOW=0 FAIL=0
B38: ROIC marginal: current=24.00% previous=21.69% Δ=+231bps
B39: All v4.3 gates satisfied. Model release authorized.
B41: Source: auto_inferences computed via helpers v4.3.0 | stable_regime_detector + sm_decision_point + audit_gate_v43 | DCE Holdings
