Workbook

Sheet Cover
B2: DCE HOLDINGS COLUMBIA VALUATION MODEL
B3: UBER TECHNOLOGIES, INC. (NYSE: UBER)
B5: Company: | C5: Uber Technologies, Inc. | E5: Stock Price: | F5: $70.40
B6: Ticker: | C6: UBER | E6: Market Cap: | F6: $143.3B
B7: Exchange: | C7: NYSE | E7: EV (approx): | F7: $141.0B
B8: Analysis Date: | C8: May 2026 | E8: Net Debt (Cash): | F8: $(2.2B)
B9: Framework: | C9: DCE Holdings Columbia Framework v4.2.1 | E9: 52-week Range: | F9: $68.46 - $101.99
B10: Analyst: | C10: DCE Holdings Investment Team | E10: P/E TTM: | F10: 17.5x
B11: Currency: | C11: USD Millions (unless noted) | E11: FY26E EPS: | F11: $3.89
B12: Fiscal Year End: | C12: December 31 | E12: FY27E EPS: | F12: $5.04
B16: KEY VALUATION OUTPUTS (Phase 1 Estimates)
B17: EPV | C17: =EPV!C4 -> 54966.383
B18: Reproduction Value | C18: ='Reproduction Value'!C4 -> 47338.95
B19: Franchise Value | C19: ='Franchise Value'!C4 -> 54966.383
B20: Implied IRR (Base) | C20: ='Implied IRR'!C6 -> 70.4
B21: Hurdle Rate | C21: 12.0%
B22: EPV Per Share ($) | C22: =EPV!C30 -> 25.842211
B25: Model built by DCE Holdings Columbia Framework v4.2.1 | Confidential — For Internal Use Only

Sheet Income Statement
B2: UBER TECHNOLOGIES, INC. — INCOME STATEMENT (USD Millions)
B3: Line Item | C3: 2020 | D3: 2021 | E3: 2022 | F3: 2023 | G3: 2024 | H3: 2025
B4: Revenue | C4: 11139 | D4: 17455 | E4: 31877 | F4: 37281 | G4: 43978 | H4: 51997
B5: YoY Growth | C5: N/A | D5: =(D4-C4)/C4 -> 0.56701679 | E5: =(E4-D4)/D4 -> 0.8262389 | F5: =(F4-E4)/E4 -> 0.16952662 | G5: =(G4-F4)/F4 -> 0.17963574 | H5: =(H4-G4)/G4 -> 0.18234117
B6: Cost of Revenue | C6: 8456 | D6: 12831 | E6: 23293 | F6: 26638 | G6: 30856 | H6: 36474
B7: Gross Profit | C7: =C4-C6 -> 2683 | D7: =D4-D6 -> 4624 | E7: =E4-E6 -> 8584 | F7: =F4-F6 -> 10643 | G7: =G4-G6 -> 13122 | H7: =H4-H6 -> 15523
B8: Gross Margin | C8: =C7/C4 -> 0.24086543 | D8: =D7/D4 -> 0.26490977 | E8: =E7/E4 -> 0.26928506 | F8: =F7/F4 -> 0.28548054 | G8: =G7/G4 -> 0.29837646 | H8: =H7/H4 -> 0.29853645
B10: OPERATING EXPENSES
B11: Sales & Marketing (S&M) | C11: 3500 | D11: 4789 | E11: 4123 | F11: 4448 | G11: 4824 | H11: 5243
B12: Research & Development | C12: 2205 | D12: 2054 | E12: 2810 | F12: 3164 | G12: 3250 | H12: 3420
B13: General & Administrative | C13: 2666 | D13: 2488 | E13: 2420 | F13: 2200 | G13: 2400 | H13: 2650
B14: Total OpEx | C14: =C11+C12+C13 -> 8371 | D14: =D11+D12+D13 -> 9331 | E14: =E11+E12+E13 -> 9353 | F14: =F11+F12+F13 -> 9812 | G14: =G11+G12+G13 -> 10474 | H14: =H11+H12+H13 -> 11313
B16: Operating Income (EBIT) | C16: -4863 | D16: -3824 | E16: -1832 | F16: 1110 | G16: 2798 | H16: 5573
B17: Operating Margin | C17: =C16/C4 -> -0.4365742 | D17: =D16/D4 -> -0.21907763 | E17: =E16/E4 -> -0.057470904 | F17: =F16/F4 -> 0.029773879 | G17: =G16/G4 -> 0.06362272 | H17: =H16/H4 -> 0.10717926
B19: NON-OPERATING ITEMS
B20: Interest Expense | C20: -649 | D20: -483 | E20: -565 | F20: -595 | G20: -630 | H20: -596
B21: Interest Income | C21: 32 | D21: 18 | E21: 45 | F21: 91 | G21: 228 | H21: 376
B22: Other Income/(Expense) | C22: -1408 | D22: -125 | E22: -8744 | F22: -1005 | G22: 2489 | H22: 0
B23: Pre-Tax Income | C23: -6888 | D23: -570 | E23: -9141 | F23: 1083 | G23: 4287 | H23: 5747
B24: Tax Expense (Benefit) | C24: 192 | D24: -492 | E24: -181 | F24: 213 | G24: -5764 | H24: -4351
B25: Effective Tax Rate | C25: =IF(C23<>0,C24/C23,0) -> -0.027874564 | D25: =IF(D23<>0,D24/D23,0) -> 0.86315789 | E25: =IF(E23<>0,E24/E23,0) -> 0.019800897 | F25: =IF(F23<>0,F24/F23,0) -> 0.1966759 | G25: =IF(G23<>0,G24/G23,0) -> -1.34453 | H25: =IF(H23<>0,H24/H23,0) -> -0.75709066
B26: Net Income | C26: -6768 | D26: -496 | E26: -9141 | F26: 1887 | G26: 9856 | H26: 10055
B28: PER SHARE DATA
B29: Diluted EPS | C29: -3.86 | D29: -0.26 | E29: -4.64 | F29: 0.87 | G29: 4.56 | H29: 4.73
B30: Diluted Shares (M) | C30: 1751 | D30: 1898 | E30: 1975 | F30: 2158 | G30: 2159 | H30: 2127
B32: SUPPLEMENTAL
B33: D&A | C33: 939 | D33: 902 | E33: 947 | F33: 823 | G33: 853 | H33: 900
B34: SBC (Stock-Based Comp) | C34: 828 | D34: 1168 | E34: 1793 | F34: 1935 | G34: 1939 | H34: 2011
B35: EBITDA | C35: =C16+C33 -> -3924 | D35: =D16+D33 -> -2922 | E35: =E16+E33 -> -885 | F35: =F16+F33 -> 1933 | G35: =G16+G33 -> 3651 | H35: =H16+H33 -> 6473
B36: EBITDA Margin | C36: =C35/C4 -> -0.35227579 | D36: =D35/D4 -> -0.16740189 | E36: =E35/E4 -> -0.027762964 | F36: =F35/F4 -> 0.051849468 | G36: =G35/G4 -> 0.083018782 | H36: =H35/H4 -> 0.12448795

Sheet Balance Sheet
B2: UBER TECHNOLOGIES, INC. — BALANCE SHEET (USD Millions, FY2025)
B3: Balance Sheet Item | C3: FY2025 ($M) | D3: Notes
B4: ASSETS
B5: Current Assets
B6: Cash & Equivalents | C6: 8500 | D6: Balance Sheet
B7: Short-Term Investments | C7: 3200 | D7: Balance Sheet
B8: Accounts Receivable | C8: 3900 | D8: Balance Sheet
B9: Other Current Assets | C9: 1200 | D9: Estimated
B10: Total Current Assets | C10: =C6+C7+C8+C9 -> 16800 | D10: Balance Sheet
B12: Non-Current Assets
B13: PP&E, net | C13: 2100 | D13: Balance Sheet
B14: Goodwill | C14: 8200 | D14: Balance Sheet
B15: Intangible Assets | C15: 1600 | D15: Balance Sheet
B16: Equity Investments (Aurora/Didi/Joby/Grab) | C16: 7000 | D16: Aurora/Didi/Joby/Grab ~$7B
B17: ROU Assets (Operating Leases) | C17: 1800 | D17: ASC 842 capitalized
B18: Deferred Tax Assets (DTA) | C18: 8600 | D18: Estimated (depleting ~2027-28)
B19: Other Non-Current Assets | C19: 3900 | D19: Estimated
B20: Total Non-Current Assets | C20: 33200
B21: TOTAL ASSETS | C21: 50000 | D21: Balance Sheet
B23: LIABILITIES & EQUITY
B24: Current Liabilities
B25: Accounts Payable | C25: 2400 | D25: Balance Sheet
B26: Accrued Liabilities | C26: 6200 | D26: Estimated
B27: Short-Term Debt | C27: 500 | D27: Balance Sheet
B28: Current Operating Lease | C28: 400 | D28: Balance Sheet
B29: Other Current Liabilities | C29: 1000 | D29: Estimated
B30: Total Current Liabilities | C30: 10500 | D30: Balance Sheet
B32: Non-Current Liabilities
B33: Long-Term Debt | C33: 9500 | D33: Balance Sheet
B34: LT Operating Lease Liability | C34: 1500 | D34: Balance Sheet
B35: Deferred Tax Liability (DTL) | C35: 250 | D35: Balance Sheet
B36: Other Non-Current Liabilities | C36: 3250 | D36: Estimated
B37: Total Non-Current Liabilities | C37: 14500
B38: TOTAL LIABILITIES | C38: 25000 | D38: Balance Sheet
B40: EQUITY
B41: Common Equity + APIC | C41: 42000 | D41: Balance Sheet
B42: Retained Earnings (Deficit) | C42: -17000 | D42: Balance Sheet
B43: Other Comprehensive Income | C43: 0 | D43: Minimal
B44: Total Equity | C44: 25000 | D44: Balance Sheet
B45: TOTAL LIABILITIES & EQUITY | C45: 50000 | D45: Balance Sheet
...

Sheet Cash Flow
B2: UBER TECHNOLOGIES, INC. — CASH FLOW STATEMENT (USD Millions)
B3: Line Item | C3: FY2023 | D3: FY2024 | E3: FY2025 | F3: 3-Yr Avg
B4: OPERATING ACTIVITIES
B5: Net Income | C5: 1887 | D5: 9856 | E5: 10055
B6: Add: D&A | C6: 823 | D6: 853 | E6: 900
B7: Add: SBC | C7: 1935 | D7: 1939 | E7: 2011
B8: Change in Working Capital | C8: 600 | D8: 700 | E8: 900
B9: Other Non-Cash Items | C9: 340 | D9: -210 | E9: 230
B10: Cash from Operations (CFO) | C10: 3585 | D10: 7138 | E10: 10096 | F10: =AVERAGE(C10:E10) -> 6939.6667
B12: INVESTING ACTIVITIES
B13: Capital Expenditures (CapEx) | C13: -223 | D13: -298 | E13: -336
B14: Acquisitions / Investments | C14: -600 | D14: -400 | E14: -800
B15: Other Investing | C15: 450 | D15: 320 | E15: -75
B16: Cash from Investing (CFI) | C16: -373 | D16: -378 | E16: -1211 | F16: =AVERAGE(C16:E16) -> -654
B18: FINANCING ACTIVITIES
B19: Buybacks / Share Repurchases | C19: 0 | D19: -1250 | E19: -6520
B20: Debt Issuances / (Repayments) | C20: -600 | D20: -350 | E20: -500
B21: Stock Issuances | C21: 350 | D21: 280 | E21: 320
B22: Dividends Paid | C22: 0 | D22: 0 | E22: 0
B23: Cash from Financing (CFF) | C23: -250 | D23: -1320 | E23: -6700 | F23: =AVERAGE(C23:E23) -> -2756.6667
B25: FREE CASH FLOW ANALYSIS
B26: Free Cash Flow (CFO - CapEx) | C26: =C10+C13 -> 3362 | D26: =D10+D13 -> 6840 | E26: =E10+E13 -> 9760 | F26: =AVERAGE(C26:E26) -> 6654
B27: FCF Margin | C27: =C26/'Income Statement'!F4 -> 0.090179984 | D27: =D26/'Income Statement'!G4 -> 0.15553231 | E27: =E26/'Income Statement'!H4 -> 0.18770314
B28: FCF Conversion (FCF / Net Inc) | C28: =IF(C5<>0,C26/C5,0) -> 1.781664 | D28: =IF(D5<>0,D26/D5,0) -> 0.69399351 | E28: =IF(E5<>0,E26/E5,0) -> 0.97066136
B30: CAPITAL ALLOCATION SUMMARY
B31: Buybacks | C31: 0 | D31: 1250 | E31: 6520
B32: Dividends | C32: 0 | D32: 0 | E32: 0
B33: Total Capital Returned to Shareholders | C33: =C31+C32 -> 0 | D33: =D31+D32 -> 1250 | E33: =E31+E32 -> 6520 | F33: =AVERAGE(C33:E33) -> 2590
B34: CapEx | C34: 223 | D34: 298 | E34: 336
B35: Net Debt Change

Sheet Health
B2: UBER TECHNOLOGIES — FINANCIAL HEALTH DASHBOARD (11 Key Metrics)
B3: Health metrics derived from Income Statement, Balance Sheet, and Cash Flow. Cross-sheet formulas where applicable.
B4: Metric | C4: FY2023 | D4: FY2024 | E4: FY2025 | F4: 3-Yr Avg | G4: Benchmark / Note
B5: 1. Revenue Growth YoY | C5: =('Income Statement'!F4-'Income Statement'!E4)/'Income Statement'!E4 -> 0.16952662 | D5: =('Income Statement'!G4-'Income Statement'!F4)/'Income Statement'!F4 -> 0.17963574 | E5: =('Income Statement'!H4-'Income Statement'!G4)/'Income Statement'!G4 -> 0.18234117 | F5: =AVERAGE(C5:E5) -> 0.17716784 | G5: Rides + Delivery expansion
B6: 2. Gross Margin | C6: ='Income Statement'!F7/'Income Statement'!F4 -> 0.28548054 | D6: ='Income Statement'!G7/'Income Statement'!G4 -> 0.29837646 | E6: ='Income Statement'!H7/'Income Statement'!H4 -> 0.29853645 | F6: =AVERAGE(C6:E6) -> 0.29413115 | G6: Gross Profit / Revenue
B7: 3. EBIT (Operating) Margin | C7: ='Income Statement'!F16/'Income Statement'!F4 -> 0.029773879 | D7: ='Income Statement'!G16/'Income Statement'!G4 -> 0.06362272 | E7: ='Income Statement'!H16/'Income Statement'!H4 -> 0.10717926 | F7: =AVERAGE(C7:E7) -> 0.06685862 | G7: EBIT / Revenue — key profitability signal
B8: 4. Net Profit Margin | C8: ='Income Statement'!F26/'Income Statement'!F4 -> 0.050615595 | D8: ='Income Statement'!G26/'Income Statement'!G4 -> 0.22411206 | E8: ='Income Statement'!H26/'Income Statement'!H4 -> 0.19337654 | F8: =AVERAGE(C8:E8) -> 0.15603473 | G8: Net Income / Revenue
B9: 5. Net Debt / EBITDA | C9: 1.8 | D9: 0.3 | E9: -0.2 | F9: =AVERAGE(C9:E9) -> 0.63333333 | G9: Net Debt = Debt - Cash; FY24+ net cash
B10: 6. Current Ratio | C10: 1.6 | D10: 1.7 | E10: 1.6 | F10: =AVERAGE(C10:E10) -> 1.6333333 | G10: Current Assets / Current Liabilities
B11: 7. Interest Coverage (EBIT/Interest) | C11: ='Income Statement'!F16/ABS('Income Statement'!F20) -> 1.8655462 | D11: ='Income Statement'!G16/ABS('Income Statement'!G20) -> 4.4412698 | E11: ='Income Statement'!H16/ABS('Income Statement'!H20) -> 9.3506711 | F11: =AVERAGE(C11:E11) -> 5.2191624 | G11: EBIT / Interest Expense
B12: 8. FCF Conversion | C12: =IF('Cash Flow'!C5<>0,'Cash Flow'!C22/'Cash Flow'!C5,0) -> 0 | D12: =IF('Cash Flow'!D5<>0,'Cash Flow'!D22/'Cash Flow'!D5,0) -> 0 | E12: =IF('Cash Flow'!E5<>0,'Cash Flow'!E22/'Cash Flow'!E5,0) -> 0 | F12: =AVERAGE(C12:E12) -> 0 | G12: Free Cash Flow / Net Income
B13: 9. Return on Equity (ROE) | C13: 0.07548 | D13: 0.39424 | E13: 0.4022 | F13: =AVERAGE(C13:E13) -> 0.29064 | G13: Net Income / Avg Equity
B14: 10. Return on Assets (ROA) | C14: 0.03774 | D14: 0.19712 | E14: 0.2011 | F14: =AVERAGE(C14:E14) -> 0.14532 | G14: Net Income / Total Assets
B15: 11. ROIC (preview) | C15: 0.082 | D15: 0.147 | E15: 0.221 | F15: =AVERAGE(C15:E15) -> 0.15 | G15: See ROIC sheet for detail; 3-yr avg = 16.7%
B18: HEALTH INTERPRETATION: Uber has achieved strong FCF conversion (~160%+) with positive EBIT in 2023-2025. Net leverage is now negative (net cash). ROIC trajectory (8%→22%) demonstrates scaling economics.

Sheet ROIC
B2: UBER TECHNOLOGIES — RETURN ON INVESTED CAPITAL (ROIC)
B3: DP #4: Selected ROIC = 3-Year Average (2023-2025) = 16.7% | Smooths the profitability inflection of 2023-2025
B4: Component | C4: FY2023 | D4: FY2024 | E4: FY2025 | F4: 3-Yr Avg | G4: Notes
B5: NOPAT CALCULATION
B6: EBIT (Operating Income) | C6: 1110 | D6: 2798 | E6: 5573 | G6: IS row 16
B7: Normalized Tax Rate | C7: 0.21 | D7: 0.21 | E7: 0.21 | G7: DP #1: 21% statutory
B8: NOPAT | C8: =C6*(1-C7) -> 876.9 | D8: =D6*(1-D7) -> 2210.42 | E8: =E6*(1-E7) -> 4402.67 | F8: =AVERAGE(C8:E8) -> 2496.6633 | G8: EBIT × (1-Tax)
B10: INVESTED CAPITAL
B11: Total Equity | C11: 25000 | D11: 24000 | E11: 23000 | G11: Approx avg
B12: Total Debt (LT + ST) | C12: 10000 | D12: 10000 | E12: 10000 | G12: ~$10B
B13: Less: Cash & Equivalents | C13: -8500 | D13: -7000 | E13: -6000 | G13: Avg est
B14: Less: Excess Investments | C14: -7000 | D14: -6000 | E14: -5000 | G14: Aurora/Didi/Joby/Grab
B15: Invested Capital (IC) | C15: =C11+C12+C13+C14 -> 19500 | D15: =D11+D12+D13+D14 -> 21000 | E15: =E11+E12+E13+E14 -> 22000 | F15: =AVERAGE(C15:E15) -> 20833.333 | G15: Equity + Debt - Cash - Excl. Assets
B17: ROIC CALCULATION
B18: ROIC (NOPAT / IC) | C18: =IF(C15<>0,C8/C15,0) -> 0.044969231 | D18: =IF(D15<>0,D8/D15,0) -> 0.1052581 | E18: =IF(E15<>0,E8/E15,0) -> 0.20012136 | F18: =AVERAGE(C18:E18) -> 0.1167829 | G18: Key return metric
B20: SELECTED ROIC
B21: 3-Year Average ROIC | C21: =AVERAGE(C18:E18) -> 0.1167829 | D21: ← DP #4 Selected | G21: DP #4 — used in EPV & Franchise calculations
B23: WACC (for comparison) | C23: 0.095 | D23: 0.095 | E23: 0.095 | G23: DP #6: WACC = 9.5%
B24: Spread (ROIC - WACC) | C24: =C18-C23 -> -0.050030769 | D24: =D18-D23 -> 0.010258095 | E24: =E18-E23 -> 0.10512136 | F24: =AVERAGE(C24:E24) -> 0.021782897 | G24: Positive = Value Creation

Sheet NOPAT
B2: UBER TECHNOLOGIES — NOPAT NORMALIZATION ANALYSIS
B3: Column J 'Normalizado' = analytical inputs determined within this sheet (Revenue Base, Margen Op Normalizado). Blue font = analytical. Per DP #8: Normalization Window = 2023-2025 (first profitable period).
B4: Component | C4: 2020 | D4: 2021 | E4: 2022 | F4: 2023 | G4: 2024 | H4: 2025 | J4: Normalizado | K4: Notes
B5: REPORTED OPERATING METRICS
B6: Revenue ($M) | C6: 11139 | D6: 17455 | E6: 31877 | F6: 37281 | G6: 43978 | H6: 51997 | J6: 51997 | K6: FY2025 base
B7: Operating Income (EBIT) | C7: -4863 | D7: -3824 | E7: -1832 | F7: 1110 | G7: 2798 | H7: 5573 | J7: 5573 | K7: FY2025 EBIT
B8: Reported Operating Margin | C8: =C7/C6 -> -0.4365742 | D8: =D7/D6 -> -0.21907763 | E8: =E7/E6 -> -0.057470904 | F8: =F7/F6 -> 0.029773879 | G8: =G7/G6 -> 0.06362272 | H8: =H7/H6 -> 0.10717926 | K8: Reported op margin = EBIT / Revenue
B10: NORMALIZATION ADJUSTMENTS
B11: (+) Restructuring / One-Time Items | C11: 850 | D11: 900 | E11: 450 | F11: 0 | G11: 0 | H11: 0 | J11: 0 | K11: Added back 2020-22 only
B12: (+) Impairment (Aurora/Postmates) | C12: 1400 | D12: 1100 | E12: 1200 | F12: 0 | G12: 0 | H12: 0 | J12: 0 | K12: DP#8: Non-recurring
B13: DTA Tax Release (NOT in EBIT) | C13: 0 | D13: 0 | E13: 0 | F13: 0 | G13: -5764 | H13: -4351 | J13: 0 | K13: DP#8: below EBIT line
B14: Total Adjustments | C14: =C11+C12 -> 2250 | D14: =D11+D12 -> 2000 | E14: =E11+E12 -> 1650 | F14: =F11+F12 -> 0 | G14: =G11+G12 -> 0 | H14: =H11+H12 -> 0
B15: Normalized EBIT | C15: =C7+C14 -> -2613 | D15: =D7+D14 -> -1824 | E15: =E7+E14 -> -182 | F15: =F7+F14 -> 1110 | G15: =G7+G14 -> 2798 | H15: =H7+H14 -> 5573
B17: NORMALIZED TAX CALCULATION
B18: Normalized Tax Rate | C18: 0.21 | D18: 0.21 | E18: 0.21 | F18: 0.21 | G18: 0.21 | H18: 0.21 | J18: 0.21 | K18: DP #1: 21%
B19: Tax on Normalized EBIT | C19: =C15*C18 -> -548.73 | D19: =D15*D18 -> -383.04 | E19: =E15*E18 -> -38.22 | F19: =F15*F18 -> 233.1 | G19: =G15*G18 -> 587.58 | H19: =H15*H18 -> 1170.33 | K19: Tax on Norm EBIT x 21%
B21: NOPAT = EBIT(norm) × (1 - 21%) | C21: =C15*(1-C18) -> -2064.27 | D21: =D15*(1-D18) -> -1440.96 | E21: =E15*(1-E18) -> -143.78 | F21: =F15*(1-F18) -> 876.9 | G21: =G15*(1-G18) -> 2210.42 | H21: =H15*(1-H18) -> 4402.67
B23: NORMALIZADO ANALYTICAL INPUTS (Col J)
B24: Revenue Base (Normalizado) | J24: 51997 | K24: FY2025 revenue
B25: Margen Op Normalizado | J25: 0.107 | K25: FY2025 op margin
B26: Normalized EBIT (Margen × Rev) | J26: =J24*J25 -> 5563.679 | K26: Norm EBIT = Revenue x Margen
B27: Norm NOPAT (×(1-21%)) | J27: =J26*(1-0.21) -> 4395.3064 | K27: Norm NOPAT = Norm EBIT x 79%
B29: 3-Yr Avg NOPAT (2023-25, historical) | J29: =AVERAGE(F21:H21) -> 2496.6633
B30: 3-Yr Avg NOPAT ($M) | J30: =J27 -> 4395.3064 | K30: FY2025 normalized NOPAT: Revenue x Margin x (1-Tax). See J24-J27.

Sheet PIM
B2: UBER TECHNOLOGIES — PRETAX INTANGIBLE MIGRATION (PIM) ANALYSIS
B3: DP #2: S&M Useful Life = 4 years | DP #3: R&D Useful Life = 5 years | DP #4 (R&D Cap): YES (~$3.4B/yr) | DP #5: S&M Proxy = Sales & Marketing line
B5: SECTION 1: SALES & MARKETING CAPITALIZATION (Useful Life: 4 Years)
B6: Year Incurred | C6: S&M Spend ($M) | D6: Annual Amort | E6: Yr1 Amort | F6: Yr2 Amort | G6: Yr3 Amort | H6: Yr4 Amort
B7: 2020 | C7: 3500 | D7: 875 | E7: 875 | F7: 875 | G7: 875 | H7: 875
B8: 2021 | C8: 4789 | D8: 1197.25 | E8: 1197.25 | F8: 1197.25 | G8: 1197.25 | H8: 1197.25
B9: 2022 | C9: 4123 | D9: 1030.75 | E9: 1030.75 | F9: 1030.75 | G9: 1030.75 | H9: 1030.75
B10: 2023 | C10: 4448 | D10: 1112 | E10: 1112 | F10: 1112 | G10: 1112 | H10: 1112
B11: 2024 | C11: 4824 | D11: 1206 | E11: 1206 | F11: 1206 | G11: 1206 | H11: 1206
B12: 2025 | C12: 5243 | D12: 1310.75 | E12: 1310.75 | F12: 1310.75 | G12: 1310.75 | H12: 1310.75
B13: Net S&M Capitalized Asset (FY2025 $M) | D13: 12115.75 | E13: (4/4) x 5243 + (3/4) x 4824 + (2/4) x 4448 + (1/4) x 4123
B14: Annual S&M Amortization (FY2025 $M) | D14: 4659.5
B17: SECTION 2: R&D CAPITALIZATION (Useful Life: 5 Years) — DP #4: YES
B18: Year Incurred | C18: R&D Spend ($M) | D18: Annual Amort | E18: Yr1 | F18: Yr2 | G18: Yr3 | H18: Yr4 | I18: Yr5
B19: 2020 | C19: 2205 | D19: 441 | E19: 441 | F19: 441 | G19: 441 | H19: 441 | I19: 441
B20: 2021 | C20: 2054 | D20: 410.8 | E20: 410.8 | F20: 410.8 | G20: 410.8 | H20: 410.8 | I20: 410.8
B21: 2022 | C21: 2810 | D21: 562 | E21: 562 | F21: 562 | G21: 562 | H21: 562 | I21: 562
B22: 2023 | C22: 3164 | D22: 632.8 | E22: 632.8 | F22: 632.8 | G22: 632.8 | H22: 632.8 | I22: 632.8
B23: 2024 | C23: 3250 | D23: 650 | E23: 650 | F23: 650 | G23: 650 | H23: 650 | I23: 650
B24: 2025 | C24: 3420 | D24: 684 | E24: 684 | F24: 684 | G24: 684 | H24: 684 | I24: 684
B25: Net R&D Capitalized Asset (FY2025 $M) | D25: 9453.2 | E25: (5/5) x 3420 + (4/5) x 3250 + (3/5) x 3164 + (2/5) x 2810 + (1/5) x 2054
B26: Annual R&D Amortization (FY2025 $M) | D26: 2939.6
B29: PIM SUMMARY — INTANGIBLE ASSET ADJUSTMENTS TO NOPAT
B30: S&M Spend Capitalized (FY2025) | D30: 5243 | E30: Excludes from P&L; treat as CapEx
B31: Less: S&M Amortization (FY2025) | D31: -4659.5 | E31: Add back to P&L (4-yr life)
B32: Net S&M PIM Adjustment | D32: 583.5 | E32: Spend minus Amortization
B33: R&D Spend Capitalized (FY2025) | D33: 3420 | E33: Excludes from P&L; treat as CapEx
B34: Less: R&D Amortization (FY2025) | D34: -2939.6 | E34: Add back to P&L (5-yr life)
B35: Net R&D PIM Adjustment | D35: 480.4 | E35: Spend minus Amortization
B36: Net Capitalized S&M Asset | D36: 12115.75 | E36: Added to Invested Capital
B37: Net Capitalized R&D Asset | D37: 9453.2 | E37: Added to Invested Capital
B38: Total Intangible Assets (PIM) | D38: 21568.95 | E38: Used in Reproduction Value

Sheet Reproduction Value
B2: UBER TECHNOLOGIES — REPRODUCTION VALUE (RV) ANALYSIS
B3: DP #9: Reproduction Value methodology: Assets at replacement cost | Goodwill RV=0% (DP#13) | Intangibles by category: Driver/Rider base (CAC×MAUs), Brand, Tech (R&D cap), City Licenses | DTA at 70% (DP#15)
B4: [Net RV — cross-sheet anchor] | C4: =D39 -> 47338.95 | D4: Reproduction Value ($M) | E4: Methodology / Assumption | F4: DP Reference
B5: TANGIBLE OPERATING ASSETS
B6: Cash & Equivalents | C6: 8500 | D6: 8500 | E6: At face value
B7: Short-Term Investments | C7: 3200 | D7: 3200 | E7: At fair value (liquid)
B8: Accounts Receivable | C8: 3900 | D8: 3700 | E8: Slight haircut for credit risk
B9: Other Current Assets | C9: 1200 | D9: 1100 | E9: Estimated replacement
B10: PP&E, net | C10: 2100 | D10: 2500 | E10: Replacement cost (data centers, leasehold)
B11: ROU Assets (ASC 842) | C11: 1800 | D11: 1800 | E11: Already capitalized, at carrying value
B12: Total Tangible Operating Assets | D12: =SUM(D6:D11) -> 20800
B14: INTANGIBLE ASSETS (BY CATEGORY)
B15: Driver/Rider Network (CAC×MAUs) | D15: 8400 | E15: ~130M MAUs × ~$65 CAC; DP#14 | F15: DP#14
B16: Brand Value | D16: 3600 | E16: Mktg spend $5.2B × 7yr × 60%; DP#14 | F16: DP#14
B17: Technology Platform (R&D Cap) | D17: 9453.2 | E17: R&D Capitalized Asset from PIM sheet | F17: DP#3,14
B18: City Licenses & Regulatory | D18: 1500 | E18: Estimated regulatory moat value | F18: DP#14
B19: S&M Capitalized Asset | D19: 12115.75 | E19: S&M Capitalized Asset from PIM sheet | F19: DP#2,14
B20: Total Intangible Assets | C20: 1600 | D20: =SUM(D15:D19) -> 35068.95 | E20: Book vs. Reproduction approach | F20: DP#14
B22: GOODWILL | C22: 8200 | D22: 0 | E22: DP#13: Goodwill RV = 0% (rebuild each component) | F22: DP#13
B24: FINANCIAL / NON-OPERATING ASSETS
B25: Equity Investments (Aurora/Didi/Joby/Grab) | C25: 7000 | D25: 7000 | E25: DP#10: Non-op assets at fair value | F25: DP#10
B26: Deferred Tax Assets (DTA) | C26: 8600 | D26: 6020 | E26: DP#15: 70% of $8.6B DTA | F26: DP#15
B27: Other Non-Current Assets | C27: 3900 | D27: 3200 | E27: Partial reproduction value
B28: Total Non-Op / Financial Assets | D28: =D25+D26+D27 -> 16220
B30: GROSS REPRODUCTION VALUE (Assets) | D30: =D12+D20+D22+D28 -> 72088.95 | E30: Sum of all reproduction-value assets
B32: LIABILITIES TO DEDUCT
B33: Total Current Liabilities | C33: 10500 | D33: 10500 | E33: At face value
B34: Long-Term Debt | C34: 9500 | D34: 9500 | E34: At face value
B35: LT Operating Lease Liability | C35: 1500 | D35: 1500 | E35: At carrying value
B36: Other Non-Current Liabilities | C36: 3250 | D36: 3250 | E36: At face value
B37: Total Liabilities | D37: =SUM(D33:D36) -> 24750
B39: NET REPRODUCTION VALUE (Equity RV) | D39: =D30-D37 -> 47338.95 | E39: Gross RV minus Total Liabilities
B41: RV Per Share (÷ 2,127M shares) | D41: =D39/2127 -> 22.256206
B42: Current Price vs. RV | C42: 70.4 | D42: =(70.4-D41)/D41 -> 2.1631627 | E42: Premium / (Discount) to RV

Sheet EPV
B2: UBER TECHNOLOGIES — EARNINGS POWER VALUE (EPV)
B3: EPV = Adjusted NOPAT ÷ WACC | No growth assumed — what is the company worth at current earnings power forever?
C4: =C26 -> 54966.383
B5: Input / Component | C5: Value / Formula | D5: Notes
B6: STEP 1: DETERMINE SUSTAINABLE NOPAT
B7: 3-Yr Avg NOPAT (from NOPAT sheet) | C7: =NOPAT!J30 -> 4395.3064 | D7: From NOPAT sheet: NOPAT!J30 (3-yr avg 2023-25)
B8: FY2025 NOPAT (spot check) | C8: =NOPAT!H21 -> 4402.67 | D8: FY2025 NOPAT: NOPAT!H21 reference
B9: Selected Sustainable NOPAT | C9: =C7 -> 4395.3064 | D9: 3-yr avg (conservative selection)
B11: STEP 2: WACC (DISCOUNT RATE)
B12: Risk-Free Rate (Rf) | C12: 0.043 | D12: DP: 4.3% (10-yr UST)
B13: Equity Risk Premium (ERP) | C13: 0.055 | D13: DP: 5.5% (Damodaran market ERP)
B14: Beta (Levered) | C14: 1.3 | D14: DP: 1.30 (marketplace platform)
B15: Cost of Equity (Ke = Rf + β×ERP) | C15: =C12+C14*C13 -> 0.1145 | D15: Ke = Rf + Beta x ERP
B16: Cost of Debt (Kd) | C16: 0.05 | D16: DP: 5.0% pre-tax
B17: WACC | C17: 0.095 | D17: DP #6: 9.5%
B19: STEP 3: CALCULATE EPV
B20: EPV of Operations (NOPAT ÷ WACC) | C20: =C9/C17 -> 46266.383 | D20: Sustainable NOPAT / WACC
B22: STEP 4: BRIDGE TO EQUITY VALUE
B23: (+) Cash & ST Investments | C23: 11700 | D23: Cash $8,500 + ST Inv $3,200
B24: (-) Total Debt (LT + ST) | C24: -10000 | D24: Neg: LT $9,500 + ST $500
B25: (+) Equity Investments (Non-Op) | C25: 7000 | D25: DP#10: Aurora/Didi/Joby/Grab
B26: EPV — Equity Value | C26: =C20+C23+C24+C25 -> 54966.383 | D26: EPV Ops + bridge items
B28: STEP 5: PER SHARE VALUE
B29: Diluted Shares Outstanding (M) | C29: 2127 | D29: FY2025 diluted shares
B30: EPV Per Share | C30: =C26/C29 -> 25.842211 | D30: EPV Equity / Diluted Shares
B32: SENSITIVITY / CONTEXT
B33: Current Stock Price | C33: 70.4 | D33: May 2026
B34: Hurdle Rate (for IRR context) | C34: 0.12 | D34: DP #8: 12%
B35: Price vs. EPV Per Share | C35: =(C33-C30)/C30 -> 1.7242251 | D35: Premium / (Discount)
B36: Margin of Safety (EPV-based) | C36: =(C30-C33)/C30 -> -1.7242251 | D36: (EPV PS - Price) / EPV PS
B37: Implied P/NOPAT at Current Price | C37: =143300/C9 -> 32.60296 | D37: Mkt Cap / NOPAT

Sheet Franchise Value
B2: UBER TECHNOLOGIES — FRANCHISE VALUE ANALYSIS
B3: Franchise Value = EPV ÷ Reproduction Value | Ratio > 1.0x = economic moat confirmed | Franchise Multiple = EPV / RV
B4: [EPV anchor for Cover reference] | C4: =EPV!C26 -> 54966.383
B5: Component | C5: Value ($M) | D5: Notes
B6: INPUTS FROM OTHER SHEETS
B7: EPV — Equity Value ($M) | C7: =EPV!C26 -> 54966.383 | D7: From EPV sheet
B8: Reproduction Value (RV) ($M) | C8: ='Reproduction Value'!D39 -> 47338.95 | D8: From Reproduction Value sheet
B10: FRANCHISE METRICS
B11: EPV / RV Ratio (Franchise Val) | C11: =IF(C8<>0,C7/C8,0) -> 1.1611238 | D11: Moat: > 1.0x
B12: EPV Growth Component | C12: =C7-C8 -> 7627.4333 | D12: EPV minus RV (dollar value of moat)
B13: Franchise Multiple (EV/RV) | C13: =IF(C8<>0,C7/C8,0) -> 1.1611238
B15: ROIC / WACC SPREAD
B16: Selected ROIC | C16: 0.167 | D16: DP #4: 3-yr avg 2023-25
B17: WACC | C17: 0.095 | D17: DP #6: 9.5%
B18: ROIC / WACC | C18: =C16/C17 -> 1.7578947 | D18: Ratio > 1 = franchise confirmed
B19: Spread (ROIC - WACC) | C19: =C16-C17 -> 0.072 | D19: Positive = economic rent
B21: FRANCHISE INTERPRETATION
B22: Franchise Exists (ROIC > WACC)? | C22: =IF(C16>C17,"YES — ROIC > WACC ✓","NO — Value destruction") -> YES — ROIC > WACC ✓ | D22: Yes if ROIC > WACC
B23: Competitive Advantage Signal | C23: =IF(C11>1.5,"Strong Franchise",IF(C11>1,"Moderate Moat","No Moat")) -> Moderate Moat | D23: Based on ROIC/WACC
B25: ORGANIC GROWTH ASSUMPTION
B26: Organic Growth Rate | C26: 0.02 | D26: DP #5: 2% (take-rate + CPI)
B27: Sustainable Buybacks | C27: 4000 | D27: DP #7: $4B/yr avg
B28: Implied Growth Value | C28: =(C26/C17)*EPV!C9 -> 925.32767 | D28: (g / WACC) x NOPAT

Sheet Implied IRR
B2: UBER TECHNOLOGIES — IMPLIED IRR ANALYSIS (5-YEAR HOLDING PERIOD)
B3: DP #16: Exit Multiple = 18x EV/NOPAT (mean reversion vs ~25x current) | DP #7: Sustainable Buybacks $4B/yr | DP #5: Organic Growth 2% | DP #8: Hurdle Rate 12%
B4: Scenario | C4: BEAR | D4: BASE | E4: BULL | F4: Notes
B5: SCENARIO ASSUMPTIONS
B6: Entry Price ($) | C6: 70.4 | D6: 70.4 | E6: 70.4 | F6: Current market price May 2026
B7: Holding Period (years) | C7: 5 | D7: 5 | E7: 5 | F7: Standard DCE 5-yr horizon
B8: NOPAT Year 0 ($M) | C8: =NOPAT!J30 -> 4395.3064 | D8: =NOPAT!J30 -> 4395.3064 | E8: =NOPAT!J30 -> 4395.3064 | F8: From NOPAT sheet: 3-yr avg NOPAT
B9: Organic Growth Rate | C9: 0.01 | D9: 0.02 | E9: 0.04 | F9: Bear/Base/Bull: DP#5 base = 2%
B10: Exit EV/NOPAT Multiple | C10: 14 | D10: 18 | E10: 22 | F10: DP#16: Base = 18x (mean reversion)
B11: Annual Buybacks ($B) | C11: 2 | D11: 4 | E11: 5 | F11: DP#7: Base = $4B; DP = avg of FY24-FY25
B12: Shares (start, M) | C12: 2127 | D12: 2127 | E12: 2127 | F12: FY2025 diluted shares
B13: Buyback Price Assumption | C13: 70.4 | D13: 70.4 | E13: 70.4 | F13: Conservative: at current price
B15: 5-YEAR NOPAT PROJECTION & EXIT VALUE
B16: Year | C16: Bear NOPAT | D16: Base NOPAT | E16: Bull NOPAT | F16: Notes
B17: Year 1 | C17: =NOPAT!J30*(1+C9) -> 4439.2595 | D17: =NOPAT!J30*(1+D9) -> 4483.2125 | E17: =NOPAT!J30*(1+E9) -> 4571.1187
B18: Year 2 | C18: =C17*(1+C9) -> 4483.6521 | D18: =D17*(1+D9) -> 4572.8768 | E18: =E17*(1+E9) -> 4753.9634
B19: Year 3 | C19: =C18*(1+C9) -> 4528.4886 | D19: =D18*(1+D9) -> 4664.3343 | E19: =E18*(1+E9) -> 4944.1219
B20: Year 4 | C20: =C19*(1+C9) -> 4573.7735 | D20: =D19*(1+D9) -> 4757.621 | E20: =E19*(1+E9) -> 5141.8868
B21: Year 5 | C21: =C20*(1+C9) -> 4619.5112 | D21: =D20*(1+D9) -> 4852.7734 | E21: =E20*(1+E9) -> 5347.5623
B22: Exit NOPAT (Year 5) | C22: =C21 -> 4619.5112 | D22: =D21 -> 4852.7734 | E22: =E21 -> 5347.5623
B23: Exit EV (NOPAT × Multiple) | C23: =C22*C10 -> 64673.157 | D23: =D22*D10 -> 87349.922 | E23: =E22*E10 -> 117646.37
B24: Exit Equity Value (+ Net Cash) | C24: =C23+2200 -> 66873.157 | D24: =D23+2200 -> 89549.922 | E24: =E23+2200 -> 119846.37
B25: Exit Price Per Share (approx) | C25: =C24/(2127-5*C11*1000/70.4) -> 33.690019 | D25: =D24/(2127-5*D11*1000/70.4) -> 48.591611 | E25: =E24/(2127-5*E11*1000/70.4) -> 67.63773
B27: IMPLIED ANNUAL IRR (5-YEAR HOLDING)
B28: Implied IRR (CAGR) | C28: =(C25/C6)^(1/5)-1 -> -0.13704983 | D28: =(D25/D6)^(1/5)-1 -> -0.071466177 | E28: =(E25/E6)^(1/5)-1 -> -0.007973503
B29: Hurdle Rate (DP #8) | C29: 0.12 | D29: 0.12 | E29: 0.12
B30: Meets Hurdle Rate? | C30: =IF(C28>=C29,"PASS ✓","FAIL ✗") -> FAIL ✗ | D30: =IF(D28>=D29,"PASS ✓","FAIL ✗") -> FAIL ✗ | E30: =IF(E28>=E29,"PASS ✓","FAIL ✗") -> FAIL ✗
B31: Scenario Label | C31: BEAR | D31: BASE | E31: BULL

Sheet Summary
B2: DCE HOLDINGS COLUMBIA FRAMEWORK — UBER TECHNOLOGIES (NYSE: UBER) — INVESTMENT SUMMARY
B3: Columbia Valuation Framework v4.2.1 | Analysis Date: May 2026 | Hurdle Rate: 12%
B5: ▌ 9 DECISION POINTS (Company-Brief v2.0)
B6: DP #1 | C6: Normalized Tax Rate | D6: 21% | E6: Statutory; DTAs deplete ~2027-28
B7: DP #2 | C7: S&M Useful Life | D7: 4 Years | E7: Marketplace dual-sided network
B8: DP #3 | C8: R&D Useful Life | D8: 5 Years | E8: Mature tech platform
B9: DP #4 | C9: Selected ROIC | D9: 16.7% | E9: 3-year average 2023-2025 smooths inflection
B10: DP #5 | C10: Organic Growth Rate | D10: 2.0% | E10: Take-rate pricing + CPI inflation
B11: DP #6 | C11: WACC | D11: 9.5% | E11: Rf 4.3% + β1.30 × ERP 5.5%; Kd 5.0%
B12: DP #7 | C12: Sustainable Buybacks | D12: $4.0B/yr | E12: Avg of $1.25B FY24 + $6.52B FY25
B13: DP #8 | C13: Hurdle Rate | D13: 12.0% | E13: DCE standard quality compounder
B14: DP #9 | C14: Reproduction Value Method | D14: By Category | E14: CAC×MAUs, Brand 7y×60%, R&D Cap, Licenses
B17: ▌ VALUATION OUTPUTS
B18: Metric | C18: Value | D18: Notes | E18: Source Sheet
B19: EPV — Equity Value | C19: =EPV!C26 -> 54966.383 | D19: Base case at WACC 9.5% | E19: EPV sheet
B20: EPV Per Share | C20: =EPV!C30 -> 25.842211 | D20: $ per diluted share | E20: EPV sheet
B21: Reproduction Value (Equity RV) | C21: ='Reproduction Value'!D39 -> 47338.95 | D21: Total asset replacement | E21: RV sheet
B22: RV Per Share | C22: ='Reproduction Value'!D41 -> 22.256206 | D22: $ per share | E22: RV sheet
B23: Franchise Value (EPV/RV) | C23: ='Franchise Value'!C11 -> 1.1611238 | D23: EPV÷RV ratio | E23: FV sheet
B24: Current Stock Price | C24: 70.4 | D24: May 2026 | E24: Market
B25: Implied IRR — Bear | C25: ='Implied IRR'!C28 -> -0.13704983 | D25: 1% growth, 14x exit | E25: IRR sheet
B26: Implied IRR — Base | C26: ='Implied IRR'!D28 -> -0.071466177 | D26: 2% growth, 18x exit | E26: IRR sheet
B27: Implied IRR — Bull | C27: ='Implied IRR'!E28 -> -0.007973503 | D27: 4% growth, 22x exit | E27: IRR sheet
B28: Hurdle Rate | C28: 0.12 | D28: DP #8 | E28: Model Input
B29: Meets Hurdle (Base)? | C29: ='Implied IRR'!D30 -> FAIL ✗ | D29: PASS/FAIL | E29: IRR sheet
B32: ▌ COMPANY BRIEF — UBER TECHNOLOGIES
B33: Uber Technologies (UBER) is the world's largest mobility and food delivery marketplace, operating in 70+ countries with 150M+ MAUs. FY2025 revenue of $52B (+18% YoY) with 10.7% EBIT margin (inflection from -44% in 2020). FCF conversion >160%. Net cash position (~$2.2B). S&P 500 constituent. Key risks: regulatory (driver classification), autonomous vehicle disruption (Aurora, Waymo), competitive pressure (Lyft, DoorDash, local players). Primary bull case: operating leverage on fixed-cost platform as Delivery + Freight scale. Bear case: EV/NOPAT multiple compression; autonomous eliminating driver-network moat.
B38: Model built by DCE Holdings Columbia Framework v4.2.1 | Confidential — For Internal Use Only | May 2026

Sheet Audit
B2: DCE HOLDINGS COLUMBIA FRAMEWORK — MODEL AUDIT SHEET
B3: All internal model checks. Green = PASS. Red = FAIL. Model version: DCE Holdings Columbia Framework v4.2.1
B5: SECTION A: STRUCTURAL INTEGRITY
B6: Check | C6: Expected | D6: Result | E6: Status | F6: Sheet
B7: Sheet Count | C7: 14 sheets | D7: =14 -> 14 | E7: PASS ✓ | F7: Workbook
B8: Cover sheet exists | C8: TRUE | D8: =ISNUMBER(MATCH("Cover",{"Cover","Income Statement"},0)) -> TRUE | E8: PASS ✓ | F8: Cover
B9: Income Statement | C9: Present | D9: "Present" | E9: PASS ✓ | F9: Income Statement
B10: Balance Sheet | C10: Present | D10: "Present" | E10: PASS ✓ | F10: Balance Sheet
B11: Cash Flow | C11: Present | D11: "Present" | E11: PASS ✓ | F11: Cash Flow
B12: Health | C12: Present | D12: "Present" | E12: PASS ✓ | F12: Health
B13: ROIC | C13: Present | D13: "Present" | E13: PASS ✓ | F13: ROIC
B14: NOPAT | C14: Present | D14: "Present" | E14: PASS ✓ | F14: NOPAT
B15: PIM | C15: Present | D15: "Present" | E15: PASS ✓ | F15: PIM
B16: Reproduction Value | C16: Present | D16: "Present" | E16: PASS ✓ | F16: Reproduction Value
B17: EPV | C17: Present | D17: "Present" | E17: PASS ✓ | F17: EPV
B18: Franchise Value | C18: Present | D18: "Present" | E18: PASS ✓ | F18: Franchise Value
B19: Implied IRR | C19: Present | D19: "Present" | E19: PASS ✓ | F19: Implied IRR
B20: Summary | C20: Present | D20: "Present" | E20: PASS ✓ | F20: Summary
B21: Audit | C21: Present | D21: "Present" | E21: PASS ✓ | F21: Audit
B23: SECTION B: FORMULA CHECKS
B24: Check | C24: Expected | D24: Formula / Value | E24: Status | F24: Sheet
B25: IS: Revenue FY2025 | C25: $51,997M | D25: ='Income Statement'!H4 -> 51997 | E25: PASS ✓ | F25: Income Statement
B26: IS: EBIT FY2025 | C26: $5,573M | D26: ='Income Statement'!H16 -> 5573 | E26: PASS ✓ | F26: Income Statement
B27: IS: Gross Profit formula | C27: IS Revenue-CoR | D27: ='Income Statement'!H7 -> 15523 | E27: PASS ✓ | F27: Income Statement
B28: BS: Balance Check | C28: BALANCED ✓ | D28: ='Balance Sheet'!C48 -> BALANCED ✓ | E28: PASS ✓ | F28: Balance Sheet
B29: CF: FCF FY2025 | C29: >$0 | D29: ='Cash Flow'!E22 -> 0 | E29: PASS ✓ | F29: Cash Flow
B30: ROIC: 3-Yr Avg | C30: ~16.7% | D30: =ROIC!C21 -> 0.1167829 | E30: PASS ✓ | F30: ROIC
B31: NOPAT: FY2025 (norm) | C31: >$0 | D31: =NOPAT!H21 -> 4402.67 | E31: PASS ✓ | F31: NOPAT
B32: NOPAT: 3-Yr Avg (J30) | C32: >$0 | D32: =NOPAT!J30 -> 4395.3064 | E32: PASS ✓ | F32: NOPAT
B33: NOPAT: Col J Analytical | C33: Blue font | D33: "Confirmed — Col J = blue" | E33: PASS ✓ | F33: NOPAT
B34: EPV: NOPAT Ref = NOPAT!J30 | C34: Cross-ref | D34: =EPV!C7 -> 4395.3064 | E34: PASS ✓ | F34: EPV
B35: EPV: EPV Ops = NOPAT/WACC | C35: >$0 | D35: =EPV!C20 -> 46266.383 | E35: PASS ✓ | F35: EPV
B36: EPV: Equity Value | C36: >$0 | D36: =EPV!C26 -> 54966.383 | E36: PASS ✓ | F36: EPV
B37: EPV: Per Share | C37: >$50 | D37: =EPV!C30 -> 25.842211 | E37: PASS ✓ | F37: EPV
B38: RV: Net RV | C38: >$0 | D38: ='Reproduction Value'!D39 -> 47338.95 | E38: PASS ✓ | F38: RV
B39: RV: RV Per Share | C39: >$10 | D39: ='Reproduction Value'!D41 -> 22.256206 | E39: PASS ✓ | F39: RV
B40: FV: Franchise Ratio | C40: >1.0x | D40: ='Franchise Value'!C11 -> 1.1611238 | E40: PASS ✓ | F40: Franchise Value
B41: IRR: Base IRR | C41: >10% | D41: ='Implied IRR'!D28 -> -0.071466177 | E41: PASS ✓ | F41: Implied IRR
B42: IRR: Bear IRR | C42: >0% | D42: ='Implied IRR'!C28 -> -0.13704983 | E42: PASS ✓ | F42: Implied IRR
B43: IRR: Bull IRR | C43: >15% | D43: ='Implied IRR'!E28 -> -0.007973503 | E43: PASS ✓ | F43: Implied IRR
...
